ERROR 2024-05-15 21:20:35,897 signal 1 140395638188808 Signal handler <promise@0x7fb065ab9950 --> <bound method Celery._autodiscover_tasks of <Celery eazyclass at 0x7fb065ab2ba0>>> raised: ModuleNotFoundError("No module named 'scheduler.tasks.models'")
Traceback (most recent call last):
  File "/usr/local/lib/python3.12/site-packages/celery/utils/dispatch/signal.py", line 276, in send
    response = receiver(signal=self, sender=sender, **named)
               ^^^^^^^^^^^^^^^^^^^^^^^^^^^^^^^^^^^^^^^^^^^^^
  File "/usr/local/lib/python3.12/site-packages/vine/promises.py", line 161, in __call__
    return self.throw()
           ^^^^^^^^^^^^
  File "/usr/local/lib/python3.12/site-packages/vine/promises.py", line 158, in __call__
    retval = fun(*final_args, **final_kwargs)
             ^^^^^^^^^^^^^^^^^^^^^^^^^^^^^^^^
  File "/usr/local/lib/python3.12/site-packages/celery/app/base.py", line 694, in _autodiscover_tasks
    return self._autodiscover_tasks_from_fixups(related_name)
           ^^^^^^^^^^^^^^^^^^^^^^^^^^^^^^^^^^^^^^^^^^^^^^^^^^
  File "/usr/local/lib/python3.12/site-packages/celery/app/base.py", line 703, in _autodiscover_tasks_from_fixups
    return self._autodiscover_tasks_from_names([
           ^^^^^^^^^^^^^^^^^^^^^^^^^^^^^^^^^^^^^
  File "/usr/local/lib/python3.12/site-packages/celery/app/base.py", line 698, in _autodiscover_tasks_from_names
    return self.loader.autodiscover_tasks(
           ^^^^^^^^^^^^^^^^^^^^^^^^^^^^^^^
  File "/usr/local/lib/python3.12/site-packages/celery/loaders/base.py", line 220, in autodiscover_tasks
    mod.__name__ for mod in autodiscover_tasks(packages or (),
                            ^^^^^^^^^^^^^^^^^^^^^^^^^^^^^^^^^^
  File "/usr/local/lib/python3.12/site-packages/celery/loaders/base.py", line 246, in autodiscover_tasks
    return [find_related_module(pkg, related_name) for pkg in packages]
            ^^^^^^^^^^^^^^^^^^^^^^^^^^^^^^^^^^^^^^
  File "/usr/local/lib/python3.12/site-packages/celery/loaders/base.py", line 278, in find_related_module
    raise e
  File "/usr/local/lib/python3.12/site-packages/celery/loaders/base.py", line 270, in find_related_module
    return importlib.import_module(module_name)
           ^^^^^^^^^^^^^^^^^^^^^^^^^^^^^^^^^^^^
  File "/usr/local/lib/python3.12/importlib/__init__.py", line 90, in import_module
    return _bootstrap._gcd_import(name[level:], package, level)
           ^^^^^^^^^^^^^^^^^^^^^^^^^^^^^^^^^^^^^^^^^^^^^^^^^^^^
  File "<frozen importlib._bootstrap>", line 1387, in _gcd_import
  File "<frozen importlib._bootstrap>", line 1360, in _find_and_load
  File "<frozen importlib._bootstrap>", line 1331, in _find_and_load_unlocked
  File "<frozen importlib._bootstrap>", line 935, in _load_unlocked
  File "<frozen importlib._bootstrap_external>", line 995, in exec_module
  File "<frozen importlib._bootstrap>", line 488, in _call_with_frames_removed
  File "/app/scheduler/tasks/__init__.py", line 2, in <module>
    from .group_parser import update_groups
  File "/app/scheduler/tasks/group_parser.py", line 10, in <module>
    from .models import Faculty, Group
ModuleNotFoundError: No module named 'scheduler.tasks.models'
ERROR 2024-05-15 21:20:35,898 signal 1 140595425463048 Signal handler <promise@0x7fdee9e9d950 --> <bound method Celery._autodiscover_tasks of <Celery eazyclass at 0x7fdeea25ec60>>> raised: ModuleNotFoundError("No module named 'scheduler.tasks.models'")
Traceback (most recent call last):
  File "/usr/local/lib/python3.12/site-packages/celery/utils/dispatch/signal.py", line 276, in send
    response = receiver(signal=self, sender=sender, **named)
               ^^^^^^^^^^^^^^^^^^^^^^^^^^^^^^^^^^^^^^^^^^^^^
  File "/usr/local/lib/python3.12/site-packages/vine/promises.py", line 161, in __call__
    return self.throw()
           ^^^^^^^^^^^^
  File "/usr/local/lib/python3.12/site-packages/vine/promises.py", line 158, in __call__
    retval = fun(*final_args, **final_kwargs)
             ^^^^^^^^^^^^^^^^^^^^^^^^^^^^^^^^
  File "/usr/local/lib/python3.12/site-packages/celery/app/base.py", line 694, in _autodiscover_tasks
    return self._autodiscover_tasks_from_fixups(related_name)
           ^^^^^^^^^^^^^^^^^^^^^^^^^^^^^^^^^^^^^^^^^^^^^^^^^^
  File "/usr/local/lib/python3.12/site-packages/celery/app/base.py", line 703, in _autodiscover_tasks_from_fixups
    return self._autodiscover_tasks_from_names([
           ^^^^^^^^^^^^^^^^^^^^^^^^^^^^^^^^^^^^^
  File "/usr/local/lib/python3.12/site-packages/celery/app/base.py", line 698, in _autodiscover_tasks_from_names
    return self.loader.autodiscover_tasks(
           ^^^^^^^^^^^^^^^^^^^^^^^^^^^^^^^
  File "/usr/local/lib/python3.12/site-packages/celery/loaders/base.py", line 220, in autodiscover_tasks
    mod.__name__ for mod in autodiscover_tasks(packages or (),
                            ^^^^^^^^^^^^^^^^^^^^^^^^^^^^^^^^^^
  File "/usr/local/lib/python3.12/site-packages/celery/loaders/base.py", line 246, in autodiscover_tasks
    return [find_related_module(pkg, related_name) for pkg in packages]
            ^^^^^^^^^^^^^^^^^^^^^^^^^^^^^^^^^^^^^^
  File "/usr/local/lib/python3.12/site-packages/celery/loaders/base.py", line 278, in find_related_module
    raise e
  File "/usr/local/lib/python3.12/site-packages/celery/loaders/base.py", line 270, in find_related_module
    return importlib.import_module(module_name)
           ^^^^^^^^^^^^^^^^^^^^^^^^^^^^^^^^^^^^
  File "/usr/local/lib/python3.12/importlib/__init__.py", line 90, in import_module
    return _bootstrap._gcd_import(name[level:], package, level)
           ^^^^^^^^^^^^^^^^^^^^^^^^^^^^^^^^^^^^^^^^^^^^^^^^^^^^
  File "<frozen importlib._bootstrap>", line 1387, in _gcd_import
  File "<frozen importlib._bootstrap>", line 1360, in _find_and_load
  File "<frozen importlib._bootstrap>", line 1331, in _find_and_load_unlocked
  File "<frozen importlib._bootstrap>", line 935, in _load_unlocked
  File "<frozen importlib._bootstrap_external>", line 995, in exec_module
  File "<frozen importlib._bootstrap>", line 488, in _call_with_frames_removed
  File "/app/scheduler/tasks/__init__.py", line 2, in <module>
    from .group_parser import update_groups
  File "/app/scheduler/tasks/group_parser.py", line 10, in <module>
    from .models import Faculty, Group
ModuleNotFoundError: No module named 'scheduler.tasks.models'
ERROR 2024-05-15 21:22:00,258 signal 17 140140669401912 Signal handler <promise@0x7f750d340c30 --> <bound method Celery._autodiscover_tasks of <Celery eazyclass at 0x7f750d36f2f0>>> raised: ModuleNotFoundError("No module named 'scheduler.tasks.models'")
Traceback (most recent call last):
  File "/usr/local/lib/python3.12/site-packages/celery/utils/dispatch/signal.py", line 276, in send
    response = receiver(signal=self, sender=sender, **named)
               ^^^^^^^^^^^^^^^^^^^^^^^^^^^^^^^^^^^^^^^^^^^^^
  File "/usr/local/lib/python3.12/site-packages/vine/promises.py", line 161, in __call__
    return self.throw()
           ^^^^^^^^^^^^
  File "/usr/local/lib/python3.12/site-packages/vine/promises.py", line 158, in __call__
    retval = fun(*final_args, **final_kwargs)
             ^^^^^^^^^^^^^^^^^^^^^^^^^^^^^^^^
  File "/usr/local/lib/python3.12/site-packages/celery/app/base.py", line 694, in _autodiscover_tasks
    return self._autodiscover_tasks_from_fixups(related_name)
           ^^^^^^^^^^^^^^^^^^^^^^^^^^^^^^^^^^^^^^^^^^^^^^^^^^
  File "/usr/local/lib/python3.12/site-packages/celery/app/base.py", line 703, in _autodiscover_tasks_from_fixups
    return self._autodiscover_tasks_from_names([
           ^^^^^^^^^^^^^^^^^^^^^^^^^^^^^^^^^^^^^
  File "/usr/local/lib/python3.12/site-packages/celery/app/base.py", line 698, in _autodiscover_tasks_from_names
    return self.loader.autodiscover_tasks(
           ^^^^^^^^^^^^^^^^^^^^^^^^^^^^^^^
  File "/usr/local/lib/python3.12/site-packages/celery/loaders/base.py", line 220, in autodiscover_tasks
    mod.__name__ for mod in autodiscover_tasks(packages or (),
                            ^^^^^^^^^^^^^^^^^^^^^^^^^^^^^^^^^^
  File "/usr/local/lib/python3.12/site-packages/celery/loaders/base.py", line 246, in autodiscover_tasks
    return [find_related_module(pkg, related_name) for pkg in packages]
            ^^^^^^^^^^^^^^^^^^^^^^^^^^^^^^^^^^^^^^
  File "/usr/local/lib/python3.12/site-packages/celery/loaders/base.py", line 278, in find_related_module
    raise e
  File "/usr/local/lib/python3.12/site-packages/celery/loaders/base.py", line 270, in find_related_module
    return importlib.import_module(module_name)
           ^^^^^^^^^^^^^^^^^^^^^^^^^^^^^^^^^^^^
  File "/usr/local/lib/python3.12/importlib/__init__.py", line 90, in import_module
    return _bootstrap._gcd_import(name[level:], package, level)
           ^^^^^^^^^^^^^^^^^^^^^^^^^^^^^^^^^^^^^^^^^^^^^^^^^^^^
  File "<frozen importlib._bootstrap>", line 1387, in _gcd_import
  File "<frozen importlib._bootstrap>", line 1360, in _find_and_load
  File "<frozen importlib._bootstrap>", line 1331, in _find_and_load_unlocked
  File "<frozen importlib._bootstrap>", line 935, in _load_unlocked
  File "<frozen importlib._bootstrap_external>", line 995, in exec_module
  File "<frozen importlib._bootstrap>", line 488, in _call_with_frames_removed
  File "/app/scheduler/tasks/__init__.py", line 2, in <module>
    from .group_parser import update_groups
  File "/app/scheduler/tasks/group_parser.py", line 10, in <module>
    from .models import Faculty, Group
ModuleNotFoundError: No module named 'scheduler.tasks.models'
ERROR 2024-05-15 21:23:18,165 signal 17 140140669401912 Signal handler <promise@0x7f750d340c30 --> <bound method Celery._autodiscover_tasks of <Celery eazyclass at 0x7f750d36f2f0>>> raised: ModuleNotFoundError("No module named 'timetable_manager'")
Traceback (most recent call last):
  File "/usr/local/lib/python3.12/site-packages/celery/utils/dispatch/signal.py", line 276, in send
    response = receiver(signal=self, sender=sender, **named)
               ^^^^^^^^^^^^^^^^^^^^^^^^^^^^^^^^^^^^^^^^^^^^^
  File "/usr/local/lib/python3.12/site-packages/vine/promises.py", line 161, in __call__
    return self.throw()
           ^^^^^^^^^^^^
  File "/usr/local/lib/python3.12/site-packages/vine/promises.py", line 158, in __call__
    retval = fun(*final_args, **final_kwargs)
             ^^^^^^^^^^^^^^^^^^^^^^^^^^^^^^^^
  File "/usr/local/lib/python3.12/site-packages/celery/app/base.py", line 694, in _autodiscover_tasks
    return self._autodiscover_tasks_from_fixups(related_name)
           ^^^^^^^^^^^^^^^^^^^^^^^^^^^^^^^^^^^^^^^^^^^^^^^^^^
  File "/usr/local/lib/python3.12/site-packages/celery/app/base.py", line 703, in _autodiscover_tasks_from_fixups
    return self._autodiscover_tasks_from_names([
           ^^^^^^^^^^^^^^^^^^^^^^^^^^^^^^^^^^^^^
  File "/usr/local/lib/python3.12/site-packages/celery/app/base.py", line 698, in _autodiscover_tasks_from_names
    return self.loader.autodiscover_tasks(
           ^^^^^^^^^^^^^^^^^^^^^^^^^^^^^^^
  File "/usr/local/lib/python3.12/site-packages/celery/loaders/base.py", line 220, in autodiscover_tasks
    mod.__name__ for mod in autodiscover_tasks(packages or (),
                            ^^^^^^^^^^^^^^^^^^^^^^^^^^^^^^^^^^
  File "/usr/local/lib/python3.12/site-packages/celery/loaders/base.py", line 246, in autodiscover_tasks
    return [find_related_module(pkg, related_name) for pkg in packages]
            ^^^^^^^^^^^^^^^^^^^^^^^^^^^^^^^^^^^^^^
  File "/usr/local/lib/python3.12/site-packages/celery/loaders/base.py", line 278, in find_related_module
    raise e
  File "/usr/local/lib/python3.12/site-packages/celery/loaders/base.py", line 270, in find_related_module
    return importlib.import_module(module_name)
           ^^^^^^^^^^^^^^^^^^^^^^^^^^^^^^^^^^^^
  File "/usr/local/lib/python3.12/importlib/__init__.py", line 90, in import_module
    return _bootstrap._gcd_import(name[level:], package, level)
           ^^^^^^^^^^^^^^^^^^^^^^^^^^^^^^^^^^^^^^^^^^^^^^^^^^^^
  File "<frozen importlib._bootstrap>", line 1387, in _gcd_import
  File "<frozen importlib._bootstrap>", line 1360, in _find_and_load
  File "<frozen importlib._bootstrap>", line 1331, in _find_and_load_unlocked
  File "<frozen importlib._bootstrap>", line 935, in _load_unlocked
  File "<frozen importlib._bootstrap_external>", line 995, in exec_module
  File "<frozen importlib._bootstrap>", line 488, in _call_with_frames_removed
  File "/app/scheduler/tasks/__init__.py", line 3, in <module>
    from timetable_manager import fill_lesson_times
ModuleNotFoundError: No module named 'timetable_manager'
ERROR 2024-05-16 13:42:25,311 signal 1 140254065072904 Signal handler <bound method DjangoFixup.on_import_modules of <celery.fixups.django.DjangoFixup object at 0x7f8f6fb5eff0>> raised: ImproperlyConfigured("The included URLconf '<module 'scheduler.urls' from '/app/scheduler/urls.py'>' does not appear to have any patterns in it. If you see the 'urlpatterns' variable with valid patterns in the file then the issue is probably caused by a circular import.")
Traceback (most recent call last):
  File "/usr/local/lib/python3.12/site-packages/django/urls/resolvers.py", line 740, in url_patterns
    iter(patterns)
TypeError: 'module' object is not iterable

The above exception was the direct cause of the following exception:

Traceback (most recent call last):
  File "/usr/local/lib/python3.12/site-packages/celery/utils/dispatch/signal.py", line 276, in send
    response = receiver(signal=self, sender=sender, **named)
               ^^^^^^^^^^^^^^^^^^^^^^^^^^^^^^^^^^^^^^^^^^^^^
  File "/usr/local/lib/python3.12/site-packages/celery/fixups/django.py", line 100, in on_import_modules
    self.worker_fixup.validate_models()
  File "/usr/local/lib/python3.12/site-packages/celery/fixups/django.py", line 140, in validate_models
    run_checks()
  File "/usr/local/lib/python3.12/site-packages/django/core/checks/registry.py", line 88, in run_checks
    new_errors = check(app_configs=app_configs, databases=databases)
                 ^^^^^^^^^^^^^^^^^^^^^^^^^^^^^^^^^^^^^^^^^^^^^^^^^^^
  File "/usr/local/lib/python3.12/site-packages/django/core/checks/urls.py", line 42, in check_url_namespaces_unique
    all_namespaces = _load_all_namespaces(resolver)
                     ^^^^^^^^^^^^^^^^^^^^^^^^^^^^^^
  File "/usr/local/lib/python3.12/site-packages/django/core/checks/urls.py", line 72, in _load_all_namespaces
    namespaces.extend(_load_all_namespaces(pattern, current))
                      ^^^^^^^^^^^^^^^^^^^^^^^^^^^^^^^^^^^^^^
  File "/usr/local/lib/python3.12/site-packages/django/core/checks/urls.py", line 61, in _load_all_namespaces
    url_patterns = getattr(resolver, "url_patterns", [])
                   ^^^^^^^^^^^^^^^^^^^^^^^^^^^^^^^^^^^^^
  File "/usr/local/lib/python3.12/site-packages/django/utils/functional.py", line 47, in __get__
    res = instance.__dict__[self.name] = self.func(instance)
                                         ^^^^^^^^^^^^^^^^^^^
  File "/usr/local/lib/python3.12/site-packages/django/urls/resolvers.py", line 748, in url_patterns
    raise ImproperlyConfigured(msg.format(name=self.urlconf_name)) from e
django.core.exceptions.ImproperlyConfigured: The included URLconf '<module 'scheduler.urls' from '/app/scheduler/urls.py'>' does not appear to have any patterns in it. If you see the 'urlpatterns' variable with valid patterns in the file then the issue is probably caused by a circular import.
ERROR 2024-05-16 13:42:26,157 signal 1 140412589984520 Signal handler <bound method DjangoFixup.on_import_modules of <celery.fixups.django.DjangoFixup object at 0x7fb458116b40>> raised: ImproperlyConfigured("The included URLconf '<module 'scheduler.urls' from '/app/scheduler/urls.py'>' does not appear to have any patterns in it. If you see the 'urlpatterns' variable with valid patterns in the file then the issue is probably caused by a circular import.")
Traceback (most recent call last):
  File "/usr/local/lib/python3.12/site-packages/django/urls/resolvers.py", line 740, in url_patterns
    iter(patterns)
TypeError: 'module' object is not iterable

The above exception was the direct cause of the following exception:

Traceback (most recent call last):
  File "/usr/local/lib/python3.12/site-packages/celery/utils/dispatch/signal.py", line 276, in send
    response = receiver(signal=self, sender=sender, **named)
               ^^^^^^^^^^^^^^^^^^^^^^^^^^^^^^^^^^^^^^^^^^^^^
  File "/usr/local/lib/python3.12/site-packages/celery/fixups/django.py", line 100, in on_import_modules
    self.worker_fixup.validate_models()
  File "/usr/local/lib/python3.12/site-packages/celery/fixups/django.py", line 140, in validate_models
    run_checks()
  File "/usr/local/lib/python3.12/site-packages/django/core/checks/registry.py", line 88, in run_checks
    new_errors = check(app_configs=app_configs, databases=databases)
                 ^^^^^^^^^^^^^^^^^^^^^^^^^^^^^^^^^^^^^^^^^^^^^^^^^^^
  File "/usr/local/lib/python3.12/site-packages/django/core/checks/urls.py", line 14, in check_url_config
    return check_resolver(resolver)
           ^^^^^^^^^^^^^^^^^^^^^^^^
  File "/usr/local/lib/python3.12/site-packages/django/core/checks/urls.py", line 24, in check_resolver
    return check_method()
           ^^^^^^^^^^^^^^
  File "/usr/local/lib/python3.12/site-packages/django/urls/resolvers.py", line 520, in check
    messages.extend(check_resolver(pattern))
                    ^^^^^^^^^^^^^^^^^^^^^^^
  File "/usr/local/lib/python3.12/site-packages/django/core/checks/urls.py", line 24, in check_resolver
    return check_method()
           ^^^^^^^^^^^^^^
  File "/usr/local/lib/python3.12/site-packages/django/urls/resolvers.py", line 519, in check
    for pattern in self.url_patterns:
                   ^^^^^^^^^^^^^^^^^
  File "/usr/local/lib/python3.12/site-packages/django/utils/functional.py", line 47, in __get__
    res = instance.__dict__[self.name] = self.func(instance)
                                         ^^^^^^^^^^^^^^^^^^^
  File "/usr/local/lib/python3.12/site-packages/django/urls/resolvers.py", line 748, in url_patterns
    raise ImproperlyConfigured(msg.format(name=self.urlconf_name)) from e
django.core.exceptions.ImproperlyConfigured: The included URLconf '<module 'scheduler.urls' from '/app/scheduler/urls.py'>' does not appear to have any patterns in it. If you see the 'urlpatterns' variable with valid patterns in the file then the issue is probably caused by a circular import.
ERROR 2024-05-16 18:09:33,745 signal 1 139680358726408 Signal handler <bound method DjangoFixup.on_import_modules of <celery.fixups.django.DjangoFixup object at 0x7f09dc5529c0>> raised: ModuleNotFoundError("No module named 'rangefilter'")
Traceback (most recent call last):
  File "/usr/local/lib/python3.12/site-packages/celery/utils/dispatch/signal.py", line 276, in send
    response = receiver(signal=self, sender=sender, **named)
               ^^^^^^^^^^^^^^^^^^^^^^^^^^^^^^^^^^^^^^^^^^^^^
  File "/usr/local/lib/python3.12/site-packages/celery/fixups/django.py", line 100, in on_import_modules
    self.worker_fixup.validate_models()
  File "/usr/local/lib/python3.12/site-packages/celery/fixups/django.py", line 138, in validate_models
    self.django_setup()
  File "/usr/local/lib/python3.12/site-packages/celery/fixups/django.py", line 134, in django_setup
    django.setup()
  File "/usr/local/lib/python3.12/site-packages/django/__init__.py", line 24, in setup
    apps.populate(settings.INSTALLED_APPS)
  File "/usr/local/lib/python3.12/site-packages/django/apps/registry.py", line 91, in populate
    app_config = AppConfig.create(entry)
                 ^^^^^^^^^^^^^^^^^^^^^^^
  File "/usr/local/lib/python3.12/site-packages/django/apps/config.py", line 193, in create
    import_module(entry)
  File "/usr/local/lib/python3.12/importlib/__init__.py", line 90, in import_module
    return _bootstrap._gcd_import(name[level:], package, level)
           ^^^^^^^^^^^^^^^^^^^^^^^^^^^^^^^^^^^^^^^^^^^^^^^^^^^^
  File "<frozen importlib._bootstrap>", line 1387, in _gcd_import
  File "<frozen importlib._bootstrap>", line 1360, in _find_and_load
  File "<frozen importlib._bootstrap>", line 1324, in _find_and_load_unlocked
ModuleNotFoundError: No module named 'rangefilter'
ERROR 2024-05-16 18:09:33,752 signal 1 139680358726408 Signal handler <promise@0x7f09dbad1950 --> <bound method Celery._autodiscover_tasks of <Celery eazyclass at 0x7f09dbac64e0>>> raised: AppRegistryNotReady("Apps aren't loaded yet.")
Traceback (most recent call last):
  File "/usr/local/lib/python3.12/site-packages/celery/utils/dispatch/signal.py", line 276, in send
    response = receiver(signal=self, sender=sender, **named)
               ^^^^^^^^^^^^^^^^^^^^^^^^^^^^^^^^^^^^^^^^^^^^^
  File "/usr/local/lib/python3.12/site-packages/vine/promises.py", line 161, in __call__
    return self.throw()
           ^^^^^^^^^^^^
  File "/usr/local/lib/python3.12/site-packages/vine/promises.py", line 158, in __call__
    retval = fun(*final_args, **final_kwargs)
             ^^^^^^^^^^^^^^^^^^^^^^^^^^^^^^^^
  File "/usr/local/lib/python3.12/site-packages/celery/app/base.py", line 694, in _autodiscover_tasks
    return self._autodiscover_tasks_from_fixups(related_name)
           ^^^^^^^^^^^^^^^^^^^^^^^^^^^^^^^^^^^^^^^^^^^^^^^^^^
  File "/usr/local/lib/python3.12/site-packages/celery/app/base.py", line 706, in _autodiscover_tasks_from_fixups
    for pkg in fixup.autodiscover_tasks()
               ^^^^^^^^^^^^^^^^^^^^^^^^^^
  File "/usr/local/lib/python3.12/site-packages/celery/fixups/django.py", line 110, in autodiscover_tasks
    return [config.name for config in apps.get_app_configs()]
                                      ^^^^^^^^^^^^^^^^^^^^^^
  File "/usr/local/lib/python3.12/site-packages/django/apps/registry.py", line 147, in get_app_configs
    self.check_apps_ready()
  File "/usr/local/lib/python3.12/site-packages/django/apps/registry.py", line 138, in check_apps_ready
    raise AppRegistryNotReady("Apps aren't loaded yet.")
django.core.exceptions.AppRegistryNotReady: Apps aren't loaded yet.
ERROR 2024-05-16 18:09:34,192 signal 1 139942062172936 Signal handler <bound method DjangoFixup.on_import_modules of <celery.fixups.django.DjangoFixup object at 0x7f46ca6d2b10>> raised: ModuleNotFoundError("No module named 'rangefilter'")
Traceback (most recent call last):
  File "/usr/local/lib/python3.12/site-packages/celery/utils/dispatch/signal.py", line 276, in send
    response = receiver(signal=self, sender=sender, **named)
               ^^^^^^^^^^^^^^^^^^^^^^^^^^^^^^^^^^^^^^^^^^^^^
  File "/usr/local/lib/python3.12/site-packages/celery/fixups/django.py", line 100, in on_import_modules
    self.worker_fixup.validate_models()
  File "/usr/local/lib/python3.12/site-packages/celery/fixups/django.py", line 138, in validate_models
    self.django_setup()
  File "/usr/local/lib/python3.12/site-packages/celery/fixups/django.py", line 134, in django_setup
    django.setup()
  File "/usr/local/lib/python3.12/site-packages/django/__init__.py", line 24, in setup
    apps.populate(settings.INSTALLED_APPS)
  File "/usr/local/lib/python3.12/site-packages/django/apps/registry.py", line 91, in populate
    app_config = AppConfig.create(entry)
                 ^^^^^^^^^^^^^^^^^^^^^^^
  File "/usr/local/lib/python3.12/site-packages/django/apps/config.py", line 193, in create
    import_module(entry)
  File "/usr/local/lib/python3.12/importlib/__init__.py", line 90, in import_module
    return _bootstrap._gcd_import(name[level:], package, level)
           ^^^^^^^^^^^^^^^^^^^^^^^^^^^^^^^^^^^^^^^^^^^^^^^^^^^^
  File "<frozen importlib._bootstrap>", line 1387, in _gcd_import
  File "<frozen importlib._bootstrap>", line 1360, in _find_and_load
  File "<frozen importlib._bootstrap>", line 1324, in _find_and_load_unlocked
ModuleNotFoundError: No module named 'rangefilter'
ERROR 2024-05-16 18:09:34,194 signal 1 139942062172936 Signal handler <promise@0x7f46ca6dd950 --> <bound method Celery._autodiscover_tasks of <Celery eazyclass at 0x7f46ca6d29c0>>> raised: AppRegistryNotReady("Apps aren't loaded yet.")
Traceback (most recent call last):
  File "/usr/local/lib/python3.12/site-packages/celery/utils/dispatch/signal.py", line 276, in send
    response = receiver(signal=self, sender=sender, **named)
               ^^^^^^^^^^^^^^^^^^^^^^^^^^^^^^^^^^^^^^^^^^^^^
  File "/usr/local/lib/python3.12/site-packages/vine/promises.py", line 161, in __call__
    return self.throw()
           ^^^^^^^^^^^^
  File "/usr/local/lib/python3.12/site-packages/vine/promises.py", line 158, in __call__
    retval = fun(*final_args, **final_kwargs)
             ^^^^^^^^^^^^^^^^^^^^^^^^^^^^^^^^
  File "/usr/local/lib/python3.12/site-packages/celery/app/base.py", line 694, in _autodiscover_tasks
    return self._autodiscover_tasks_from_fixups(related_name)
           ^^^^^^^^^^^^^^^^^^^^^^^^^^^^^^^^^^^^^^^^^^^^^^^^^^
  File "/usr/local/lib/python3.12/site-packages/celery/app/base.py", line 706, in _autodiscover_tasks_from_fixups
    for pkg in fixup.autodiscover_tasks()
               ^^^^^^^^^^^^^^^^^^^^^^^^^^
  File "/usr/local/lib/python3.12/site-packages/celery/fixups/django.py", line 110, in autodiscover_tasks
    return [config.name for config in apps.get_app_configs()]
                                      ^^^^^^^^^^^^^^^^^^^^^^
  File "/usr/local/lib/python3.12/site-packages/django/apps/registry.py", line 147, in get_app_configs
    self.check_apps_ready()
  File "/usr/local/lib/python3.12/site-packages/django/apps/registry.py", line 138, in check_apps_ready
    raise AppRegistryNotReady("Apps aren't loaded yet.")
django.core.exceptions.AppRegistryNotReady: Apps aren't loaded yet.
ERROR 2024-05-16 18:10:34,314 signal 1 140089158712072 Signal handler <bound method DjangoFixup.on_import_modules of <celery.fixups.django.DjangoFixup object at 0x7f690a11aed0>> raised: ModuleNotFoundError("No module named 'rangefilter'")
Traceback (most recent call last):
  File "/usr/local/lib/python3.12/site-packages/celery/utils/dispatch/signal.py", line 276, in send
    response = receiver(signal=self, sender=sender, **named)
               ^^^^^^^^^^^^^^^^^^^^^^^^^^^^^^^^^^^^^^^^^^^^^
  File "/usr/local/lib/python3.12/site-packages/celery/fixups/django.py", line 100, in on_import_modules
    self.worker_fixup.validate_models()
  File "/usr/local/lib/python3.12/site-packages/celery/fixups/django.py", line 138, in validate_models
    self.django_setup()
  File "/usr/local/lib/python3.12/site-packages/celery/fixups/django.py", line 134, in django_setup
    django.setup()
  File "/usr/local/lib/python3.12/site-packages/django/__init__.py", line 24, in setup
    apps.populate(settings.INSTALLED_APPS)
  File "/usr/local/lib/python3.12/site-packages/django/apps/registry.py", line 91, in populate
    app_config = AppConfig.create(entry)
                 ^^^^^^^^^^^^^^^^^^^^^^^
  File "/usr/local/lib/python3.12/site-packages/django/apps/config.py", line 193, in create
    import_module(entry)
  File "/usr/local/lib/python3.12/importlib/__init__.py", line 90, in import_module
    return _bootstrap._gcd_import(name[level:], package, level)
           ^^^^^^^^^^^^^^^^^^^^^^^^^^^^^^^^^^^^^^^^^^^^^^^^^^^^
  File "<frozen importlib._bootstrap>", line 1387, in _gcd_import
  File "<frozen importlib._bootstrap>", line 1360, in _find_and_load
  File "<frozen importlib._bootstrap>", line 1324, in _find_and_load_unlocked
ModuleNotFoundError: No module named 'rangefilter'
ERROR 2024-05-16 18:10:34,315 signal 1 140089158712072 Signal handler <promise@0x7f690a125950 --> <bound method Celery._autodiscover_tasks of <Celery eazyclass at 0x7f690a11ae10>>> raised: AppRegistryNotReady("Apps aren't loaded yet.")
Traceback (most recent call last):
  File "/usr/local/lib/python3.12/site-packages/celery/utils/dispatch/signal.py", line 276, in send
    response = receiver(signal=self, sender=sender, **named)
               ^^^^^^^^^^^^^^^^^^^^^^^^^^^^^^^^^^^^^^^^^^^^^
  File "/usr/local/lib/python3.12/site-packages/vine/promises.py", line 161, in __call__
    return self.throw()
           ^^^^^^^^^^^^
  File "/usr/local/lib/python3.12/site-packages/vine/promises.py", line 158, in __call__
    retval = fun(*final_args, **final_kwargs)
             ^^^^^^^^^^^^^^^^^^^^^^^^^^^^^^^^
  File "/usr/local/lib/python3.12/site-packages/celery/app/base.py", line 694, in _autodiscover_tasks
    return self._autodiscover_tasks_from_fixups(related_name)
           ^^^^^^^^^^^^^^^^^^^^^^^^^^^^^^^^^^^^^^^^^^^^^^^^^^
  File "/usr/local/lib/python3.12/site-packages/celery/app/base.py", line 706, in _autodiscover_tasks_from_fixups
    for pkg in fixup.autodiscover_tasks()
               ^^^^^^^^^^^^^^^^^^^^^^^^^^
  File "/usr/local/lib/python3.12/site-packages/celery/fixups/django.py", line 110, in autodiscover_tasks
    return [config.name for config in apps.get_app_configs()]
                                      ^^^^^^^^^^^^^^^^^^^^^^
  File "/usr/local/lib/python3.12/site-packages/django/apps/registry.py", line 147, in get_app_configs
    self.check_apps_ready()
  File "/usr/local/lib/python3.12/site-packages/django/apps/registry.py", line 138, in check_apps_ready
    raise AppRegistryNotReady("Apps aren't loaded yet.")
django.core.exceptions.AppRegistryNotReady: Apps aren't loaded yet.
ERROR 2024-05-16 18:10:59,221 signal 1 140151699282696 Signal handler <bound method DjangoFixup.on_import_modules of <celery.fixups.django.DjangoFixup object at 0x7f7799c56b70>> raised: ModuleNotFoundError("No module named 'rangefilter'")
Traceback (most recent call last):
  File "/usr/local/lib/python3.12/site-packages/celery/utils/dispatch/signal.py", line 276, in send
    response = receiver(signal=self, sender=sender, **named)
               ^^^^^^^^^^^^^^^^^^^^^^^^^^^^^^^^^^^^^^^^^^^^^
  File "/usr/local/lib/python3.12/site-packages/celery/fixups/django.py", line 100, in on_import_modules
    self.worker_fixup.validate_models()
  File "/usr/local/lib/python3.12/site-packages/celery/fixups/django.py", line 138, in validate_models
    self.django_setup()
  File "/usr/local/lib/python3.12/site-packages/celery/fixups/django.py", line 134, in django_setup
    django.setup()
  File "/usr/local/lib/python3.12/site-packages/django/__init__.py", line 24, in setup
    apps.populate(settings.INSTALLED_APPS)
  File "/usr/local/lib/python3.12/site-packages/django/apps/registry.py", line 91, in populate
    app_config = AppConfig.create(entry)
                 ^^^^^^^^^^^^^^^^^^^^^^^
  File "/usr/local/lib/python3.12/site-packages/django/apps/config.py", line 193, in create
    import_module(entry)
  File "/usr/local/lib/python3.12/importlib/__init__.py", line 90, in import_module
    return _bootstrap._gcd_import(name[level:], package, level)
           ^^^^^^^^^^^^^^^^^^^^^^^^^^^^^^^^^^^^^^^^^^^^^^^^^^^^
  File "<frozen importlib._bootstrap>", line 1387, in _gcd_import
  File "<frozen importlib._bootstrap>", line 1360, in _find_and_load
  File "<frozen importlib._bootstrap>", line 1324, in _find_and_load_unlocked
ModuleNotFoundError: No module named 'rangefilter'
ERROR 2024-05-16 18:10:59,223 signal 1 140151699282696 Signal handler <promise@0x7f7799c61950 --> <bound method Celery._autodiscover_tasks of <Celery eazyclass at 0x7f7799fbc950>>> raised: AppRegistryNotReady("Apps aren't loaded yet.")
Traceback (most recent call last):
  File "/usr/local/lib/python3.12/site-packages/celery/utils/dispatch/signal.py", line 276, in send
    response = receiver(signal=self, sender=sender, **named)
               ^^^^^^^^^^^^^^^^^^^^^^^^^^^^^^^^^^^^^^^^^^^^^
  File "/usr/local/lib/python3.12/site-packages/vine/promises.py", line 161, in __call__
    return self.throw()
           ^^^^^^^^^^^^
  File "/usr/local/lib/python3.12/site-packages/vine/promises.py", line 158, in __call__
    retval = fun(*final_args, **final_kwargs)
             ^^^^^^^^^^^^^^^^^^^^^^^^^^^^^^^^
  File "/usr/local/lib/python3.12/site-packages/celery/app/base.py", line 694, in _autodiscover_tasks
    return self._autodiscover_tasks_from_fixups(related_name)
           ^^^^^^^^^^^^^^^^^^^^^^^^^^^^^^^^^^^^^^^^^^^^^^^^^^
  File "/usr/local/lib/python3.12/site-packages/celery/app/base.py", line 706, in _autodiscover_tasks_from_fixups
    for pkg in fixup.autodiscover_tasks()
               ^^^^^^^^^^^^^^^^^^^^^^^^^^
  File "/usr/local/lib/python3.12/site-packages/celery/fixups/django.py", line 110, in autodiscover_tasks
    return [config.name for config in apps.get_app_configs()]
                                      ^^^^^^^^^^^^^^^^^^^^^^
  File "/usr/local/lib/python3.12/site-packages/django/apps/registry.py", line 147, in get_app_configs
    self.check_apps_ready()
  File "/usr/local/lib/python3.12/site-packages/django/apps/registry.py", line 138, in check_apps_ready
    raise AppRegistryNotReady("Apps aren't loaded yet.")
django.core.exceptions.AppRegistryNotReady: Apps aren't loaded yet.
ERROR 2024-05-17 13:26:17,714 signal 27 139661740387128 Signal handler <promise@0x7f058abf4c30 --> <bound method Celery._autodiscover_tasks of <Celery eazyclass at 0x7f058ac357c0>>> raised: ImportError("cannot import name 'update_all_lessons' from 'scheduler.tasks.lessons_parser' (/app/scheduler/tasks/lessons_parser.py)")
Traceback (most recent call last):
  File "/usr/local/lib/python3.12/site-packages/celery/utils/dispatch/signal.py", line 276, in send
    response = receiver(signal=self, sender=sender, **named)
               ^^^^^^^^^^^^^^^^^^^^^^^^^^^^^^^^^^^^^^^^^^^^^
  File "/usr/local/lib/python3.12/site-packages/vine/promises.py", line 161, in __call__
    return self.throw()
           ^^^^^^^^^^^^
  File "/usr/local/lib/python3.12/site-packages/vine/promises.py", line 158, in __call__
    retval = fun(*final_args, **final_kwargs)
             ^^^^^^^^^^^^^^^^^^^^^^^^^^^^^^^^
  File "/usr/local/lib/python3.12/site-packages/celery/app/base.py", line 694, in _autodiscover_tasks
    return self._autodiscover_tasks_from_fixups(related_name)
           ^^^^^^^^^^^^^^^^^^^^^^^^^^^^^^^^^^^^^^^^^^^^^^^^^^
  File "/usr/local/lib/python3.12/site-packages/celery/app/base.py", line 703, in _autodiscover_tasks_from_fixups
    return self._autodiscover_tasks_from_names([
           ^^^^^^^^^^^^^^^^^^^^^^^^^^^^^^^^^^^^^
  File "/usr/local/lib/python3.12/site-packages/celery/app/base.py", line 698, in _autodiscover_tasks_from_names
    return self.loader.autodiscover_tasks(
           ^^^^^^^^^^^^^^^^^^^^^^^^^^^^^^^
  File "/usr/local/lib/python3.12/site-packages/celery/loaders/base.py", line 220, in autodiscover_tasks
    mod.__name__ for mod in autodiscover_tasks(packages or (),
                            ^^^^^^^^^^^^^^^^^^^^^^^^^^^^^^^^^^
  File "/usr/local/lib/python3.12/site-packages/celery/loaders/base.py", line 246, in autodiscover_tasks
    return [find_related_module(pkg, related_name) for pkg in packages]
            ^^^^^^^^^^^^^^^^^^^^^^^^^^^^^^^^^^^^^^
  File "/usr/local/lib/python3.12/site-packages/celery/loaders/base.py", line 270, in find_related_module
    return importlib.import_module(module_name)
           ^^^^^^^^^^^^^^^^^^^^^^^^^^^^^^^^^^^^
  File "/usr/local/lib/python3.12/importlib/__init__.py", line 90, in import_module
    return _bootstrap._gcd_import(name[level:], package, level)
           ^^^^^^^^^^^^^^^^^^^^^^^^^^^^^^^^^^^^^^^^^^^^^^^^^^^^
  File "<frozen importlib._bootstrap>", line 1387, in _gcd_import
  File "<frozen importlib._bootstrap>", line 1360, in _find_and_load
  File "<frozen importlib._bootstrap>", line 1331, in _find_and_load_unlocked
  File "<frozen importlib._bootstrap>", line 935, in _load_unlocked
  File "<frozen importlib._bootstrap_external>", line 995, in exec_module
  File "<frozen importlib._bootstrap>", line 488, in _call_with_frames_removed
  File "/app/scheduler/tasks/__init__.py", line 1, in <module>
    from .lessons_parser import update_all_lessons
ImportError: cannot import name 'update_all_lessons' from 'scheduler.tasks.lessons_parser' (/app/scheduler/tasks/lessons_parser.py)
ERROR 2024-05-17 13:26:46,035 signal 27 139661740387128 Signal handler <promise@0x7f058abf4c30 --> <bound method Celery._autodiscover_tasks of <Celery eazyclass at 0x7f058ac357c0>>> raised: ImportError("cannot import name 'update_all_lessons' from 'scheduler.tasks.lessons_parser' (/app/scheduler/tasks/lessons_parser.py)")
Traceback (most recent call last):
  File "/usr/local/lib/python3.12/site-packages/celery/utils/dispatch/signal.py", line 276, in send
    response = receiver(signal=self, sender=sender, **named)
               ^^^^^^^^^^^^^^^^^^^^^^^^^^^^^^^^^^^^^^^^^^^^^
  File "/usr/local/lib/python3.12/site-packages/vine/promises.py", line 161, in __call__
    return self.throw()
           ^^^^^^^^^^^^
  File "/usr/local/lib/python3.12/site-packages/vine/promises.py", line 158, in __call__
    retval = fun(*final_args, **final_kwargs)
             ^^^^^^^^^^^^^^^^^^^^^^^^^^^^^^^^
  File "/usr/local/lib/python3.12/site-packages/celery/app/base.py", line 694, in _autodiscover_tasks
    return self._autodiscover_tasks_from_fixups(related_name)
           ^^^^^^^^^^^^^^^^^^^^^^^^^^^^^^^^^^^^^^^^^^^^^^^^^^
  File "/usr/local/lib/python3.12/site-packages/celery/app/base.py", line 703, in _autodiscover_tasks_from_fixups
    return self._autodiscover_tasks_from_names([
           ^^^^^^^^^^^^^^^^^^^^^^^^^^^^^^^^^^^^^
  File "/usr/local/lib/python3.12/site-packages/celery/app/base.py", line 698, in _autodiscover_tasks_from_names
    return self.loader.autodiscover_tasks(
           ^^^^^^^^^^^^^^^^^^^^^^^^^^^^^^^
  File "/usr/local/lib/python3.12/site-packages/celery/loaders/base.py", line 220, in autodiscover_tasks
    mod.__name__ for mod in autodiscover_tasks(packages or (),
                            ^^^^^^^^^^^^^^^^^^^^^^^^^^^^^^^^^^
  File "/usr/local/lib/python3.12/site-packages/celery/loaders/base.py", line 246, in autodiscover_tasks
    return [find_related_module(pkg, related_name) for pkg in packages]
            ^^^^^^^^^^^^^^^^^^^^^^^^^^^^^^^^^^^^^^
  File "/usr/local/lib/python3.12/site-packages/celery/loaders/base.py", line 270, in find_related_module
    return importlib.import_module(module_name)
           ^^^^^^^^^^^^^^^^^^^^^^^^^^^^^^^^^^^^
  File "/usr/local/lib/python3.12/importlib/__init__.py", line 90, in import_module
    return _bootstrap._gcd_import(name[level:], package, level)
           ^^^^^^^^^^^^^^^^^^^^^^^^^^^^^^^^^^^^^^^^^^^^^^^^^^^^
  File "<frozen importlib._bootstrap>", line 1387, in _gcd_import
  File "<frozen importlib._bootstrap>", line 1360, in _find_and_load
  File "<frozen importlib._bootstrap>", line 1331, in _find_and_load_unlocked
  File "<frozen importlib._bootstrap>", line 935, in _load_unlocked
  File "<frozen importlib._bootstrap_external>", line 995, in exec_module
  File "<frozen importlib._bootstrap>", line 488, in _call_with_frames_removed
  File "/app/scheduler/tasks/__init__.py", line 1, in <module>
    from .lessons_parser import update_all_lessons
ImportError: cannot import name 'update_all_lessons' from 'scheduler.tasks.lessons_parser' (/app/scheduler/tasks/lessons_parser.py)
ERROR 2024-05-17 23:23:02,693 signal 53 140703913478968 Signal handler <promise@0x7ff8315c0910 --> <bound method Celery._autodiscover_tasks of <Celery eazyclass at 0x7ff83161b8c0>>> raised: NameError("name 'TIMEOUT_OTHER' is not defined")
Traceback (most recent call last):
  File "/usr/local/lib/python3.12/site-packages/celery/utils/dispatch/signal.py", line 276, in send
    response = receiver(signal=self, sender=sender, **named)
               ^^^^^^^^^^^^^^^^^^^^^^^^^^^^^^^^^^^^^^^^^^^^^
  File "/usr/local/lib/python3.12/site-packages/vine/promises.py", line 161, in __call__
    return self.throw()
           ^^^^^^^^^^^^
  File "/usr/local/lib/python3.12/site-packages/vine/promises.py", line 158, in __call__
    retval = fun(*final_args, **final_kwargs)
             ^^^^^^^^^^^^^^^^^^^^^^^^^^^^^^^^
  File "/usr/local/lib/python3.12/site-packages/celery/app/base.py", line 694, in _autodiscover_tasks
    return self._autodiscover_tasks_from_fixups(related_name)
           ^^^^^^^^^^^^^^^^^^^^^^^^^^^^^^^^^^^^^^^^^^^^^^^^^^
  File "/usr/local/lib/python3.12/site-packages/celery/app/base.py", line 703, in _autodiscover_tasks_from_fixups
    return self._autodiscover_tasks_from_names([
           ^^^^^^^^^^^^^^^^^^^^^^^^^^^^^^^^^^^^^
  File "/usr/local/lib/python3.12/site-packages/celery/app/base.py", line 698, in _autodiscover_tasks_from_names
    return self.loader.autodiscover_tasks(
           ^^^^^^^^^^^^^^^^^^^^^^^^^^^^^^^
  File "/usr/local/lib/python3.12/site-packages/celery/loaders/base.py", line 220, in autodiscover_tasks
    mod.__name__ for mod in autodiscover_tasks(packages or (),
                            ^^^^^^^^^^^^^^^^^^^^^^^^^^^^^^^^^^
  File "/usr/local/lib/python3.12/site-packages/celery/loaders/base.py", line 246, in autodiscover_tasks
    return [find_related_module(pkg, related_name) for pkg in packages]
            ^^^^^^^^^^^^^^^^^^^^^^^^^^^^^^^^^^^^^^
  File "/usr/local/lib/python3.12/site-packages/celery/loaders/base.py", line 270, in find_related_module
    return importlib.import_module(module_name)
           ^^^^^^^^^^^^^^^^^^^^^^^^^^^^^^^^^^^^
  File "/usr/local/lib/python3.12/importlib/__init__.py", line 90, in import_module
    return _bootstrap._gcd_import(name[level:], package, level)
           ^^^^^^^^^^^^^^^^^^^^^^^^^^^^^^^^^^^^^^^^^^^^^^^^^^^^
  File "<frozen importlib._bootstrap>", line 1387, in _gcd_import
  File "<frozen importlib._bootstrap>", line 1360, in _find_and_load
  File "<frozen importlib._bootstrap>", line 1331, in _find_and_load_unlocked
  File "<frozen importlib._bootstrap>", line 935, in _load_unlocked
  File "<frozen importlib._bootstrap_external>", line 995, in exec_module
  File "<frozen importlib._bootstrap>", line 488, in _call_with_frames_removed
  File "/app/scheduler/tasks/__init__.py", line 1, in <module>
    from .lessons_parser import update_schedule
  File "/app/scheduler/tasks/lessons_parser.py", line 103, in <module>
    def get_or_create_cached(model_class: Model, defaults: dict, timeout: int = TIMEOUT_OTHER) -> Model:
                                                                                ^^^^^^^^^^^^^
NameError: name 'TIMEOUT_OTHER' is not defined
ERROR 2024-05-20 15:45:48,033 db_query 37 139694515624712 Ошибка при синхронизации буфера уроков: relation "lesson" does not exist
LINE 3:                     INSERT INTO lesson (group_id, lesson_tim...
                                        ^

INFO 2024-05-20 17:14:34,830 db_query 27 139735766735624 Вставка новых уроков завершена успешно.
INFO 2024-05-20 17:14:34,833 db_query 27 139735766735624 Обновление измененных уроков завершено успешно.
ERROR 2024-05-20 17:14:34,835 db_query 27 139735766735624 Ошибка при синхронизации буфера уроков: relation "scheduler_lesson_time" does not exist
LINE 5:                     FROM scheduler_lesson_time lt
                                 ^

INFO 2024-05-20 17:19:06,522 db_query 28 139917417806600 Вставка новых уроков завершена успешно.
INFO 2024-05-20 17:19:06,524 db_query 28 139917417806600 Обновление измененных уроков завершено успешно.
ERROR 2024-05-20 17:19:06,525 db_query 28 139917417806600 Ошибка при синхронизации буфера уроков: invalid reference to FROM-clause entry for table "l"
LINE 6: ...           LEFT JOIN scheduler_lessonbuffer lb ON l.group_id...
                                                             ^
DETAIL:  There is an entry for table "l", but it cannot be referenced from this part of the query.

INFO 2024-05-20 17:31:23,171 db_query 29 139792523524872 Вставка новых уроков завершена успешно.
INFO 2024-05-20 17:31:23,173 db_query 29 139792523524872 Обновление измененных уроков завершено успешно.
ERROR 2024-05-20 17:31:23,175 db_query 29 139792523524872 Ошибка при синхронизации буфера уроков: relation "scheduler_lesson_time" does not exist
LINE 5:                     FROM scheduler_lesson_time lt
                                 ^

INFO 2024-05-20 17:37:38,899 db_query 30 140699545475848 Вставка новых уроков завершена успешно.
INFO 2024-05-20 17:37:38,902 db_query 30 140699545475848 Обновление измененных уроков завершено успешно.
ERROR 2024-05-20 17:37:38,904 db_query 30 140699545475848 Ошибка при синхронизации буфера уроков: invalid reference to FROM-clause entry for table "l"
LINE 6: ...           LEFT JOIN scheduler_lessonbuffer lb ON l.group_id...
                                                             ^
DETAIL:  There is an entry for table "l", but it cannot be referenced from this part of the query.

INFO 2024-05-20 17:41:40,897 db_query 31 140560259877640 Вставка новых уроков завершена успешно.
INFO 2024-05-20 17:41:40,899 db_query 31 140560259877640 Обновление измененных уроков завершено успешно.
ERROR 2024-05-20 17:41:40,900 db_query 31 140560259877640 Ошибка при синхронизации буфера уроков: invalid reference to FROM-clause entry for table "l"
LINE 6: ...           LEFT JOIN scheduler_lessonbuffer lb ON l.group_id...
                                                             ^
DETAIL:  There is an entry for table "l", but it cannot be referenced from this part of the query.

INFO 2024-05-20 18:39:12,357 db_query 32 140201173404424 Вставка новых уроков завершена успешно.
INFO 2024-05-20 18:39:12,360 db_query 32 140201173404424 Обновление измененных уроков завершено успешно.
ERROR 2024-05-20 18:39:12,362 db_query 32 140201173404424 Ошибка при синхронизации буфера уроков: invalid reference to FROM-clause entry for table "l"
LINE 6: ...           LEFT JOIN scheduler_lessonbuffer lb ON l.group_id...
                                                             ^
DETAIL:  There is an entry for table "l", but it cannot be referenced from this part of the query.

INFO 2024-05-20 18:42:45,531 db_query 33 139976012327688 Вставка новых уроков завершена успешно.
INFO 2024-05-20 18:42:45,534 db_query 33 139976012327688 Обновление измененных уроков завершено успешно.
ERROR 2024-05-20 18:42:45,535 db_query 33 139976012327688 Ошибка при синхронизации буфера уроков: syntax error at or near ")"
LINE 10:                 )
                         ^

INFO 2024-05-20 18:44:41,700 db_query 34 140426916080392 Вставка новых уроков завершена успешно.
INFO 2024-05-20 18:44:41,702 db_query 34 140426916080392 Обновление измененных уроков завершено успешно.
INFO 2024-05-20 18:44:41,707 db_query 34 140426916080392 Деактивация уроков завершена успешно.
INFO 2024-05-20 18:57:19,284 db_query 37 140539296701192 Вставка новых уроков завершена успешно: 0 шт
INFO 2024-05-20 18:57:19,288 db_query 37 140539296701192 Обновление измененных уроков завершено успешно: 1 шт
INFO 2024-05-20 18:57:19,291 db_query 37 140539296701192 Деактивация уроков завершена успешно: 0 шт
INFO 2024-05-20 19:02:48,189 db_query 43 139656917355272 Вставка новых уроков завершена успешно: 1 шт
INFO 2024-05-20 19:02:48,193 db_query 43 139656917355272 Обновление измененных уроков завершено успешно: 1 шт
INFO 2024-05-20 19:02:48,197 db_query 43 139656917355272 Деактивация уроков завершена успешно: 1 шт
INFO 2024-05-20 19:05:11,513 db_query 44 140690873346824 Вставка новых уроков завершена успешно: 0 шт
INFO 2024-05-20 19:05:11,516 db_query 44 140690873346824 Обновление измененных уроков завершено успешно: 1 шт
INFO 2024-05-20 19:05:11,518 db_query 44 140690873346824 Деактивация уроков завершена успешно: 1 шт
ERROR 2024-05-21 01:52:07,449 signal 17 140096735415096 Signal handler <promise@0x7f6ad2e0c910 --> <bound method Celery._autodiscover_tasks of <Celery eazyclass at 0x7f6ad2e46420>>> raised: ModuleNotFoundError("No module named 'db_query'")
Traceback (most recent call last):
  File "/usr/local/lib/python3.12/site-packages/celery/utils/dispatch/signal.py", line 276, in send
    response = receiver(signal=self, sender=sender, **named)
               ^^^^^^^^^^^^^^^^^^^^^^^^^^^^^^^^^^^^^^^^^^^^^
  File "/usr/local/lib/python3.12/site-packages/vine/promises.py", line 161, in __call__
    return self.throw()
           ^^^^^^^^^^^^
  File "/usr/local/lib/python3.12/site-packages/vine/promises.py", line 158, in __call__
    retval = fun(*final_args, **final_kwargs)
             ^^^^^^^^^^^^^^^^^^^^^^^^^^^^^^^^
  File "/usr/local/lib/python3.12/site-packages/celery/app/base.py", line 694, in _autodiscover_tasks
    return self._autodiscover_tasks_from_fixups(related_name)
           ^^^^^^^^^^^^^^^^^^^^^^^^^^^^^^^^^^^^^^^^^^^^^^^^^^
  File "/usr/local/lib/python3.12/site-packages/celery/app/base.py", line 703, in _autodiscover_tasks_from_fixups
    return self._autodiscover_tasks_from_names([
           ^^^^^^^^^^^^^^^^^^^^^^^^^^^^^^^^^^^^^
  File "/usr/local/lib/python3.12/site-packages/celery/app/base.py", line 698, in _autodiscover_tasks_from_names
    return self.loader.autodiscover_tasks(
           ^^^^^^^^^^^^^^^^^^^^^^^^^^^^^^^
  File "/usr/local/lib/python3.12/site-packages/celery/loaders/base.py", line 220, in autodiscover_tasks
    mod.__name__ for mod in autodiscover_tasks(packages or (),
                            ^^^^^^^^^^^^^^^^^^^^^^^^^^^^^^^^^^
  File "/usr/local/lib/python3.12/site-packages/celery/loaders/base.py", line 246, in autodiscover_tasks
    return [find_related_module(pkg, related_name) for pkg in packages]
            ^^^^^^^^^^^^^^^^^^^^^^^^^^^^^^^^^^^^^^
  File "/usr/local/lib/python3.12/site-packages/celery/loaders/base.py", line 278, in find_related_module
    raise e
  File "/usr/local/lib/python3.12/site-packages/celery/loaders/base.py", line 270, in find_related_module
    return importlib.import_module(module_name)
           ^^^^^^^^^^^^^^^^^^^^^^^^^^^^^^^^^^^^
  File "/usr/local/lib/python3.12/importlib/__init__.py", line 90, in import_module
    return _bootstrap._gcd_import(name[level:], package, level)
           ^^^^^^^^^^^^^^^^^^^^^^^^^^^^^^^^^^^^^^^^^^^^^^^^^^^^
  File "<frozen importlib._bootstrap>", line 1387, in _gcd_import
  File "<frozen importlib._bootstrap>", line 1360, in _find_and_load
  File "<frozen importlib._bootstrap>", line 1331, in _find_and_load_unlocked
  File "<frozen importlib._bootstrap>", line 935, in _load_unlocked
  File "<frozen importlib._bootstrap_external>", line 995, in exec_module
  File "<frozen importlib._bootstrap>", line 488, in _call_with_frames_removed
  File "/app/scheduler/tasks/__init__.py", line 1, in <module>
    from .schedule_parser import update_schedule
  File "/app/scheduler/tasks/schedule_parser.py", line 14, in <module>
    from db_query import synchronize_lessons
ModuleNotFoundError: No module named 'db_query'
ERROR 2024-05-21 01:53:01,102 signal 1 140378917968648 Signal handler <promise@0x7fac8066c7d0 --> <bound method Celery._autodiscover_tasks of <Celery eazyclass at 0x7fac80e2d130>>> raised: ModuleNotFoundError("No module named 'db_query'")
Traceback (most recent call last):
  File "/usr/local/lib/python3.12/site-packages/celery/utils/dispatch/signal.py", line 276, in send
    response = receiver(signal=self, sender=sender, **named)
               ^^^^^^^^^^^^^^^^^^^^^^^^^^^^^^^^^^^^^^^^^^^^^
  File "/usr/local/lib/python3.12/site-packages/vine/promises.py", line 161, in __call__
    return self.throw()
           ^^^^^^^^^^^^
  File "/usr/local/lib/python3.12/site-packages/vine/promises.py", line 158, in __call__
    retval = fun(*final_args, **final_kwargs)
             ^^^^^^^^^^^^^^^^^^^^^^^^^^^^^^^^
  File "/usr/local/lib/python3.12/site-packages/celery/app/base.py", line 694, in _autodiscover_tasks
    return self._autodiscover_tasks_from_fixups(related_name)
           ^^^^^^^^^^^^^^^^^^^^^^^^^^^^^^^^^^^^^^^^^^^^^^^^^^
  File "/usr/local/lib/python3.12/site-packages/celery/app/base.py", line 703, in _autodiscover_tasks_from_fixups
    return self._autodiscover_tasks_from_names([
           ^^^^^^^^^^^^^^^^^^^^^^^^^^^^^^^^^^^^^
  File "/usr/local/lib/python3.12/site-packages/celery/app/base.py", line 698, in _autodiscover_tasks_from_names
    return self.loader.autodiscover_tasks(
           ^^^^^^^^^^^^^^^^^^^^^^^^^^^^^^^
  File "/usr/local/lib/python3.12/site-packages/celery/loaders/base.py", line 220, in autodiscover_tasks
    mod.__name__ for mod in autodiscover_tasks(packages or (),
                            ^^^^^^^^^^^^^^^^^^^^^^^^^^^^^^^^^^
  File "/usr/local/lib/python3.12/site-packages/celery/loaders/base.py", line 246, in autodiscover_tasks
    return [find_related_module(pkg, related_name) for pkg in packages]
            ^^^^^^^^^^^^^^^^^^^^^^^^^^^^^^^^^^^^^^
  File "/usr/local/lib/python3.12/site-packages/celery/loaders/base.py", line 278, in find_related_module
    raise e
  File "/usr/local/lib/python3.12/site-packages/celery/loaders/base.py", line 270, in find_related_module
    return importlib.import_module(module_name)
           ^^^^^^^^^^^^^^^^^^^^^^^^^^^^^^^^^^^^
  File "/usr/local/lib/python3.12/importlib/__init__.py", line 90, in import_module
    return _bootstrap._gcd_import(name[level:], package, level)
           ^^^^^^^^^^^^^^^^^^^^^^^^^^^^^^^^^^^^^^^^^^^^^^^^^^^^
  File "<frozen importlib._bootstrap>", line 1387, in _gcd_import
  File "<frozen importlib._bootstrap>", line 1360, in _find_and_load
  File "<frozen importlib._bootstrap>", line 1331, in _find_and_load_unlocked
  File "<frozen importlib._bootstrap>", line 935, in _load_unlocked
  File "<frozen importlib._bootstrap_external>", line 995, in exec_module
  File "<frozen importlib._bootstrap>", line 488, in _call_with_frames_removed
  File "/app/scheduler/tasks/__init__.py", line 1, in <module>
    from .schedule_parser import update_schedule
  File "/app/scheduler/tasks/schedule_parser.py", line 14, in <module>
    from db_query import synchronize_lessons
ModuleNotFoundError: No module named 'db_query'
ERROR 2024-05-21 01:53:01,154 signal 1 140329536707336 Signal handler <promise@0x7fa1010987d0 --> <bound method Celery._autodiscover_tasks of <Celery eazyclass at 0x7fa10129c1d0>>> raised: ModuleNotFoundError("No module named 'db_query'")
Traceback (most recent call last):
  File "/usr/local/lib/python3.12/site-packages/celery/utils/dispatch/signal.py", line 276, in send
    response = receiver(signal=self, sender=sender, **named)
               ^^^^^^^^^^^^^^^^^^^^^^^^^^^^^^^^^^^^^^^^^^^^^
  File "/usr/local/lib/python3.12/site-packages/vine/promises.py", line 161, in __call__
    return self.throw()
           ^^^^^^^^^^^^
  File "/usr/local/lib/python3.12/site-packages/vine/promises.py", line 158, in __call__
    retval = fun(*final_args, **final_kwargs)
             ^^^^^^^^^^^^^^^^^^^^^^^^^^^^^^^^
  File "/usr/local/lib/python3.12/site-packages/celery/app/base.py", line 694, in _autodiscover_tasks
    return self._autodiscover_tasks_from_fixups(related_name)
           ^^^^^^^^^^^^^^^^^^^^^^^^^^^^^^^^^^^^^^^^^^^^^^^^^^
  File "/usr/local/lib/python3.12/site-packages/celery/app/base.py", line 703, in _autodiscover_tasks_from_fixups
    return self._autodiscover_tasks_from_names([
           ^^^^^^^^^^^^^^^^^^^^^^^^^^^^^^^^^^^^^
  File "/usr/local/lib/python3.12/site-packages/celery/app/base.py", line 698, in _autodiscover_tasks_from_names
    return self.loader.autodiscover_tasks(
           ^^^^^^^^^^^^^^^^^^^^^^^^^^^^^^^
  File "/usr/local/lib/python3.12/site-packages/celery/loaders/base.py", line 220, in autodiscover_tasks
    mod.__name__ for mod in autodiscover_tasks(packages or (),
                            ^^^^^^^^^^^^^^^^^^^^^^^^^^^^^^^^^^
  File "/usr/local/lib/python3.12/site-packages/celery/loaders/base.py", line 246, in autodiscover_tasks
    return [find_related_module(pkg, related_name) for pkg in packages]
            ^^^^^^^^^^^^^^^^^^^^^^^^^^^^^^^^^^^^^^
  File "/usr/local/lib/python3.12/site-packages/celery/loaders/base.py", line 278, in find_related_module
    raise e
  File "/usr/local/lib/python3.12/site-packages/celery/loaders/base.py", line 270, in find_related_module
    return importlib.import_module(module_name)
           ^^^^^^^^^^^^^^^^^^^^^^^^^^^^^^^^^^^^
  File "/usr/local/lib/python3.12/importlib/__init__.py", line 90, in import_module
    return _bootstrap._gcd_import(name[level:], package, level)
           ^^^^^^^^^^^^^^^^^^^^^^^^^^^^^^^^^^^^^^^^^^^^^^^^^^^^
  File "<frozen importlib._bootstrap>", line 1387, in _gcd_import
  File "<frozen importlib._bootstrap>", line 1360, in _find_and_load
  File "<frozen importlib._bootstrap>", line 1331, in _find_and_load_unlocked
  File "<frozen importlib._bootstrap>", line 935, in _load_unlocked
  File "<frozen importlib._bootstrap_external>", line 995, in exec_module
  File "<frozen importlib._bootstrap>", line 488, in _call_with_frames_removed
  File "/app/scheduler/tasks/__init__.py", line 1, in <module>
    from .schedule_parser import update_schedule
  File "/app/scheduler/tasks/schedule_parser.py", line 14, in <module>
    from db_query import synchronize_lessons
ModuleNotFoundError: No module named 'db_query'
ERROR 2024-05-21 01:53:09,654 signal 19 140259717569336 Signal handler <promise@0x7f90c5208910 --> <bound method Celery._autodiscover_tasks of <Celery eazyclass at 0x7f90c4c44950>>> raised: ModuleNotFoundError("No module named 'db_query'")
Traceback (most recent call last):
  File "/usr/local/lib/python3.12/site-packages/celery/utils/dispatch/signal.py", line 276, in send
    response = receiver(signal=self, sender=sender, **named)
               ^^^^^^^^^^^^^^^^^^^^^^^^^^^^^^^^^^^^^^^^^^^^^
  File "/usr/local/lib/python3.12/site-packages/vine/promises.py", line 161, in __call__
    return self.throw()
           ^^^^^^^^^^^^
  File "/usr/local/lib/python3.12/site-packages/vine/promises.py", line 158, in __call__
    retval = fun(*final_args, **final_kwargs)
             ^^^^^^^^^^^^^^^^^^^^^^^^^^^^^^^^
  File "/usr/local/lib/python3.12/site-packages/celery/app/base.py", line 694, in _autodiscover_tasks
    return self._autodiscover_tasks_from_fixups(related_name)
           ^^^^^^^^^^^^^^^^^^^^^^^^^^^^^^^^^^^^^^^^^^^^^^^^^^
  File "/usr/local/lib/python3.12/site-packages/celery/app/base.py", line 703, in _autodiscover_tasks_from_fixups
    return self._autodiscover_tasks_from_names([
           ^^^^^^^^^^^^^^^^^^^^^^^^^^^^^^^^^^^^^
  File "/usr/local/lib/python3.12/site-packages/celery/app/base.py", line 698, in _autodiscover_tasks_from_names
    return self.loader.autodiscover_tasks(
           ^^^^^^^^^^^^^^^^^^^^^^^^^^^^^^^
  File "/usr/local/lib/python3.12/site-packages/celery/loaders/base.py", line 220, in autodiscover_tasks
    mod.__name__ for mod in autodiscover_tasks(packages or (),
                            ^^^^^^^^^^^^^^^^^^^^^^^^^^^^^^^^^^
  File "/usr/local/lib/python3.12/site-packages/celery/loaders/base.py", line 246, in autodiscover_tasks
    return [find_related_module(pkg, related_name) for pkg in packages]
            ^^^^^^^^^^^^^^^^^^^^^^^^^^^^^^^^^^^^^^
  File "/usr/local/lib/python3.12/site-packages/celery/loaders/base.py", line 278, in find_related_module
    raise e
  File "/usr/local/lib/python3.12/site-packages/celery/loaders/base.py", line 270, in find_related_module
    return importlib.import_module(module_name)
           ^^^^^^^^^^^^^^^^^^^^^^^^^^^^^^^^^^^^
  File "/usr/local/lib/python3.12/importlib/__init__.py", line 90, in import_module
    return _bootstrap._gcd_import(name[level:], package, level)
           ^^^^^^^^^^^^^^^^^^^^^^^^^^^^^^^^^^^^^^^^^^^^^^^^^^^^
  File "<frozen importlib._bootstrap>", line 1387, in _gcd_import
  File "<frozen importlib._bootstrap>", line 1360, in _find_and_load
  File "<frozen importlib._bootstrap>", line 1331, in _find_and_load_unlocked
  File "<frozen importlib._bootstrap>", line 935, in _load_unlocked
  File "<frozen importlib._bootstrap_external>", line 995, in exec_module
  File "<frozen importlib._bootstrap>", line 488, in _call_with_frames_removed
  File "/app/scheduler/tasks/__init__.py", line 1, in <module>
    from .schedule_parser import update_schedule
  File "/app/scheduler/tasks/schedule_parser.py", line 14, in <module>
    from db_query import synchronize_lessons
ModuleNotFoundError: No module named 'db_query'
ERROR 2024-05-23 13:44:21,090 signal 1 139823436286728 Signal handler <bound method DjangoFixup.on_import_modules of <celery.fixups.django.DjangoFixup object at 0x7f2b2bc23860>> raised: ModuleNotFoundError("No module named 'rest_framework'")
Traceback (most recent call last):
  File "/usr/local/lib/python3.12/site-packages/celery/utils/dispatch/signal.py", line 276, in send
    response = receiver(signal=self, sender=sender, **named)
               ^^^^^^^^^^^^^^^^^^^^^^^^^^^^^^^^^^^^^^^^^^^^^
  File "/usr/local/lib/python3.12/site-packages/celery/fixups/django.py", line 100, in on_import_modules
    self.worker_fixup.validate_models()
  File "/usr/local/lib/python3.12/site-packages/celery/fixups/django.py", line 138, in validate_models
    self.django_setup()
  File "/usr/local/lib/python3.12/site-packages/celery/fixups/django.py", line 134, in django_setup
    django.setup()
  File "/usr/local/lib/python3.12/site-packages/django/__init__.py", line 24, in setup
    apps.populate(settings.INSTALLED_APPS)
  File "/usr/local/lib/python3.12/site-packages/django/apps/registry.py", line 91, in populate
    app_config = AppConfig.create(entry)
                 ^^^^^^^^^^^^^^^^^^^^^^^
  File "/usr/local/lib/python3.12/site-packages/django/apps/config.py", line 193, in create
    import_module(entry)
  File "/usr/local/lib/python3.12/importlib/__init__.py", line 90, in import_module
    return _bootstrap._gcd_import(name[level:], package, level)
           ^^^^^^^^^^^^^^^^^^^^^^^^^^^^^^^^^^^^^^^^^^^^^^^^^^^^
  File "<frozen importlib._bootstrap>", line 1387, in _gcd_import
  File "<frozen importlib._bootstrap>", line 1360, in _find_and_load
  File "<frozen importlib._bootstrap>", line 1324, in _find_and_load_unlocked
ModuleNotFoundError: No module named 'rest_framework'
ERROR 2024-05-23 13:44:21,096 signal 1 139823436286728 Signal handler <promise@0x7f2b2b1c8870 --> <bound method Celery._autodiscover_tasks of <Celery eazyclass at 0x7f2b2b3d6510>>> raised: AppRegistryNotReady("Apps aren't loaded yet.")
Traceback (most recent call last):
  File "/usr/local/lib/python3.12/site-packages/celery/utils/dispatch/signal.py", line 276, in send
    response = receiver(signal=self, sender=sender, **named)
               ^^^^^^^^^^^^^^^^^^^^^^^^^^^^^^^^^^^^^^^^^^^^^
  File "/usr/local/lib/python3.12/site-packages/vine/promises.py", line 161, in __call__
    return self.throw()
           ^^^^^^^^^^^^
  File "/usr/local/lib/python3.12/site-packages/vine/promises.py", line 158, in __call__
    retval = fun(*final_args, **final_kwargs)
             ^^^^^^^^^^^^^^^^^^^^^^^^^^^^^^^^
  File "/usr/local/lib/python3.12/site-packages/celery/app/base.py", line 694, in _autodiscover_tasks
    return self._autodiscover_tasks_from_fixups(related_name)
           ^^^^^^^^^^^^^^^^^^^^^^^^^^^^^^^^^^^^^^^^^^^^^^^^^^
  File "/usr/local/lib/python3.12/site-packages/celery/app/base.py", line 706, in _autodiscover_tasks_from_fixups
    for pkg in fixup.autodiscover_tasks()
               ^^^^^^^^^^^^^^^^^^^^^^^^^^
  File "/usr/local/lib/python3.12/site-packages/celery/fixups/django.py", line 110, in autodiscover_tasks
    return [config.name for config in apps.get_app_configs()]
                                      ^^^^^^^^^^^^^^^^^^^^^^
  File "/usr/local/lib/python3.12/site-packages/django/apps/registry.py", line 147, in get_app_configs
    self.check_apps_ready()
  File "/usr/local/lib/python3.12/site-packages/django/apps/registry.py", line 138, in check_apps_ready
    raise AppRegistryNotReady("Apps aren't loaded yet.")
django.core.exceptions.AppRegistryNotReady: Apps aren't loaded yet.
ERROR 2024-05-23 13:44:21,345 signal 1 139864944859912 Signal handler <bound method DjangoFixup.on_import_modules of <celery.fixups.django.DjangoFixup object at 0x7f34d5816cf0>> raised: ModuleNotFoundError("No module named 'rest_framework'")
Traceback (most recent call last):
  File "/usr/local/lib/python3.12/site-packages/celery/utils/dispatch/signal.py", line 276, in send
    response = receiver(signal=self, sender=sender, **named)
               ^^^^^^^^^^^^^^^^^^^^^^^^^^^^^^^^^^^^^^^^^^^^^
  File "/usr/local/lib/python3.12/site-packages/celery/fixups/django.py", line 100, in on_import_modules
    self.worker_fixup.validate_models()
  File "/usr/local/lib/python3.12/site-packages/celery/fixups/django.py", line 138, in validate_models
    self.django_setup()
  File "/usr/local/lib/python3.12/site-packages/celery/fixups/django.py", line 134, in django_setup
    django.setup()
  File "/usr/local/lib/python3.12/site-packages/django/__init__.py", line 24, in setup
    apps.populate(settings.INSTALLED_APPS)
  File "/usr/local/lib/python3.12/site-packages/django/apps/registry.py", line 91, in populate
    app_config = AppConfig.create(entry)
                 ^^^^^^^^^^^^^^^^^^^^^^^
  File "/usr/local/lib/python3.12/site-packages/django/apps/config.py", line 193, in create
    import_module(entry)
  File "/usr/local/lib/python3.12/importlib/__init__.py", line 90, in import_module
    return _bootstrap._gcd_import(name[level:], package, level)
           ^^^^^^^^^^^^^^^^^^^^^^^^^^^^^^^^^^^^^^^^^^^^^^^^^^^^
  File "<frozen importlib._bootstrap>", line 1387, in _gcd_import
  File "<frozen importlib._bootstrap>", line 1360, in _find_and_load
  File "<frozen importlib._bootstrap>", line 1324, in _find_and_load_unlocked
ModuleNotFoundError: No module named 'rest_framework'
ERROR 2024-05-23 13:44:21,347 signal 1 139864944859912 Signal handler <promise@0x7f34d5378870 --> <bound method Celery._autodiscover_tasks of <Celery eazyclass at 0x7f34d553a750>>> raised: AppRegistryNotReady("Apps aren't loaded yet.")
Traceback (most recent call last):
  File "/usr/local/lib/python3.12/site-packages/celery/utils/dispatch/signal.py", line 276, in send
    response = receiver(signal=self, sender=sender, **named)
               ^^^^^^^^^^^^^^^^^^^^^^^^^^^^^^^^^^^^^^^^^^^^^
  File "/usr/local/lib/python3.12/site-packages/vine/promises.py", line 161, in __call__
    return self.throw()
           ^^^^^^^^^^^^
  File "/usr/local/lib/python3.12/site-packages/vine/promises.py", line 158, in __call__
    retval = fun(*final_args, **final_kwargs)
             ^^^^^^^^^^^^^^^^^^^^^^^^^^^^^^^^
  File "/usr/local/lib/python3.12/site-packages/celery/app/base.py", line 694, in _autodiscover_tasks
    return self._autodiscover_tasks_from_fixups(related_name)
           ^^^^^^^^^^^^^^^^^^^^^^^^^^^^^^^^^^^^^^^^^^^^^^^^^^
  File "/usr/local/lib/python3.12/site-packages/celery/app/base.py", line 706, in _autodiscover_tasks_from_fixups
    for pkg in fixup.autodiscover_tasks()
               ^^^^^^^^^^^^^^^^^^^^^^^^^^
  File "/usr/local/lib/python3.12/site-packages/celery/fixups/django.py", line 110, in autodiscover_tasks
    return [config.name for config in apps.get_app_configs()]
                                      ^^^^^^^^^^^^^^^^^^^^^^
  File "/usr/local/lib/python3.12/site-packages/django/apps/registry.py", line 147, in get_app_configs
    self.check_apps_ready()
  File "/usr/local/lib/python3.12/site-packages/django/apps/registry.py", line 138, in check_apps_ready
    raise AppRegistryNotReady("Apps aren't loaded yet.")
django.core.exceptions.AppRegistryNotReady: Apps aren't loaded yet.
INFO 2024-05-23 21:50:52,544 command 1 139896229509928 Visit me at http://0.0.0.0:5555
INFO 2024-05-23 21:50:52,553 command 1 139896229509928 Broker: redis://redis:6379/0
INFO 2024-05-23 21:50:52,560 command 1 139896229509928 Registered tasks: 
['celery.accumulate',
 'celery.backend_cleanup',
 'celery.chain',
 'celery.chord',
 'celery.chord_unlock',
 'celery.chunks',
 'celery.group',
 'celery.map',
 'celery.starmap',
 'scheduler.tasks.group_parser.update_groups',
 'scheduler.tasks.schedule_parser.parse_group_data',
 'scheduler.tasks.schedule_parser.process_data_final',
 'scheduler.tasks.schedule_parser.send_group_notification',
 'scheduler.tasks.schedule_parser.send_notifications',
 'scheduler.tasks.schedule_parser.update_schedule',
 'scheduler.tasks.timetable_manager.fill_lesson_times',
 'scheduler.tasks.update_last_active.delete_inactive_records',
 'scheduler.tasks.update_last_active.update_last_active_records']
INFO 2024-05-23 21:50:52,567 mixins 1 139896132422456 Connected to redis://redis:6379/0
INFO 2024-05-23 22:11:06,979 timetable_manager 36 140595327064872 Расписание звонков заполнены на период 2024-05-22 - 2024-06-30.
INFO 2024-05-23 22:26:22,156 command 1 139896229509928 15 detected, shutting down
INFO 2024-05-23 22:26:30,166 command 1 139941936048936 Visit me at http://0.0.0.0:5555
INFO 2024-05-23 22:26:30,173 command 1 139941936048936 Broker: redis://redis:6379/0
INFO 2024-05-23 22:26:30,181 command 1 139941936048936 Registered tasks: 
['celery.accumulate',
 'celery.backend_cleanup',
 'celery.chain',
 'celery.chord',
 'celery.chord_unlock',
 'celery.chunks',
 'celery.group',
 'celery.map',
 'celery.starmap',
 'scheduler.tasks.group_parser.update_groups',
 'scheduler.tasks.schedule_parser.parse_group_data',
 'scheduler.tasks.schedule_parser.process_data_final',
 'scheduler.tasks.schedule_parser.send_group_notification',
 'scheduler.tasks.schedule_parser.send_notifications',
 'scheduler.tasks.schedule_parser.update_schedule',
 'scheduler.tasks.timetable_manager.fill_lesson_times',
 'scheduler.tasks.update_last_active.delete_inactive_records',
 'scheduler.tasks.update_last_active.update_last_active_records']
INFO 2024-05-23 22:26:30,190 mixins 1 139941838965560 Connected to redis://redis:6379/0
WARNING 2024-05-23 22:26:31,233 inspector 1 139941835782968 Inspect method registered failed
WARNING 2024-05-23 22:26:31,243 inspector 1 139941837904696 Inspect method stats failed
WARNING 2024-05-23 22:26:31,244 inspector 1 139941834722104 Inspect method scheduled failed
WARNING 2024-05-23 22:26:31,244 inspector 1 139941831539512 Inspect method revoked failed
WARNING 2024-05-23 22:26:31,245 inspector 1 139941833661240 Inspect method active failed
WARNING 2024-05-23 22:26:31,246 inspector 1 139941832600376 Inspect method reserved failed
WARNING 2024-05-23 22:26:31,246 inspector 1 139941830478648 Inspect method conf failed
WARNING 2024-05-23 22:26:31,249 inspector 1 139941836843832 Inspect method active_queues failed
INFO 2024-05-24 02:42:07,214 command 1 139941936048936 15 detected, shutting down
INFO 2024-05-24 02:42:52,308 command 1 140519101733672 Visit me at http://0.0.0.0:5555
INFO 2024-05-24 02:42:52,314 command 1 140519101733672 Broker: redis://redis:6379/0
INFO 2024-05-24 02:42:52,322 command 1 140519101733672 Registered tasks: 
['celery.accumulate',
 'celery.backend_cleanup',
 'celery.chain',
 'celery.chord',
 'celery.chord_unlock',
 'celery.chunks',
 'celery.group',
 'celery.map',
 'celery.starmap',
 'scheduler.tasks.group_parser.update_groups',
 'scheduler.tasks.schedule_parser.parse_group_data',
 'scheduler.tasks.schedule_parser.process_data_final',
 'scheduler.tasks.schedule_parser.send_group_notification',
 'scheduler.tasks.schedule_parser.send_notifications',
 'scheduler.tasks.schedule_parser.update_schedule',
 'scheduler.tasks.timetable_manager.fill_lesson_times',
 'scheduler.tasks.update_last_active.delete_inactive_records',
 'scheduler.tasks.update_last_active.update_last_active_records']
INFO 2024-05-24 02:42:52,330 mixins 1 140519004646200 Connected to redis://redis:6379/0
WARNING 2024-05-24 02:42:53,370 inspector 1 140518998281016 Inspect method reserved failed
WARNING 2024-05-24 02:42:53,374 inspector 1 140519001463608 Inspect method registered failed
WARNING 2024-05-24 02:42:53,378 inspector 1 140519003585336 Inspect method stats failed
WARNING 2024-05-24 02:42:53,379 inspector 1 140518999341880 Inspect method active failed
WARNING 2024-05-24 02:42:53,381 inspector 1 140518996159288 Inspect method conf failed
WARNING 2024-05-24 02:42:53,381 inspector 1 140518997220152 Inspect method revoked failed
WARNING 2024-05-24 02:42:53,382 inspector 1 140519002524472 Inspect method active_queues failed
WARNING 2024-05-24 02:42:53,382 inspector 1 140519000402744 Inspect method scheduled failed
INFO 2024-05-24 02:57:26,811 command 1 140519101733672 15 detected, shutting down
INFO 2024-05-24 02:57:33,461 command 1 139718168435496 Visit me at http://0.0.0.0:5555
INFO 2024-05-24 02:57:33,469 command 1 139718168435496 Broker: redis://redis:6379/0
INFO 2024-05-24 02:57:33,479 command 1 139718168435496 Registered tasks: 
['celery.accumulate',
 'celery.backend_cleanup',
 'celery.chain',
 'celery.chord',
 'celery.chord_unlock',
 'celery.chunks',
 'celery.group',
 'celery.map',
 'celery.starmap',
 'scheduler.tasks.group_parser.update_groups',
 'scheduler.tasks.schedule_parser.parse_group_data',
 'scheduler.tasks.schedule_parser.process_data_final',
 'scheduler.tasks.schedule_parser.send_group_notification',
 'scheduler.tasks.schedule_parser.send_notifications',
 'scheduler.tasks.schedule_parser.update_schedule',
 'scheduler.tasks.timetable_manager.fill_lesson_times',
 'scheduler.tasks.update_last_active.delete_inactive_records',
 'scheduler.tasks.update_last_active.update_last_active_records']
INFO 2024-05-24 02:57:33,487 mixins 1 139718071360312 Connected to redis://redis:6379/0
WARNING 2024-05-24 02:57:34,536 inspector 1 139718069238584 Inspect method active_queues failed
WARNING 2024-05-24 02:57:34,543 inspector 1 139718062873400 Inspect method conf failed
WARNING 2024-05-24 02:57:34,544 inspector 1 139718068177720 Inspect method registered failed
WARNING 2024-05-24 02:57:34,545 inspector 1 139718070299448 Inspect method stats failed
WARNING 2024-05-24 02:57:34,547 inspector 1 139718064995128 Inspect method reserved failed
WARNING 2024-05-24 02:57:34,549 inspector 1 139718063934264 Inspect method revoked failed
WARNING 2024-05-24 02:57:34,550 inspector 1 139718066055992 Inspect method active failed
WARNING 2024-05-24 02:57:34,551 inspector 1 139718067116856 Inspect method scheduled failed
INFO 2024-05-25 12:53:51,476 command 1 139718168435496 15 detected, shutting down
INFO 2024-05-25 12:54:00,881 command 1 140213852707624 Visit me at http://0.0.0.0:5555
INFO 2024-05-25 12:54:00,895 command 1 140213852707624 Broker: redis://redis:6379/0
INFO 2024-05-25 12:54:00,903 command 1 140213852707624 Registered tasks: 
['celery.accumulate',
 'celery.backend_cleanup',
 'celery.chain',
 'celery.chord',
 'celery.chord_unlock',
 'celery.chunks',
 'celery.group',
 'celery.map',
 'celery.starmap',
 'scheduler.tasks.group_parser.deactivate_all_groups',
 'scheduler.tasks.group_parser.update_groups',
 'scheduler.tasks.schedule_parser.parse_group_data',
 'scheduler.tasks.schedule_parser.process_data_final',
 'scheduler.tasks.schedule_parser.send_group_notification',
 'scheduler.tasks.schedule_parser.send_notifications',
 'scheduler.tasks.schedule_parser.update_schedule',
 'scheduler.tasks.timetable_manager.fill_lesson_times',
 'scheduler.tasks.update_last_active.delete_inactive_records',
 'scheduler.tasks.update_last_active.update_last_active_records']
INFO 2024-05-25 12:54:00,913 mixins 1 140213758069560 Connected to redis://redis:6379/0
WARNING 2024-05-25 12:54:01,959 inspector 1 140213755947832 Inspect method active_queues failed
WARNING 2024-05-25 12:54:01,968 inspector 1 140213750643512 Inspect method revoked failed
WARNING 2024-05-25 12:54:01,969 inspector 1 140213753826104 Inspect method scheduled failed
WARNING 2024-05-25 12:54:01,970 inspector 1 140213751704376 Inspect method reserved failed
WARNING 2024-05-25 12:54:01,971 inspector 1 140213752765240 Inspect method active failed
WARNING 2024-05-25 12:54:01,975 inspector 1 140213754886968 Inspect method registered failed
WARNING 2024-05-25 12:54:01,976 inspector 1 140213749582648 Inspect method conf failed
WARNING 2024-05-25 12:54:01,976 inspector 1 140213757008696 Inspect method stats failed
INFO 2024-05-25 23:48:25,257 command 1 140213852707624 15 detected, shutting down
