ERROR 2024-05-15 21:20:35,897 signal 1 140395638188808 Signal handler <promise@0x7fb065ab9950 --> <bound method Celery._autodiscover_tasks of <Celery eazyclass at 0x7fb065ab2ba0>>> raised: ModuleNotFoundError("No module named 'scheduler.tasks.models'")
Traceback (most recent call last):
  File "/usr/local/lib/python3.12/site-packages/celery/utils/dispatch/signal.py", line 276, in send
    response = receiver(signal=self, sender=sender, **named)
               ^^^^^^^^^^^^^^^^^^^^^^^^^^^^^^^^^^^^^^^^^^^^^
  File "/usr/local/lib/python3.12/site-packages/vine/promises.py", line 161, in __call__
    return self.throw()
           ^^^^^^^^^^^^
  File "/usr/local/lib/python3.12/site-packages/vine/promises.py", line 158, in __call__
    retval = fun(*final_args, **final_kwargs)
             ^^^^^^^^^^^^^^^^^^^^^^^^^^^^^^^^
  File "/usr/local/lib/python3.12/site-packages/celery/app/base.py", line 694, in _autodiscover_tasks
    return self._autodiscover_tasks_from_fixups(related_name)
           ^^^^^^^^^^^^^^^^^^^^^^^^^^^^^^^^^^^^^^^^^^^^^^^^^^
  File "/usr/local/lib/python3.12/site-packages/celery/app/base.py", line 703, in _autodiscover_tasks_from_fixups
    return self._autodiscover_tasks_from_names([
           ^^^^^^^^^^^^^^^^^^^^^^^^^^^^^^^^^^^^^
  File "/usr/local/lib/python3.12/site-packages/celery/app/base.py", line 698, in _autodiscover_tasks_from_names
    return self.loader.autodiscover_tasks(
           ^^^^^^^^^^^^^^^^^^^^^^^^^^^^^^^
  File "/usr/local/lib/python3.12/site-packages/celery/loaders/base.py", line 220, in autodiscover_tasks
    mod.__name__ for mod in autodiscover_tasks(packages or (),
                            ^^^^^^^^^^^^^^^^^^^^^^^^^^^^^^^^^^
  File "/usr/local/lib/python3.12/site-packages/celery/loaders/base.py", line 246, in autodiscover_tasks
    return [find_related_module(pkg, related_name) for pkg in packages]
            ^^^^^^^^^^^^^^^^^^^^^^^^^^^^^^^^^^^^^^
  File "/usr/local/lib/python3.12/site-packages/celery/loaders/base.py", line 278, in find_related_module
    raise e
  File "/usr/local/lib/python3.12/site-packages/celery/loaders/base.py", line 270, in find_related_module
    return importlib.import_module(module_name)
           ^^^^^^^^^^^^^^^^^^^^^^^^^^^^^^^^^^^^
  File "/usr/local/lib/python3.12/importlib/__init__.py", line 90, in import_module
    return _bootstrap._gcd_import(name[level:], package, level)
           ^^^^^^^^^^^^^^^^^^^^^^^^^^^^^^^^^^^^^^^^^^^^^^^^^^^^
  File "<frozen importlib._bootstrap>", line 1387, in _gcd_import
  File "<frozen importlib._bootstrap>", line 1360, in _find_and_load
  File "<frozen importlib._bootstrap>", line 1331, in _find_and_load_unlocked
  File "<frozen importlib._bootstrap>", line 935, in _load_unlocked
  File "<frozen importlib._bootstrap_external>", line 995, in exec_module
  File "<frozen importlib._bootstrap>", line 488, in _call_with_frames_removed
  File "/app/scheduler/tasks/__init__.py", line 2, in <module>
    from .group_parser import update_groups
  File "/app/scheduler/tasks/group_parser.py", line 10, in <module>
    from .models import Faculty, Group
ModuleNotFoundError: No module named 'scheduler.tasks.models'
ERROR 2024-05-15 21:20:35,898 signal 1 140595425463048 Signal handler <promise@0x7fdee9e9d950 --> <bound method Celery._autodiscover_tasks of <Celery eazyclass at 0x7fdeea25ec60>>> raised: ModuleNotFoundError("No module named 'scheduler.tasks.models'")
Traceback (most recent call last):
  File "/usr/local/lib/python3.12/site-packages/celery/utils/dispatch/signal.py", line 276, in send
    response = receiver(signal=self, sender=sender, **named)
               ^^^^^^^^^^^^^^^^^^^^^^^^^^^^^^^^^^^^^^^^^^^^^
  File "/usr/local/lib/python3.12/site-packages/vine/promises.py", line 161, in __call__
    return self.throw()
           ^^^^^^^^^^^^
  File "/usr/local/lib/python3.12/site-packages/vine/promises.py", line 158, in __call__
    retval = fun(*final_args, **final_kwargs)
             ^^^^^^^^^^^^^^^^^^^^^^^^^^^^^^^^
  File "/usr/local/lib/python3.12/site-packages/celery/app/base.py", line 694, in _autodiscover_tasks
    return self._autodiscover_tasks_from_fixups(related_name)
           ^^^^^^^^^^^^^^^^^^^^^^^^^^^^^^^^^^^^^^^^^^^^^^^^^^
  File "/usr/local/lib/python3.12/site-packages/celery/app/base.py", line 703, in _autodiscover_tasks_from_fixups
    return self._autodiscover_tasks_from_names([
           ^^^^^^^^^^^^^^^^^^^^^^^^^^^^^^^^^^^^^
  File "/usr/local/lib/python3.12/site-packages/celery/app/base.py", line 698, in _autodiscover_tasks_from_names
    return self.loader.autodiscover_tasks(
           ^^^^^^^^^^^^^^^^^^^^^^^^^^^^^^^
  File "/usr/local/lib/python3.12/site-packages/celery/loaders/base.py", line 220, in autodiscover_tasks
    mod.__name__ for mod in autodiscover_tasks(packages or (),
                            ^^^^^^^^^^^^^^^^^^^^^^^^^^^^^^^^^^
  File "/usr/local/lib/python3.12/site-packages/celery/loaders/base.py", line 246, in autodiscover_tasks
    return [find_related_module(pkg, related_name) for pkg in packages]
            ^^^^^^^^^^^^^^^^^^^^^^^^^^^^^^^^^^^^^^
  File "/usr/local/lib/python3.12/site-packages/celery/loaders/base.py", line 278, in find_related_module
    raise e
  File "/usr/local/lib/python3.12/site-packages/celery/loaders/base.py", line 270, in find_related_module
    return importlib.import_module(module_name)
           ^^^^^^^^^^^^^^^^^^^^^^^^^^^^^^^^^^^^
  File "/usr/local/lib/python3.12/importlib/__init__.py", line 90, in import_module
    return _bootstrap._gcd_import(name[level:], package, level)
           ^^^^^^^^^^^^^^^^^^^^^^^^^^^^^^^^^^^^^^^^^^^^^^^^^^^^
  File "<frozen importlib._bootstrap>", line 1387, in _gcd_import
  File "<frozen importlib._bootstrap>", line 1360, in _find_and_load
  File "<frozen importlib._bootstrap>", line 1331, in _find_and_load_unlocked
  File "<frozen importlib._bootstrap>", line 935, in _load_unlocked
  File "<frozen importlib._bootstrap_external>", line 995, in exec_module
  File "<frozen importlib._bootstrap>", line 488, in _call_with_frames_removed
  File "/app/scheduler/tasks/__init__.py", line 2, in <module>
    from .group_parser import update_groups
  File "/app/scheduler/tasks/group_parser.py", line 10, in <module>
    from .models import Faculty, Group
ModuleNotFoundError: No module named 'scheduler.tasks.models'
ERROR 2024-05-15 21:22:00,258 signal 17 140140669401912 Signal handler <promise@0x7f750d340c30 --> <bound method Celery._autodiscover_tasks of <Celery eazyclass at 0x7f750d36f2f0>>> raised: ModuleNotFoundError("No module named 'scheduler.tasks.models'")
Traceback (most recent call last):
  File "/usr/local/lib/python3.12/site-packages/celery/utils/dispatch/signal.py", line 276, in send
    response = receiver(signal=self, sender=sender, **named)
               ^^^^^^^^^^^^^^^^^^^^^^^^^^^^^^^^^^^^^^^^^^^^^
  File "/usr/local/lib/python3.12/site-packages/vine/promises.py", line 161, in __call__
    return self.throw()
           ^^^^^^^^^^^^
  File "/usr/local/lib/python3.12/site-packages/vine/promises.py", line 158, in __call__
    retval = fun(*final_args, **final_kwargs)
             ^^^^^^^^^^^^^^^^^^^^^^^^^^^^^^^^
  File "/usr/local/lib/python3.12/site-packages/celery/app/base.py", line 694, in _autodiscover_tasks
    return self._autodiscover_tasks_from_fixups(related_name)
           ^^^^^^^^^^^^^^^^^^^^^^^^^^^^^^^^^^^^^^^^^^^^^^^^^^
  File "/usr/local/lib/python3.12/site-packages/celery/app/base.py", line 703, in _autodiscover_tasks_from_fixups
    return self._autodiscover_tasks_from_names([
           ^^^^^^^^^^^^^^^^^^^^^^^^^^^^^^^^^^^^^
  File "/usr/local/lib/python3.12/site-packages/celery/app/base.py", line 698, in _autodiscover_tasks_from_names
    return self.loader.autodiscover_tasks(
           ^^^^^^^^^^^^^^^^^^^^^^^^^^^^^^^
  File "/usr/local/lib/python3.12/site-packages/celery/loaders/base.py", line 220, in autodiscover_tasks
    mod.__name__ for mod in autodiscover_tasks(packages or (),
                            ^^^^^^^^^^^^^^^^^^^^^^^^^^^^^^^^^^
  File "/usr/local/lib/python3.12/site-packages/celery/loaders/base.py", line 246, in autodiscover_tasks
    return [find_related_module(pkg, related_name) for pkg in packages]
            ^^^^^^^^^^^^^^^^^^^^^^^^^^^^^^^^^^^^^^
  File "/usr/local/lib/python3.12/site-packages/celery/loaders/base.py", line 278, in find_related_module
    raise e
  File "/usr/local/lib/python3.12/site-packages/celery/loaders/base.py", line 270, in find_related_module
    return importlib.import_module(module_name)
           ^^^^^^^^^^^^^^^^^^^^^^^^^^^^^^^^^^^^
  File "/usr/local/lib/python3.12/importlib/__init__.py", line 90, in import_module
    return _bootstrap._gcd_import(name[level:], package, level)
           ^^^^^^^^^^^^^^^^^^^^^^^^^^^^^^^^^^^^^^^^^^^^^^^^^^^^
  File "<frozen importlib._bootstrap>", line 1387, in _gcd_import
  File "<frozen importlib._bootstrap>", line 1360, in _find_and_load
  File "<frozen importlib._bootstrap>", line 1331, in _find_and_load_unlocked
  File "<frozen importlib._bootstrap>", line 935, in _load_unlocked
  File "<frozen importlib._bootstrap_external>", line 995, in exec_module
  File "<frozen importlib._bootstrap>", line 488, in _call_with_frames_removed
  File "/app/scheduler/tasks/__init__.py", line 2, in <module>
    from .group_parser import update_groups
  File "/app/scheduler/tasks/group_parser.py", line 10, in <module>
    from .models import Faculty, Group
ModuleNotFoundError: No module named 'scheduler.tasks.models'
ERROR 2024-05-15 21:23:18,165 signal 17 140140669401912 Signal handler <promise@0x7f750d340c30 --> <bound method Celery._autodiscover_tasks of <Celery eazyclass at 0x7f750d36f2f0>>> raised: ModuleNotFoundError("No module named 'timetable_manager'")
Traceback (most recent call last):
  File "/usr/local/lib/python3.12/site-packages/celery/utils/dispatch/signal.py", line 276, in send
    response = receiver(signal=self, sender=sender, **named)
               ^^^^^^^^^^^^^^^^^^^^^^^^^^^^^^^^^^^^^^^^^^^^^
  File "/usr/local/lib/python3.12/site-packages/vine/promises.py", line 161, in __call__
    return self.throw()
           ^^^^^^^^^^^^
  File "/usr/local/lib/python3.12/site-packages/vine/promises.py", line 158, in __call__
    retval = fun(*final_args, **final_kwargs)
             ^^^^^^^^^^^^^^^^^^^^^^^^^^^^^^^^
  File "/usr/local/lib/python3.12/site-packages/celery/app/base.py", line 694, in _autodiscover_tasks
    return self._autodiscover_tasks_from_fixups(related_name)
           ^^^^^^^^^^^^^^^^^^^^^^^^^^^^^^^^^^^^^^^^^^^^^^^^^^
  File "/usr/local/lib/python3.12/site-packages/celery/app/base.py", line 703, in _autodiscover_tasks_from_fixups
    return self._autodiscover_tasks_from_names([
           ^^^^^^^^^^^^^^^^^^^^^^^^^^^^^^^^^^^^^
  File "/usr/local/lib/python3.12/site-packages/celery/app/base.py", line 698, in _autodiscover_tasks_from_names
    return self.loader.autodiscover_tasks(
           ^^^^^^^^^^^^^^^^^^^^^^^^^^^^^^^
  File "/usr/local/lib/python3.12/site-packages/celery/loaders/base.py", line 220, in autodiscover_tasks
    mod.__name__ for mod in autodiscover_tasks(packages or (),
                            ^^^^^^^^^^^^^^^^^^^^^^^^^^^^^^^^^^
  File "/usr/local/lib/python3.12/site-packages/celery/loaders/base.py", line 246, in autodiscover_tasks
    return [find_related_module(pkg, related_name) for pkg in packages]
            ^^^^^^^^^^^^^^^^^^^^^^^^^^^^^^^^^^^^^^
  File "/usr/local/lib/python3.12/site-packages/celery/loaders/base.py", line 278, in find_related_module
    raise e
  File "/usr/local/lib/python3.12/site-packages/celery/loaders/base.py", line 270, in find_related_module
    return importlib.import_module(module_name)
           ^^^^^^^^^^^^^^^^^^^^^^^^^^^^^^^^^^^^
  File "/usr/local/lib/python3.12/importlib/__init__.py", line 90, in import_module
    return _bootstrap._gcd_import(name[level:], package, level)
           ^^^^^^^^^^^^^^^^^^^^^^^^^^^^^^^^^^^^^^^^^^^^^^^^^^^^
  File "<frozen importlib._bootstrap>", line 1387, in _gcd_import
  File "<frozen importlib._bootstrap>", line 1360, in _find_and_load
  File "<frozen importlib._bootstrap>", line 1331, in _find_and_load_unlocked
  File "<frozen importlib._bootstrap>", line 935, in _load_unlocked
  File "<frozen importlib._bootstrap_external>", line 995, in exec_module
  File "<frozen importlib._bootstrap>", line 488, in _call_with_frames_removed
  File "/app/scheduler/tasks/__init__.py", line 3, in <module>
    from timetable_manager import fill_lesson_times
ModuleNotFoundError: No module named 'timetable_manager'
ERROR 2024-05-16 13:42:25,311 signal 1 140254065072904 Signal handler <bound method DjangoFixup.on_import_modules of <celery.fixups.django.DjangoFixup object at 0x7f8f6fb5eff0>> raised: ImproperlyConfigured("The included URLconf '<module 'scheduler.urls' from '/app/scheduler/urls.py'>' does not appear to have any patterns in it. If you see the 'urlpatterns' variable with valid patterns in the file then the issue is probably caused by a circular import.")
Traceback (most recent call last):
  File "/usr/local/lib/python3.12/site-packages/django/urls/resolvers.py", line 740, in url_patterns
    iter(patterns)
TypeError: 'module' object is not iterable

The above exception was the direct cause of the following exception:

Traceback (most recent call last):
  File "/usr/local/lib/python3.12/site-packages/celery/utils/dispatch/signal.py", line 276, in send
    response = receiver(signal=self, sender=sender, **named)
               ^^^^^^^^^^^^^^^^^^^^^^^^^^^^^^^^^^^^^^^^^^^^^
  File "/usr/local/lib/python3.12/site-packages/celery/fixups/django.py", line 100, in on_import_modules
    self.worker_fixup.validate_models()
  File "/usr/local/lib/python3.12/site-packages/celery/fixups/django.py", line 140, in validate_models
    run_checks()
  File "/usr/local/lib/python3.12/site-packages/django/core/checks/registry.py", line 88, in run_checks
    new_errors = check(app_configs=app_configs, databases=databases)
                 ^^^^^^^^^^^^^^^^^^^^^^^^^^^^^^^^^^^^^^^^^^^^^^^^^^^
  File "/usr/local/lib/python3.12/site-packages/django/core/checks/urls.py", line 42, in check_url_namespaces_unique
    all_namespaces = _load_all_namespaces(resolver)
                     ^^^^^^^^^^^^^^^^^^^^^^^^^^^^^^
  File "/usr/local/lib/python3.12/site-packages/django/core/checks/urls.py", line 72, in _load_all_namespaces
    namespaces.extend(_load_all_namespaces(pattern, current))
                      ^^^^^^^^^^^^^^^^^^^^^^^^^^^^^^^^^^^^^^
  File "/usr/local/lib/python3.12/site-packages/django/core/checks/urls.py", line 61, in _load_all_namespaces
    url_patterns = getattr(resolver, "url_patterns", [])
                   ^^^^^^^^^^^^^^^^^^^^^^^^^^^^^^^^^^^^^
  File "/usr/local/lib/python3.12/site-packages/django/utils/functional.py", line 47, in __get__
    res = instance.__dict__[self.name] = self.func(instance)
                                         ^^^^^^^^^^^^^^^^^^^
  File "/usr/local/lib/python3.12/site-packages/django/urls/resolvers.py", line 748, in url_patterns
    raise ImproperlyConfigured(msg.format(name=self.urlconf_name)) from e
django.core.exceptions.ImproperlyConfigured: The included URLconf '<module 'scheduler.urls' from '/app/scheduler/urls.py'>' does not appear to have any patterns in it. If you see the 'urlpatterns' variable with valid patterns in the file then the issue is probably caused by a circular import.
ERROR 2024-05-16 13:42:26,157 signal 1 140412589984520 Signal handler <bound method DjangoFixup.on_import_modules of <celery.fixups.django.DjangoFixup object at 0x7fb458116b40>> raised: ImproperlyConfigured("The included URLconf '<module 'scheduler.urls' from '/app/scheduler/urls.py'>' does not appear to have any patterns in it. If you see the 'urlpatterns' variable with valid patterns in the file then the issue is probably caused by a circular import.")
Traceback (most recent call last):
  File "/usr/local/lib/python3.12/site-packages/django/urls/resolvers.py", line 740, in url_patterns
    iter(patterns)
TypeError: 'module' object is not iterable

The above exception was the direct cause of the following exception:

Traceback (most recent call last):
  File "/usr/local/lib/python3.12/site-packages/celery/utils/dispatch/signal.py", line 276, in send
    response = receiver(signal=self, sender=sender, **named)
               ^^^^^^^^^^^^^^^^^^^^^^^^^^^^^^^^^^^^^^^^^^^^^
  File "/usr/local/lib/python3.12/site-packages/celery/fixups/django.py", line 100, in on_import_modules
    self.worker_fixup.validate_models()
  File "/usr/local/lib/python3.12/site-packages/celery/fixups/django.py", line 140, in validate_models
    run_checks()
  File "/usr/local/lib/python3.12/site-packages/django/core/checks/registry.py", line 88, in run_checks
    new_errors = check(app_configs=app_configs, databases=databases)
                 ^^^^^^^^^^^^^^^^^^^^^^^^^^^^^^^^^^^^^^^^^^^^^^^^^^^
  File "/usr/local/lib/python3.12/site-packages/django/core/checks/urls.py", line 14, in check_url_config
    return check_resolver(resolver)
           ^^^^^^^^^^^^^^^^^^^^^^^^
  File "/usr/local/lib/python3.12/site-packages/django/core/checks/urls.py", line 24, in check_resolver
    return check_method()
           ^^^^^^^^^^^^^^
  File "/usr/local/lib/python3.12/site-packages/django/urls/resolvers.py", line 520, in check
    messages.extend(check_resolver(pattern))
                    ^^^^^^^^^^^^^^^^^^^^^^^
  File "/usr/local/lib/python3.12/site-packages/django/core/checks/urls.py", line 24, in check_resolver
    return check_method()
           ^^^^^^^^^^^^^^
  File "/usr/local/lib/python3.12/site-packages/django/urls/resolvers.py", line 519, in check
    for pattern in self.url_patterns:
                   ^^^^^^^^^^^^^^^^^
  File "/usr/local/lib/python3.12/site-packages/django/utils/functional.py", line 47, in __get__
    res = instance.__dict__[self.name] = self.func(instance)
                                         ^^^^^^^^^^^^^^^^^^^
  File "/usr/local/lib/python3.12/site-packages/django/urls/resolvers.py", line 748, in url_patterns
    raise ImproperlyConfigured(msg.format(name=self.urlconf_name)) from e
django.core.exceptions.ImproperlyConfigured: The included URLconf '<module 'scheduler.urls' from '/app/scheduler/urls.py'>' does not appear to have any patterns in it. If you see the 'urlpatterns' variable with valid patterns in the file then the issue is probably caused by a circular import.
ERROR 2024-05-16 18:09:33,745 signal 1 139680358726408 Signal handler <bound method DjangoFixup.on_import_modules of <celery.fixups.django.DjangoFixup object at 0x7f09dc5529c0>> raised: ModuleNotFoundError("No module named 'rangefilter'")
Traceback (most recent call last):
  File "/usr/local/lib/python3.12/site-packages/celery/utils/dispatch/signal.py", line 276, in send
    response = receiver(signal=self, sender=sender, **named)
               ^^^^^^^^^^^^^^^^^^^^^^^^^^^^^^^^^^^^^^^^^^^^^
  File "/usr/local/lib/python3.12/site-packages/celery/fixups/django.py", line 100, in on_import_modules
    self.worker_fixup.validate_models()
  File "/usr/local/lib/python3.12/site-packages/celery/fixups/django.py", line 138, in validate_models
    self.django_setup()
  File "/usr/local/lib/python3.12/site-packages/celery/fixups/django.py", line 134, in django_setup
    django.setup()
  File "/usr/local/lib/python3.12/site-packages/django/__init__.py", line 24, in setup
    apps.populate(settings.INSTALLED_APPS)
  File "/usr/local/lib/python3.12/site-packages/django/apps/registry.py", line 91, in populate
    app_config = AppConfig.create(entry)
                 ^^^^^^^^^^^^^^^^^^^^^^^
  File "/usr/local/lib/python3.12/site-packages/django/apps/config.py", line 193, in create
    import_module(entry)
  File "/usr/local/lib/python3.12/importlib/__init__.py", line 90, in import_module
    return _bootstrap._gcd_import(name[level:], package, level)
           ^^^^^^^^^^^^^^^^^^^^^^^^^^^^^^^^^^^^^^^^^^^^^^^^^^^^
  File "<frozen importlib._bootstrap>", line 1387, in _gcd_import
  File "<frozen importlib._bootstrap>", line 1360, in _find_and_load
  File "<frozen importlib._bootstrap>", line 1324, in _find_and_load_unlocked
ModuleNotFoundError: No module named 'rangefilter'
ERROR 2024-05-16 18:09:33,752 signal 1 139680358726408 Signal handler <promise@0x7f09dbad1950 --> <bound method Celery._autodiscover_tasks of <Celery eazyclass at 0x7f09dbac64e0>>> raised: AppRegistryNotReady("Apps aren't loaded yet.")
Traceback (most recent call last):
  File "/usr/local/lib/python3.12/site-packages/celery/utils/dispatch/signal.py", line 276, in send
    response = receiver(signal=self, sender=sender, **named)
               ^^^^^^^^^^^^^^^^^^^^^^^^^^^^^^^^^^^^^^^^^^^^^
  File "/usr/local/lib/python3.12/site-packages/vine/promises.py", line 161, in __call__
    return self.throw()
           ^^^^^^^^^^^^
  File "/usr/local/lib/python3.12/site-packages/vine/promises.py", line 158, in __call__
    retval = fun(*final_args, **final_kwargs)
             ^^^^^^^^^^^^^^^^^^^^^^^^^^^^^^^^
  File "/usr/local/lib/python3.12/site-packages/celery/app/base.py", line 694, in _autodiscover_tasks
    return self._autodiscover_tasks_from_fixups(related_name)
           ^^^^^^^^^^^^^^^^^^^^^^^^^^^^^^^^^^^^^^^^^^^^^^^^^^
  File "/usr/local/lib/python3.12/site-packages/celery/app/base.py", line 706, in _autodiscover_tasks_from_fixups
    for pkg in fixup.autodiscover_tasks()
               ^^^^^^^^^^^^^^^^^^^^^^^^^^
  File "/usr/local/lib/python3.12/site-packages/celery/fixups/django.py", line 110, in autodiscover_tasks
    return [config.name for config in apps.get_app_configs()]
                                      ^^^^^^^^^^^^^^^^^^^^^^
  File "/usr/local/lib/python3.12/site-packages/django/apps/registry.py", line 147, in get_app_configs
    self.check_apps_ready()
  File "/usr/local/lib/python3.12/site-packages/django/apps/registry.py", line 138, in check_apps_ready
    raise AppRegistryNotReady("Apps aren't loaded yet.")
django.core.exceptions.AppRegistryNotReady: Apps aren't loaded yet.
ERROR 2024-05-16 18:09:34,192 signal 1 139942062172936 Signal handler <bound method DjangoFixup.on_import_modules of <celery.fixups.django.DjangoFixup object at 0x7f46ca6d2b10>> raised: ModuleNotFoundError("No module named 'rangefilter'")
Traceback (most recent call last):
  File "/usr/local/lib/python3.12/site-packages/celery/utils/dispatch/signal.py", line 276, in send
    response = receiver(signal=self, sender=sender, **named)
               ^^^^^^^^^^^^^^^^^^^^^^^^^^^^^^^^^^^^^^^^^^^^^
  File "/usr/local/lib/python3.12/site-packages/celery/fixups/django.py", line 100, in on_import_modules
    self.worker_fixup.validate_models()
  File "/usr/local/lib/python3.12/site-packages/celery/fixups/django.py", line 138, in validate_models
    self.django_setup()
  File "/usr/local/lib/python3.12/site-packages/celery/fixups/django.py", line 134, in django_setup
    django.setup()
  File "/usr/local/lib/python3.12/site-packages/django/__init__.py", line 24, in setup
    apps.populate(settings.INSTALLED_APPS)
  File "/usr/local/lib/python3.12/site-packages/django/apps/registry.py", line 91, in populate
    app_config = AppConfig.create(entry)
                 ^^^^^^^^^^^^^^^^^^^^^^^
  File "/usr/local/lib/python3.12/site-packages/django/apps/config.py", line 193, in create
    import_module(entry)
  File "/usr/local/lib/python3.12/importlib/__init__.py", line 90, in import_module
    return _bootstrap._gcd_import(name[level:], package, level)
           ^^^^^^^^^^^^^^^^^^^^^^^^^^^^^^^^^^^^^^^^^^^^^^^^^^^^
  File "<frozen importlib._bootstrap>", line 1387, in _gcd_import
  File "<frozen importlib._bootstrap>", line 1360, in _find_and_load
  File "<frozen importlib._bootstrap>", line 1324, in _find_and_load_unlocked
ModuleNotFoundError: No module named 'rangefilter'
ERROR 2024-05-16 18:09:34,194 signal 1 139942062172936 Signal handler <promise@0x7f46ca6dd950 --> <bound method Celery._autodiscover_tasks of <Celery eazyclass at 0x7f46ca6d29c0>>> raised: AppRegistryNotReady("Apps aren't loaded yet.")
Traceback (most recent call last):
  File "/usr/local/lib/python3.12/site-packages/celery/utils/dispatch/signal.py", line 276, in send
    response = receiver(signal=self, sender=sender, **named)
               ^^^^^^^^^^^^^^^^^^^^^^^^^^^^^^^^^^^^^^^^^^^^^
  File "/usr/local/lib/python3.12/site-packages/vine/promises.py", line 161, in __call__
    return self.throw()
           ^^^^^^^^^^^^
  File "/usr/local/lib/python3.12/site-packages/vine/promises.py", line 158, in __call__
    retval = fun(*final_args, **final_kwargs)
             ^^^^^^^^^^^^^^^^^^^^^^^^^^^^^^^^
  File "/usr/local/lib/python3.12/site-packages/celery/app/base.py", line 694, in _autodiscover_tasks
    return self._autodiscover_tasks_from_fixups(related_name)
           ^^^^^^^^^^^^^^^^^^^^^^^^^^^^^^^^^^^^^^^^^^^^^^^^^^
  File "/usr/local/lib/python3.12/site-packages/celery/app/base.py", line 706, in _autodiscover_tasks_from_fixups
    for pkg in fixup.autodiscover_tasks()
               ^^^^^^^^^^^^^^^^^^^^^^^^^^
  File "/usr/local/lib/python3.12/site-packages/celery/fixups/django.py", line 110, in autodiscover_tasks
    return [config.name for config in apps.get_app_configs()]
                                      ^^^^^^^^^^^^^^^^^^^^^^
  File "/usr/local/lib/python3.12/site-packages/django/apps/registry.py", line 147, in get_app_configs
    self.check_apps_ready()
  File "/usr/local/lib/python3.12/site-packages/django/apps/registry.py", line 138, in check_apps_ready
    raise AppRegistryNotReady("Apps aren't loaded yet.")
django.core.exceptions.AppRegistryNotReady: Apps aren't loaded yet.
ERROR 2024-05-16 18:10:34,314 signal 1 140089158712072 Signal handler <bound method DjangoFixup.on_import_modules of <celery.fixups.django.DjangoFixup object at 0x7f690a11aed0>> raised: ModuleNotFoundError("No module named 'rangefilter'")
Traceback (most recent call last):
  File "/usr/local/lib/python3.12/site-packages/celery/utils/dispatch/signal.py", line 276, in send
    response = receiver(signal=self, sender=sender, **named)
               ^^^^^^^^^^^^^^^^^^^^^^^^^^^^^^^^^^^^^^^^^^^^^
  File "/usr/local/lib/python3.12/site-packages/celery/fixups/django.py", line 100, in on_import_modules
    self.worker_fixup.validate_models()
  File "/usr/local/lib/python3.12/site-packages/celery/fixups/django.py", line 138, in validate_models
    self.django_setup()
  File "/usr/local/lib/python3.12/site-packages/celery/fixups/django.py", line 134, in django_setup
    django.setup()
  File "/usr/local/lib/python3.12/site-packages/django/__init__.py", line 24, in setup
    apps.populate(settings.INSTALLED_APPS)
  File "/usr/local/lib/python3.12/site-packages/django/apps/registry.py", line 91, in populate
    app_config = AppConfig.create(entry)
                 ^^^^^^^^^^^^^^^^^^^^^^^
  File "/usr/local/lib/python3.12/site-packages/django/apps/config.py", line 193, in create
    import_module(entry)
  File "/usr/local/lib/python3.12/importlib/__init__.py", line 90, in import_module
    return _bootstrap._gcd_import(name[level:], package, level)
           ^^^^^^^^^^^^^^^^^^^^^^^^^^^^^^^^^^^^^^^^^^^^^^^^^^^^
  File "<frozen importlib._bootstrap>", line 1387, in _gcd_import
  File "<frozen importlib._bootstrap>", line 1360, in _find_and_load
  File "<frozen importlib._bootstrap>", line 1324, in _find_and_load_unlocked
ModuleNotFoundError: No module named 'rangefilter'
ERROR 2024-05-16 18:10:34,315 signal 1 140089158712072 Signal handler <promise@0x7f690a125950 --> <bound method Celery._autodiscover_tasks of <Celery eazyclass at 0x7f690a11ae10>>> raised: AppRegistryNotReady("Apps aren't loaded yet.")
Traceback (most recent call last):
  File "/usr/local/lib/python3.12/site-packages/celery/utils/dispatch/signal.py", line 276, in send
    response = receiver(signal=self, sender=sender, **named)
               ^^^^^^^^^^^^^^^^^^^^^^^^^^^^^^^^^^^^^^^^^^^^^
  File "/usr/local/lib/python3.12/site-packages/vine/promises.py", line 161, in __call__
    return self.throw()
           ^^^^^^^^^^^^
  File "/usr/local/lib/python3.12/site-packages/vine/promises.py", line 158, in __call__
    retval = fun(*final_args, **final_kwargs)
             ^^^^^^^^^^^^^^^^^^^^^^^^^^^^^^^^
  File "/usr/local/lib/python3.12/site-packages/celery/app/base.py", line 694, in _autodiscover_tasks
    return self._autodiscover_tasks_from_fixups(related_name)
           ^^^^^^^^^^^^^^^^^^^^^^^^^^^^^^^^^^^^^^^^^^^^^^^^^^
  File "/usr/local/lib/python3.12/site-packages/celery/app/base.py", line 706, in _autodiscover_tasks_from_fixups
    for pkg in fixup.autodiscover_tasks()
               ^^^^^^^^^^^^^^^^^^^^^^^^^^
  File "/usr/local/lib/python3.12/site-packages/celery/fixups/django.py", line 110, in autodiscover_tasks
    return [config.name for config in apps.get_app_configs()]
                                      ^^^^^^^^^^^^^^^^^^^^^^
  File "/usr/local/lib/python3.12/site-packages/django/apps/registry.py", line 147, in get_app_configs
    self.check_apps_ready()
  File "/usr/local/lib/python3.12/site-packages/django/apps/registry.py", line 138, in check_apps_ready
    raise AppRegistryNotReady("Apps aren't loaded yet.")
django.core.exceptions.AppRegistryNotReady: Apps aren't loaded yet.
ERROR 2024-05-16 18:10:59,221 signal 1 140151699282696 Signal handler <bound method DjangoFixup.on_import_modules of <celery.fixups.django.DjangoFixup object at 0x7f7799c56b70>> raised: ModuleNotFoundError("No module named 'rangefilter'")
Traceback (most recent call last):
  File "/usr/local/lib/python3.12/site-packages/celery/utils/dispatch/signal.py", line 276, in send
    response = receiver(signal=self, sender=sender, **named)
               ^^^^^^^^^^^^^^^^^^^^^^^^^^^^^^^^^^^^^^^^^^^^^
  File "/usr/local/lib/python3.12/site-packages/celery/fixups/django.py", line 100, in on_import_modules
    self.worker_fixup.validate_models()
  File "/usr/local/lib/python3.12/site-packages/celery/fixups/django.py", line 138, in validate_models
    self.django_setup()
  File "/usr/local/lib/python3.12/site-packages/celery/fixups/django.py", line 134, in django_setup
    django.setup()
  File "/usr/local/lib/python3.12/site-packages/django/__init__.py", line 24, in setup
    apps.populate(settings.INSTALLED_APPS)
  File "/usr/local/lib/python3.12/site-packages/django/apps/registry.py", line 91, in populate
    app_config = AppConfig.create(entry)
                 ^^^^^^^^^^^^^^^^^^^^^^^
  File "/usr/local/lib/python3.12/site-packages/django/apps/config.py", line 193, in create
    import_module(entry)
  File "/usr/local/lib/python3.12/importlib/__init__.py", line 90, in import_module
    return _bootstrap._gcd_import(name[level:], package, level)
           ^^^^^^^^^^^^^^^^^^^^^^^^^^^^^^^^^^^^^^^^^^^^^^^^^^^^
  File "<frozen importlib._bootstrap>", line 1387, in _gcd_import
  File "<frozen importlib._bootstrap>", line 1360, in _find_and_load
  File "<frozen importlib._bootstrap>", line 1324, in _find_and_load_unlocked
ModuleNotFoundError: No module named 'rangefilter'
ERROR 2024-05-16 18:10:59,223 signal 1 140151699282696 Signal handler <promise@0x7f7799c61950 --> <bound method Celery._autodiscover_tasks of <Celery eazyclass at 0x7f7799fbc950>>> raised: AppRegistryNotReady("Apps aren't loaded yet.")
Traceback (most recent call last):
  File "/usr/local/lib/python3.12/site-packages/celery/utils/dispatch/signal.py", line 276, in send
    response = receiver(signal=self, sender=sender, **named)
               ^^^^^^^^^^^^^^^^^^^^^^^^^^^^^^^^^^^^^^^^^^^^^
  File "/usr/local/lib/python3.12/site-packages/vine/promises.py", line 161, in __call__
    return self.throw()
           ^^^^^^^^^^^^
  File "/usr/local/lib/python3.12/site-packages/vine/promises.py", line 158, in __call__
    retval = fun(*final_args, **final_kwargs)
             ^^^^^^^^^^^^^^^^^^^^^^^^^^^^^^^^
  File "/usr/local/lib/python3.12/site-packages/celery/app/base.py", line 694, in _autodiscover_tasks
    return self._autodiscover_tasks_from_fixups(related_name)
           ^^^^^^^^^^^^^^^^^^^^^^^^^^^^^^^^^^^^^^^^^^^^^^^^^^
  File "/usr/local/lib/python3.12/site-packages/celery/app/base.py", line 706, in _autodiscover_tasks_from_fixups
    for pkg in fixup.autodiscover_tasks()
               ^^^^^^^^^^^^^^^^^^^^^^^^^^
  File "/usr/local/lib/python3.12/site-packages/celery/fixups/django.py", line 110, in autodiscover_tasks
    return [config.name for config in apps.get_app_configs()]
                                      ^^^^^^^^^^^^^^^^^^^^^^
  File "/usr/local/lib/python3.12/site-packages/django/apps/registry.py", line 147, in get_app_configs
    self.check_apps_ready()
  File "/usr/local/lib/python3.12/site-packages/django/apps/registry.py", line 138, in check_apps_ready
    raise AppRegistryNotReady("Apps aren't loaded yet.")
django.core.exceptions.AppRegistryNotReady: Apps aren't loaded yet.
ERROR 2024-05-17 13:26:17,714 signal 27 139661740387128 Signal handler <promise@0x7f058abf4c30 --> <bound method Celery._autodiscover_tasks of <Celery eazyclass at 0x7f058ac357c0>>> raised: ImportError("cannot import name 'update_all_lessons' from 'scheduler.tasks.lessons_parser' (/app/scheduler/tasks/lessons_parser.py)")
Traceback (most recent call last):
  File "/usr/local/lib/python3.12/site-packages/celery/utils/dispatch/signal.py", line 276, in send
    response = receiver(signal=self, sender=sender, **named)
               ^^^^^^^^^^^^^^^^^^^^^^^^^^^^^^^^^^^^^^^^^^^^^
  File "/usr/local/lib/python3.12/site-packages/vine/promises.py", line 161, in __call__
    return self.throw()
           ^^^^^^^^^^^^
  File "/usr/local/lib/python3.12/site-packages/vine/promises.py", line 158, in __call__
    retval = fun(*final_args, **final_kwargs)
             ^^^^^^^^^^^^^^^^^^^^^^^^^^^^^^^^
  File "/usr/local/lib/python3.12/site-packages/celery/app/base.py", line 694, in _autodiscover_tasks
    return self._autodiscover_tasks_from_fixups(related_name)
           ^^^^^^^^^^^^^^^^^^^^^^^^^^^^^^^^^^^^^^^^^^^^^^^^^^
  File "/usr/local/lib/python3.12/site-packages/celery/app/base.py", line 703, in _autodiscover_tasks_from_fixups
    return self._autodiscover_tasks_from_names([
           ^^^^^^^^^^^^^^^^^^^^^^^^^^^^^^^^^^^^^
  File "/usr/local/lib/python3.12/site-packages/celery/app/base.py", line 698, in _autodiscover_tasks_from_names
    return self.loader.autodiscover_tasks(
           ^^^^^^^^^^^^^^^^^^^^^^^^^^^^^^^
  File "/usr/local/lib/python3.12/site-packages/celery/loaders/base.py", line 220, in autodiscover_tasks
    mod.__name__ for mod in autodiscover_tasks(packages or (),
                            ^^^^^^^^^^^^^^^^^^^^^^^^^^^^^^^^^^
  File "/usr/local/lib/python3.12/site-packages/celery/loaders/base.py", line 246, in autodiscover_tasks
    return [find_related_module(pkg, related_name) for pkg in packages]
            ^^^^^^^^^^^^^^^^^^^^^^^^^^^^^^^^^^^^^^
  File "/usr/local/lib/python3.12/site-packages/celery/loaders/base.py", line 270, in find_related_module
    return importlib.import_module(module_name)
           ^^^^^^^^^^^^^^^^^^^^^^^^^^^^^^^^^^^^
  File "/usr/local/lib/python3.12/importlib/__init__.py", line 90, in import_module
    return _bootstrap._gcd_import(name[level:], package, level)
           ^^^^^^^^^^^^^^^^^^^^^^^^^^^^^^^^^^^^^^^^^^^^^^^^^^^^
  File "<frozen importlib._bootstrap>", line 1387, in _gcd_import
  File "<frozen importlib._bootstrap>", line 1360, in _find_and_load
  File "<frozen importlib._bootstrap>", line 1331, in _find_and_load_unlocked
  File "<frozen importlib._bootstrap>", line 935, in _load_unlocked
  File "<frozen importlib._bootstrap_external>", line 995, in exec_module
  File "<frozen importlib._bootstrap>", line 488, in _call_with_frames_removed
  File "/app/scheduler/tasks/__init__.py", line 1, in <module>
    from .lessons_parser import update_all_lessons
ImportError: cannot import name 'update_all_lessons' from 'scheduler.tasks.lessons_parser' (/app/scheduler/tasks/lessons_parser.py)
ERROR 2024-05-17 13:26:46,035 signal 27 139661740387128 Signal handler <promise@0x7f058abf4c30 --> <bound method Celery._autodiscover_tasks of <Celery eazyclass at 0x7f058ac357c0>>> raised: ImportError("cannot import name 'update_all_lessons' from 'scheduler.tasks.lessons_parser' (/app/scheduler/tasks/lessons_parser.py)")
Traceback (most recent call last):
  File "/usr/local/lib/python3.12/site-packages/celery/utils/dispatch/signal.py", line 276, in send
    response = receiver(signal=self, sender=sender, **named)
               ^^^^^^^^^^^^^^^^^^^^^^^^^^^^^^^^^^^^^^^^^^^^^
  File "/usr/local/lib/python3.12/site-packages/vine/promises.py", line 161, in __call__
    return self.throw()
           ^^^^^^^^^^^^
  File "/usr/local/lib/python3.12/site-packages/vine/promises.py", line 158, in __call__
    retval = fun(*final_args, **final_kwargs)
             ^^^^^^^^^^^^^^^^^^^^^^^^^^^^^^^^
  File "/usr/local/lib/python3.12/site-packages/celery/app/base.py", line 694, in _autodiscover_tasks
    return self._autodiscover_tasks_from_fixups(related_name)
           ^^^^^^^^^^^^^^^^^^^^^^^^^^^^^^^^^^^^^^^^^^^^^^^^^^
  File "/usr/local/lib/python3.12/site-packages/celery/app/base.py", line 703, in _autodiscover_tasks_from_fixups
    return self._autodiscover_tasks_from_names([
           ^^^^^^^^^^^^^^^^^^^^^^^^^^^^^^^^^^^^^
  File "/usr/local/lib/python3.12/site-packages/celery/app/base.py", line 698, in _autodiscover_tasks_from_names
    return self.loader.autodiscover_tasks(
           ^^^^^^^^^^^^^^^^^^^^^^^^^^^^^^^
  File "/usr/local/lib/python3.12/site-packages/celery/loaders/base.py", line 220, in autodiscover_tasks
    mod.__name__ for mod in autodiscover_tasks(packages or (),
                            ^^^^^^^^^^^^^^^^^^^^^^^^^^^^^^^^^^
  File "/usr/local/lib/python3.12/site-packages/celery/loaders/base.py", line 246, in autodiscover_tasks
    return [find_related_module(pkg, related_name) for pkg in packages]
            ^^^^^^^^^^^^^^^^^^^^^^^^^^^^^^^^^^^^^^
  File "/usr/local/lib/python3.12/site-packages/celery/loaders/base.py", line 270, in find_related_module
    return importlib.import_module(module_name)
           ^^^^^^^^^^^^^^^^^^^^^^^^^^^^^^^^^^^^
  File "/usr/local/lib/python3.12/importlib/__init__.py", line 90, in import_module
    return _bootstrap._gcd_import(name[level:], package, level)
           ^^^^^^^^^^^^^^^^^^^^^^^^^^^^^^^^^^^^^^^^^^^^^^^^^^^^
  File "<frozen importlib._bootstrap>", line 1387, in _gcd_import
  File "<frozen importlib._bootstrap>", line 1360, in _find_and_load
  File "<frozen importlib._bootstrap>", line 1331, in _find_and_load_unlocked
  File "<frozen importlib._bootstrap>", line 935, in _load_unlocked
  File "<frozen importlib._bootstrap_external>", line 995, in exec_module
  File "<frozen importlib._bootstrap>", line 488, in _call_with_frames_removed
  File "/app/scheduler/tasks/__init__.py", line 1, in <module>
    from .lessons_parser import update_all_lessons
ImportError: cannot import name 'update_all_lessons' from 'scheduler.tasks.lessons_parser' (/app/scheduler/tasks/lessons_parser.py)
ERROR 2024-05-17 23:23:02,693 signal 53 140703913478968 Signal handler <promise@0x7ff8315c0910 --> <bound method Celery._autodiscover_tasks of <Celery eazyclass at 0x7ff83161b8c0>>> raised: NameError("name 'TIMEOUT_OTHER' is not defined")
Traceback (most recent call last):
  File "/usr/local/lib/python3.12/site-packages/celery/utils/dispatch/signal.py", line 276, in send
    response = receiver(signal=self, sender=sender, **named)
               ^^^^^^^^^^^^^^^^^^^^^^^^^^^^^^^^^^^^^^^^^^^^^
  File "/usr/local/lib/python3.12/site-packages/vine/promises.py", line 161, in __call__
    return self.throw()
           ^^^^^^^^^^^^
  File "/usr/local/lib/python3.12/site-packages/vine/promises.py", line 158, in __call__
    retval = fun(*final_args, **final_kwargs)
             ^^^^^^^^^^^^^^^^^^^^^^^^^^^^^^^^
  File "/usr/local/lib/python3.12/site-packages/celery/app/base.py", line 694, in _autodiscover_tasks
    return self._autodiscover_tasks_from_fixups(related_name)
           ^^^^^^^^^^^^^^^^^^^^^^^^^^^^^^^^^^^^^^^^^^^^^^^^^^
  File "/usr/local/lib/python3.12/site-packages/celery/app/base.py", line 703, in _autodiscover_tasks_from_fixups
    return self._autodiscover_tasks_from_names([
           ^^^^^^^^^^^^^^^^^^^^^^^^^^^^^^^^^^^^^
  File "/usr/local/lib/python3.12/site-packages/celery/app/base.py", line 698, in _autodiscover_tasks_from_names
    return self.loader.autodiscover_tasks(
           ^^^^^^^^^^^^^^^^^^^^^^^^^^^^^^^
  File "/usr/local/lib/python3.12/site-packages/celery/loaders/base.py", line 220, in autodiscover_tasks
    mod.__name__ for mod in autodiscover_tasks(packages or (),
                            ^^^^^^^^^^^^^^^^^^^^^^^^^^^^^^^^^^
  File "/usr/local/lib/python3.12/site-packages/celery/loaders/base.py", line 246, in autodiscover_tasks
    return [find_related_module(pkg, related_name) for pkg in packages]
            ^^^^^^^^^^^^^^^^^^^^^^^^^^^^^^^^^^^^^^
  File "/usr/local/lib/python3.12/site-packages/celery/loaders/base.py", line 270, in find_related_module
    return importlib.import_module(module_name)
           ^^^^^^^^^^^^^^^^^^^^^^^^^^^^^^^^^^^^
  File "/usr/local/lib/python3.12/importlib/__init__.py", line 90, in import_module
    return _bootstrap._gcd_import(name[level:], package, level)
           ^^^^^^^^^^^^^^^^^^^^^^^^^^^^^^^^^^^^^^^^^^^^^^^^^^^^
  File "<frozen importlib._bootstrap>", line 1387, in _gcd_import
  File "<frozen importlib._bootstrap>", line 1360, in _find_and_load
  File "<frozen importlib._bootstrap>", line 1331, in _find_and_load_unlocked
  File "<frozen importlib._bootstrap>", line 935, in _load_unlocked
  File "<frozen importlib._bootstrap_external>", line 995, in exec_module
  File "<frozen importlib._bootstrap>", line 488, in _call_with_frames_removed
  File "/app/scheduler/tasks/__init__.py", line 1, in <module>
    from .lessons_parser import update_schedule
  File "/app/scheduler/tasks/lessons_parser.py", line 103, in <module>
    def get_or_create_cached(model_class: Model, defaults: dict, timeout: int = TIMEOUT_OTHER) -> Model:
                                                                                ^^^^^^^^^^^^^
NameError: name 'TIMEOUT_OTHER' is not defined
ERROR 2024-05-20 15:45:48,033 db_query 37 139694515624712 Ошибка при синхронизации буфера уроков: relation "lesson" does not exist
LINE 3:                     INSERT INTO lesson (group_id, lesson_tim...
                                        ^

INFO 2024-05-20 17:14:34,830 db_query 27 139735766735624 Вставка новых уроков завершена успешно.
INFO 2024-05-20 17:14:34,833 db_query 27 139735766735624 Обновление измененных уроков завершено успешно.
ERROR 2024-05-20 17:14:34,835 db_query 27 139735766735624 Ошибка при синхронизации буфера уроков: relation "scheduler_lesson_time" does not exist
LINE 5:                     FROM scheduler_lesson_time lt
                                 ^

INFO 2024-05-20 17:19:06,522 db_query 28 139917417806600 Вставка новых уроков завершена успешно.
INFO 2024-05-20 17:19:06,524 db_query 28 139917417806600 Обновление измененных уроков завершено успешно.
ERROR 2024-05-20 17:19:06,525 db_query 28 139917417806600 Ошибка при синхронизации буфера уроков: invalid reference to FROM-clause entry for table "l"
LINE 6: ...           LEFT JOIN scheduler_lessonbuffer lb ON l.group_id...
                                                             ^
DETAIL:  There is an entry for table "l", but it cannot be referenced from this part of the query.

INFO 2024-05-20 17:31:23,171 db_query 29 139792523524872 Вставка новых уроков завершена успешно.
INFO 2024-05-20 17:31:23,173 db_query 29 139792523524872 Обновление измененных уроков завершено успешно.
ERROR 2024-05-20 17:31:23,175 db_query 29 139792523524872 Ошибка при синхронизации буфера уроков: relation "scheduler_lesson_time" does not exist
LINE 5:                     FROM scheduler_lesson_time lt
                                 ^

INFO 2024-05-20 17:37:38,899 db_query 30 140699545475848 Вставка новых уроков завершена успешно.
INFO 2024-05-20 17:37:38,902 db_query 30 140699545475848 Обновление измененных уроков завершено успешно.
ERROR 2024-05-20 17:37:38,904 db_query 30 140699545475848 Ошибка при синхронизации буфера уроков: invalid reference to FROM-clause entry for table "l"
LINE 6: ...           LEFT JOIN scheduler_lessonbuffer lb ON l.group_id...
                                                             ^
DETAIL:  There is an entry for table "l", but it cannot be referenced from this part of the query.

INFO 2024-05-20 17:41:40,897 db_query 31 140560259877640 Вставка новых уроков завершена успешно.
INFO 2024-05-20 17:41:40,899 db_query 31 140560259877640 Обновление измененных уроков завершено успешно.
ERROR 2024-05-20 17:41:40,900 db_query 31 140560259877640 Ошибка при синхронизации буфера уроков: invalid reference to FROM-clause entry for table "l"
LINE 6: ...           LEFT JOIN scheduler_lessonbuffer lb ON l.group_id...
                                                             ^
DETAIL:  There is an entry for table "l", but it cannot be referenced from this part of the query.

INFO 2024-05-20 18:39:12,357 db_query 32 140201173404424 Вставка новых уроков завершена успешно.
INFO 2024-05-20 18:39:12,360 db_query 32 140201173404424 Обновление измененных уроков завершено успешно.
ERROR 2024-05-20 18:39:12,362 db_query 32 140201173404424 Ошибка при синхронизации буфера уроков: invalid reference to FROM-clause entry for table "l"
LINE 6: ...           LEFT JOIN scheduler_lessonbuffer lb ON l.group_id...
                                                             ^
DETAIL:  There is an entry for table "l", but it cannot be referenced from this part of the query.

INFO 2024-05-20 18:42:45,531 db_query 33 139976012327688 Вставка новых уроков завершена успешно.
INFO 2024-05-20 18:42:45,534 db_query 33 139976012327688 Обновление измененных уроков завершено успешно.
ERROR 2024-05-20 18:42:45,535 db_query 33 139976012327688 Ошибка при синхронизации буфера уроков: syntax error at or near ")"
LINE 10:                 )
                         ^

INFO 2024-05-20 18:44:41,700 db_query 34 140426916080392 Вставка новых уроков завершена успешно.
INFO 2024-05-20 18:44:41,702 db_query 34 140426916080392 Обновление измененных уроков завершено успешно.
INFO 2024-05-20 18:44:41,707 db_query 34 140426916080392 Деактивация уроков завершена успешно.
INFO 2024-05-20 18:57:19,284 db_query 37 140539296701192 Вставка новых уроков завершена успешно: 0 шт
INFO 2024-05-20 18:57:19,288 db_query 37 140539296701192 Обновление измененных уроков завершено успешно: 1 шт
INFO 2024-05-20 18:57:19,291 db_query 37 140539296701192 Деактивация уроков завершена успешно: 0 шт
INFO 2024-05-20 19:02:48,189 db_query 43 139656917355272 Вставка новых уроков завершена успешно: 1 шт
INFO 2024-05-20 19:02:48,193 db_query 43 139656917355272 Обновление измененных уроков завершено успешно: 1 шт
INFO 2024-05-20 19:02:48,197 db_query 43 139656917355272 Деактивация уроков завершена успешно: 1 шт
INFO 2024-05-20 19:05:11,513 db_query 44 140690873346824 Вставка новых уроков завершена успешно: 0 шт
INFO 2024-05-20 19:05:11,516 db_query 44 140690873346824 Обновление измененных уроков завершено успешно: 1 шт
INFO 2024-05-20 19:05:11,518 db_query 44 140690873346824 Деактивация уроков завершена успешно: 1 шт
ERROR 2024-05-21 01:52:07,449 signal 17 140096735415096 Signal handler <promise@0x7f6ad2e0c910 --> <bound method Celery._autodiscover_tasks of <Celery eazyclass at 0x7f6ad2e46420>>> raised: ModuleNotFoundError("No module named 'db_query'")
Traceback (most recent call last):
  File "/usr/local/lib/python3.12/site-packages/celery/utils/dispatch/signal.py", line 276, in send
    response = receiver(signal=self, sender=sender, **named)
               ^^^^^^^^^^^^^^^^^^^^^^^^^^^^^^^^^^^^^^^^^^^^^
  File "/usr/local/lib/python3.12/site-packages/vine/promises.py", line 161, in __call__
    return self.throw()
           ^^^^^^^^^^^^
  File "/usr/local/lib/python3.12/site-packages/vine/promises.py", line 158, in __call__
    retval = fun(*final_args, **final_kwargs)
             ^^^^^^^^^^^^^^^^^^^^^^^^^^^^^^^^
  File "/usr/local/lib/python3.12/site-packages/celery/app/base.py", line 694, in _autodiscover_tasks
    return self._autodiscover_tasks_from_fixups(related_name)
           ^^^^^^^^^^^^^^^^^^^^^^^^^^^^^^^^^^^^^^^^^^^^^^^^^^
  File "/usr/local/lib/python3.12/site-packages/celery/app/base.py", line 703, in _autodiscover_tasks_from_fixups
    return self._autodiscover_tasks_from_names([
           ^^^^^^^^^^^^^^^^^^^^^^^^^^^^^^^^^^^^^
  File "/usr/local/lib/python3.12/site-packages/celery/app/base.py", line 698, in _autodiscover_tasks_from_names
    return self.loader.autodiscover_tasks(
           ^^^^^^^^^^^^^^^^^^^^^^^^^^^^^^^
  File "/usr/local/lib/python3.12/site-packages/celery/loaders/base.py", line 220, in autodiscover_tasks
    mod.__name__ for mod in autodiscover_tasks(packages or (),
                            ^^^^^^^^^^^^^^^^^^^^^^^^^^^^^^^^^^
  File "/usr/local/lib/python3.12/site-packages/celery/loaders/base.py", line 246, in autodiscover_tasks
    return [find_related_module(pkg, related_name) for pkg in packages]
            ^^^^^^^^^^^^^^^^^^^^^^^^^^^^^^^^^^^^^^
  File "/usr/local/lib/python3.12/site-packages/celery/loaders/base.py", line 278, in find_related_module
    raise e
  File "/usr/local/lib/python3.12/site-packages/celery/loaders/base.py", line 270, in find_related_module
    return importlib.import_module(module_name)
           ^^^^^^^^^^^^^^^^^^^^^^^^^^^^^^^^^^^^
  File "/usr/local/lib/python3.12/importlib/__init__.py", line 90, in import_module
    return _bootstrap._gcd_import(name[level:], package, level)
           ^^^^^^^^^^^^^^^^^^^^^^^^^^^^^^^^^^^^^^^^^^^^^^^^^^^^
  File "<frozen importlib._bootstrap>", line 1387, in _gcd_import
  File "<frozen importlib._bootstrap>", line 1360, in _find_and_load
  File "<frozen importlib._bootstrap>", line 1331, in _find_and_load_unlocked
  File "<frozen importlib._bootstrap>", line 935, in _load_unlocked
  File "<frozen importlib._bootstrap_external>", line 995, in exec_module
  File "<frozen importlib._bootstrap>", line 488, in _call_with_frames_removed
  File "/app/scheduler/tasks/__init__.py", line 1, in <module>
    from .schedule_parser import update_schedule
  File "/app/scheduler/tasks/schedule_parser.py", line 14, in <module>
    from db_query import synchronize_lessons
ModuleNotFoundError: No module named 'db_query'
ERROR 2024-05-21 01:53:01,102 signal 1 140378917968648 Signal handler <promise@0x7fac8066c7d0 --> <bound method Celery._autodiscover_tasks of <Celery eazyclass at 0x7fac80e2d130>>> raised: ModuleNotFoundError("No module named 'db_query'")
Traceback (most recent call last):
  File "/usr/local/lib/python3.12/site-packages/celery/utils/dispatch/signal.py", line 276, in send
    response = receiver(signal=self, sender=sender, **named)
               ^^^^^^^^^^^^^^^^^^^^^^^^^^^^^^^^^^^^^^^^^^^^^
  File "/usr/local/lib/python3.12/site-packages/vine/promises.py", line 161, in __call__
    return self.throw()
           ^^^^^^^^^^^^
  File "/usr/local/lib/python3.12/site-packages/vine/promises.py", line 158, in __call__
    retval = fun(*final_args, **final_kwargs)
             ^^^^^^^^^^^^^^^^^^^^^^^^^^^^^^^^
  File "/usr/local/lib/python3.12/site-packages/celery/app/base.py", line 694, in _autodiscover_tasks
    return self._autodiscover_tasks_from_fixups(related_name)
           ^^^^^^^^^^^^^^^^^^^^^^^^^^^^^^^^^^^^^^^^^^^^^^^^^^
  File "/usr/local/lib/python3.12/site-packages/celery/app/base.py", line 703, in _autodiscover_tasks_from_fixups
    return self._autodiscover_tasks_from_names([
           ^^^^^^^^^^^^^^^^^^^^^^^^^^^^^^^^^^^^^
  File "/usr/local/lib/python3.12/site-packages/celery/app/base.py", line 698, in _autodiscover_tasks_from_names
    return self.loader.autodiscover_tasks(
           ^^^^^^^^^^^^^^^^^^^^^^^^^^^^^^^
  File "/usr/local/lib/python3.12/site-packages/celery/loaders/base.py", line 220, in autodiscover_tasks
    mod.__name__ for mod in autodiscover_tasks(packages or (),
                            ^^^^^^^^^^^^^^^^^^^^^^^^^^^^^^^^^^
  File "/usr/local/lib/python3.12/site-packages/celery/loaders/base.py", line 246, in autodiscover_tasks
    return [find_related_module(pkg, related_name) for pkg in packages]
            ^^^^^^^^^^^^^^^^^^^^^^^^^^^^^^^^^^^^^^
  File "/usr/local/lib/python3.12/site-packages/celery/loaders/base.py", line 278, in find_related_module
    raise e
  File "/usr/local/lib/python3.12/site-packages/celery/loaders/base.py", line 270, in find_related_module
    return importlib.import_module(module_name)
           ^^^^^^^^^^^^^^^^^^^^^^^^^^^^^^^^^^^^
  File "/usr/local/lib/python3.12/importlib/__init__.py", line 90, in import_module
    return _bootstrap._gcd_import(name[level:], package, level)
           ^^^^^^^^^^^^^^^^^^^^^^^^^^^^^^^^^^^^^^^^^^^^^^^^^^^^
  File "<frozen importlib._bootstrap>", line 1387, in _gcd_import
  File "<frozen importlib._bootstrap>", line 1360, in _find_and_load
  File "<frozen importlib._bootstrap>", line 1331, in _find_and_load_unlocked
  File "<frozen importlib._bootstrap>", line 935, in _load_unlocked
  File "<frozen importlib._bootstrap_external>", line 995, in exec_module
  File "<frozen importlib._bootstrap>", line 488, in _call_with_frames_removed
  File "/app/scheduler/tasks/__init__.py", line 1, in <module>
    from .schedule_parser import update_schedule
  File "/app/scheduler/tasks/schedule_parser.py", line 14, in <module>
    from db_query import synchronize_lessons
ModuleNotFoundError: No module named 'db_query'
ERROR 2024-05-21 01:53:01,154 signal 1 140329536707336 Signal handler <promise@0x7fa1010987d0 --> <bound method Celery._autodiscover_tasks of <Celery eazyclass at 0x7fa10129c1d0>>> raised: ModuleNotFoundError("No module named 'db_query'")
Traceback (most recent call last):
  File "/usr/local/lib/python3.12/site-packages/celery/utils/dispatch/signal.py", line 276, in send
    response = receiver(signal=self, sender=sender, **named)
               ^^^^^^^^^^^^^^^^^^^^^^^^^^^^^^^^^^^^^^^^^^^^^
  File "/usr/local/lib/python3.12/site-packages/vine/promises.py", line 161, in __call__
    return self.throw()
           ^^^^^^^^^^^^
  File "/usr/local/lib/python3.12/site-packages/vine/promises.py", line 158, in __call__
    retval = fun(*final_args, **final_kwargs)
             ^^^^^^^^^^^^^^^^^^^^^^^^^^^^^^^^
  File "/usr/local/lib/python3.12/site-packages/celery/app/base.py", line 694, in _autodiscover_tasks
    return self._autodiscover_tasks_from_fixups(related_name)
           ^^^^^^^^^^^^^^^^^^^^^^^^^^^^^^^^^^^^^^^^^^^^^^^^^^
  File "/usr/local/lib/python3.12/site-packages/celery/app/base.py", line 703, in _autodiscover_tasks_from_fixups
    return self._autodiscover_tasks_from_names([
           ^^^^^^^^^^^^^^^^^^^^^^^^^^^^^^^^^^^^^
  File "/usr/local/lib/python3.12/site-packages/celery/app/base.py", line 698, in _autodiscover_tasks_from_names
    return self.loader.autodiscover_tasks(
           ^^^^^^^^^^^^^^^^^^^^^^^^^^^^^^^
  File "/usr/local/lib/python3.12/site-packages/celery/loaders/base.py", line 220, in autodiscover_tasks
    mod.__name__ for mod in autodiscover_tasks(packages or (),
                            ^^^^^^^^^^^^^^^^^^^^^^^^^^^^^^^^^^
  File "/usr/local/lib/python3.12/site-packages/celery/loaders/base.py", line 246, in autodiscover_tasks
    return [find_related_module(pkg, related_name) for pkg in packages]
            ^^^^^^^^^^^^^^^^^^^^^^^^^^^^^^^^^^^^^^
  File "/usr/local/lib/python3.12/site-packages/celery/loaders/base.py", line 278, in find_related_module
    raise e
  File "/usr/local/lib/python3.12/site-packages/celery/loaders/base.py", line 270, in find_related_module
    return importlib.import_module(module_name)
           ^^^^^^^^^^^^^^^^^^^^^^^^^^^^^^^^^^^^
  File "/usr/local/lib/python3.12/importlib/__init__.py", line 90, in import_module
    return _bootstrap._gcd_import(name[level:], package, level)
           ^^^^^^^^^^^^^^^^^^^^^^^^^^^^^^^^^^^^^^^^^^^^^^^^^^^^
  File "<frozen importlib._bootstrap>", line 1387, in _gcd_import
  File "<frozen importlib._bootstrap>", line 1360, in _find_and_load
  File "<frozen importlib._bootstrap>", line 1331, in _find_and_load_unlocked
  File "<frozen importlib._bootstrap>", line 935, in _load_unlocked
  File "<frozen importlib._bootstrap_external>", line 995, in exec_module
  File "<frozen importlib._bootstrap>", line 488, in _call_with_frames_removed
  File "/app/scheduler/tasks/__init__.py", line 1, in <module>
    from .schedule_parser import update_schedule
  File "/app/scheduler/tasks/schedule_parser.py", line 14, in <module>
    from db_query import synchronize_lessons
ModuleNotFoundError: No module named 'db_query'
ERROR 2024-05-21 01:53:09,654 signal 19 140259717569336 Signal handler <promise@0x7f90c5208910 --> <bound method Celery._autodiscover_tasks of <Celery eazyclass at 0x7f90c4c44950>>> raised: ModuleNotFoundError("No module named 'db_query'")
Traceback (most recent call last):
  File "/usr/local/lib/python3.12/site-packages/celery/utils/dispatch/signal.py", line 276, in send
    response = receiver(signal=self, sender=sender, **named)
               ^^^^^^^^^^^^^^^^^^^^^^^^^^^^^^^^^^^^^^^^^^^^^
  File "/usr/local/lib/python3.12/site-packages/vine/promises.py", line 161, in __call__
    return self.throw()
           ^^^^^^^^^^^^
  File "/usr/local/lib/python3.12/site-packages/vine/promises.py", line 158, in __call__
    retval = fun(*final_args, **final_kwargs)
             ^^^^^^^^^^^^^^^^^^^^^^^^^^^^^^^^
  File "/usr/local/lib/python3.12/site-packages/celery/app/base.py", line 694, in _autodiscover_tasks
    return self._autodiscover_tasks_from_fixups(related_name)
           ^^^^^^^^^^^^^^^^^^^^^^^^^^^^^^^^^^^^^^^^^^^^^^^^^^
  File "/usr/local/lib/python3.12/site-packages/celery/app/base.py", line 703, in _autodiscover_tasks_from_fixups
    return self._autodiscover_tasks_from_names([
           ^^^^^^^^^^^^^^^^^^^^^^^^^^^^^^^^^^^^^
  File "/usr/local/lib/python3.12/site-packages/celery/app/base.py", line 698, in _autodiscover_tasks_from_names
    return self.loader.autodiscover_tasks(
           ^^^^^^^^^^^^^^^^^^^^^^^^^^^^^^^
  File "/usr/local/lib/python3.12/site-packages/celery/loaders/base.py", line 220, in autodiscover_tasks
    mod.__name__ for mod in autodiscover_tasks(packages or (),
                            ^^^^^^^^^^^^^^^^^^^^^^^^^^^^^^^^^^
  File "/usr/local/lib/python3.12/site-packages/celery/loaders/base.py", line 246, in autodiscover_tasks
    return [find_related_module(pkg, related_name) for pkg in packages]
            ^^^^^^^^^^^^^^^^^^^^^^^^^^^^^^^^^^^^^^
  File "/usr/local/lib/python3.12/site-packages/celery/loaders/base.py", line 278, in find_related_module
    raise e
  File "/usr/local/lib/python3.12/site-packages/celery/loaders/base.py", line 270, in find_related_module
    return importlib.import_module(module_name)
           ^^^^^^^^^^^^^^^^^^^^^^^^^^^^^^^^^^^^
  File "/usr/local/lib/python3.12/importlib/__init__.py", line 90, in import_module
    return _bootstrap._gcd_import(name[level:], package, level)
           ^^^^^^^^^^^^^^^^^^^^^^^^^^^^^^^^^^^^^^^^^^^^^^^^^^^^
  File "<frozen importlib._bootstrap>", line 1387, in _gcd_import
  File "<frozen importlib._bootstrap>", line 1360, in _find_and_load
  File "<frozen importlib._bootstrap>", line 1331, in _find_and_load_unlocked
  File "<frozen importlib._bootstrap>", line 935, in _load_unlocked
  File "<frozen importlib._bootstrap_external>", line 995, in exec_module
  File "<frozen importlib._bootstrap>", line 488, in _call_with_frames_removed
  File "/app/scheduler/tasks/__init__.py", line 1, in <module>
    from .schedule_parser import update_schedule
  File "/app/scheduler/tasks/schedule_parser.py", line 14, in <module>
    from db_query import synchronize_lessons
ModuleNotFoundError: No module named 'db_query'
ERROR 2024-05-23 13:44:21,090 signal 1 139823436286728 Signal handler <bound method DjangoFixup.on_import_modules of <celery.fixups.django.DjangoFixup object at 0x7f2b2bc23860>> raised: ModuleNotFoundError("No module named 'rest_framework'")
Traceback (most recent call last):
  File "/usr/local/lib/python3.12/site-packages/celery/utils/dispatch/signal.py", line 276, in send
    response = receiver(signal=self, sender=sender, **named)
               ^^^^^^^^^^^^^^^^^^^^^^^^^^^^^^^^^^^^^^^^^^^^^
  File "/usr/local/lib/python3.12/site-packages/celery/fixups/django.py", line 100, in on_import_modules
    self.worker_fixup.validate_models()
  File "/usr/local/lib/python3.12/site-packages/celery/fixups/django.py", line 138, in validate_models
    self.django_setup()
  File "/usr/local/lib/python3.12/site-packages/celery/fixups/django.py", line 134, in django_setup
    django.setup()
  File "/usr/local/lib/python3.12/site-packages/django/__init__.py", line 24, in setup
    apps.populate(settings.INSTALLED_APPS)
  File "/usr/local/lib/python3.12/site-packages/django/apps/registry.py", line 91, in populate
    app_config = AppConfig.create(entry)
                 ^^^^^^^^^^^^^^^^^^^^^^^
  File "/usr/local/lib/python3.12/site-packages/django/apps/config.py", line 193, in create
    import_module(entry)
  File "/usr/local/lib/python3.12/importlib/__init__.py", line 90, in import_module
    return _bootstrap._gcd_import(name[level:], package, level)
           ^^^^^^^^^^^^^^^^^^^^^^^^^^^^^^^^^^^^^^^^^^^^^^^^^^^^
  File "<frozen importlib._bootstrap>", line 1387, in _gcd_import
  File "<frozen importlib._bootstrap>", line 1360, in _find_and_load
  File "<frozen importlib._bootstrap>", line 1324, in _find_and_load_unlocked
ModuleNotFoundError: No module named 'rest_framework'
ERROR 2024-05-23 13:44:21,096 signal 1 139823436286728 Signal handler <promise@0x7f2b2b1c8870 --> <bound method Celery._autodiscover_tasks of <Celery eazyclass at 0x7f2b2b3d6510>>> raised: AppRegistryNotReady("Apps aren't loaded yet.")
Traceback (most recent call last):
  File "/usr/local/lib/python3.12/site-packages/celery/utils/dispatch/signal.py", line 276, in send
    response = receiver(signal=self, sender=sender, **named)
               ^^^^^^^^^^^^^^^^^^^^^^^^^^^^^^^^^^^^^^^^^^^^^
  File "/usr/local/lib/python3.12/site-packages/vine/promises.py", line 161, in __call__
    return self.throw()
           ^^^^^^^^^^^^
  File "/usr/local/lib/python3.12/site-packages/vine/promises.py", line 158, in __call__
    retval = fun(*final_args, **final_kwargs)
             ^^^^^^^^^^^^^^^^^^^^^^^^^^^^^^^^
  File "/usr/local/lib/python3.12/site-packages/celery/app/base.py", line 694, in _autodiscover_tasks
    return self._autodiscover_tasks_from_fixups(related_name)
           ^^^^^^^^^^^^^^^^^^^^^^^^^^^^^^^^^^^^^^^^^^^^^^^^^^
  File "/usr/local/lib/python3.12/site-packages/celery/app/base.py", line 706, in _autodiscover_tasks_from_fixups
    for pkg in fixup.autodiscover_tasks()
               ^^^^^^^^^^^^^^^^^^^^^^^^^^
  File "/usr/local/lib/python3.12/site-packages/celery/fixups/django.py", line 110, in autodiscover_tasks
    return [config.name for config in apps.get_app_configs()]
                                      ^^^^^^^^^^^^^^^^^^^^^^
  File "/usr/local/lib/python3.12/site-packages/django/apps/registry.py", line 147, in get_app_configs
    self.check_apps_ready()
  File "/usr/local/lib/python3.12/site-packages/django/apps/registry.py", line 138, in check_apps_ready
    raise AppRegistryNotReady("Apps aren't loaded yet.")
django.core.exceptions.AppRegistryNotReady: Apps aren't loaded yet.
ERROR 2024-05-23 13:44:21,345 signal 1 139864944859912 Signal handler <bound method DjangoFixup.on_import_modules of <celery.fixups.django.DjangoFixup object at 0x7f34d5816cf0>> raised: ModuleNotFoundError("No module named 'rest_framework'")
Traceback (most recent call last):
  File "/usr/local/lib/python3.12/site-packages/celery/utils/dispatch/signal.py", line 276, in send
    response = receiver(signal=self, sender=sender, **named)
               ^^^^^^^^^^^^^^^^^^^^^^^^^^^^^^^^^^^^^^^^^^^^^
  File "/usr/local/lib/python3.12/site-packages/celery/fixups/django.py", line 100, in on_import_modules
    self.worker_fixup.validate_models()
  File "/usr/local/lib/python3.12/site-packages/celery/fixups/django.py", line 138, in validate_models
    self.django_setup()
  File "/usr/local/lib/python3.12/site-packages/celery/fixups/django.py", line 134, in django_setup
    django.setup()
  File "/usr/local/lib/python3.12/site-packages/django/__init__.py", line 24, in setup
    apps.populate(settings.INSTALLED_APPS)
  File "/usr/local/lib/python3.12/site-packages/django/apps/registry.py", line 91, in populate
    app_config = AppConfig.create(entry)
                 ^^^^^^^^^^^^^^^^^^^^^^^
  File "/usr/local/lib/python3.12/site-packages/django/apps/config.py", line 193, in create
    import_module(entry)
  File "/usr/local/lib/python3.12/importlib/__init__.py", line 90, in import_module
    return _bootstrap._gcd_import(name[level:], package, level)
           ^^^^^^^^^^^^^^^^^^^^^^^^^^^^^^^^^^^^^^^^^^^^^^^^^^^^
  File "<frozen importlib._bootstrap>", line 1387, in _gcd_import
  File "<frozen importlib._bootstrap>", line 1360, in _find_and_load
  File "<frozen importlib._bootstrap>", line 1324, in _find_and_load_unlocked
ModuleNotFoundError: No module named 'rest_framework'
ERROR 2024-05-23 13:44:21,347 signal 1 139864944859912 Signal handler <promise@0x7f34d5378870 --> <bound method Celery._autodiscover_tasks of <Celery eazyclass at 0x7f34d553a750>>> raised: AppRegistryNotReady("Apps aren't loaded yet.")
Traceback (most recent call last):
  File "/usr/local/lib/python3.12/site-packages/celery/utils/dispatch/signal.py", line 276, in send
    response = receiver(signal=self, sender=sender, **named)
               ^^^^^^^^^^^^^^^^^^^^^^^^^^^^^^^^^^^^^^^^^^^^^
  File "/usr/local/lib/python3.12/site-packages/vine/promises.py", line 161, in __call__
    return self.throw()
           ^^^^^^^^^^^^
  File "/usr/local/lib/python3.12/site-packages/vine/promises.py", line 158, in __call__
    retval = fun(*final_args, **final_kwargs)
             ^^^^^^^^^^^^^^^^^^^^^^^^^^^^^^^^
  File "/usr/local/lib/python3.12/site-packages/celery/app/base.py", line 694, in _autodiscover_tasks
    return self._autodiscover_tasks_from_fixups(related_name)
           ^^^^^^^^^^^^^^^^^^^^^^^^^^^^^^^^^^^^^^^^^^^^^^^^^^
  File "/usr/local/lib/python3.12/site-packages/celery/app/base.py", line 706, in _autodiscover_tasks_from_fixups
    for pkg in fixup.autodiscover_tasks()
               ^^^^^^^^^^^^^^^^^^^^^^^^^^
  File "/usr/local/lib/python3.12/site-packages/celery/fixups/django.py", line 110, in autodiscover_tasks
    return [config.name for config in apps.get_app_configs()]
                                      ^^^^^^^^^^^^^^^^^^^^^^
  File "/usr/local/lib/python3.12/site-packages/django/apps/registry.py", line 147, in get_app_configs
    self.check_apps_ready()
  File "/usr/local/lib/python3.12/site-packages/django/apps/registry.py", line 138, in check_apps_ready
    raise AppRegistryNotReady("Apps aren't loaded yet.")
django.core.exceptions.AppRegistryNotReady: Apps aren't loaded yet.
INFO 2024-05-23 21:50:52,544 command 1 139896229509928 Visit me at http://0.0.0.0:5555
INFO 2024-05-23 21:50:52,553 command 1 139896229509928 Broker: redis://redis:6379/0
INFO 2024-05-23 21:50:52,560 command 1 139896229509928 Registered tasks: 
['celery.accumulate',
 'celery.backend_cleanup',
 'celery.chain',
 'celery.chord',
 'celery.chord_unlock',
 'celery.chunks',
 'celery.group',
 'celery.map',
 'celery.starmap',
 'scheduler.tasks.group_parser.update_groups',
 'scheduler.tasks.schedule_parser.parse_group_data',
 'scheduler.tasks.schedule_parser.process_data_final',
 'scheduler.tasks.schedule_parser.send_group_notification',
 'scheduler.tasks.schedule_parser.send_notifications',
 'scheduler.tasks.schedule_parser.update_schedule',
 'scheduler.tasks.timetable_manager.fill_lesson_times',
 'scheduler.tasks.update_last_active.delete_inactive_records',
 'scheduler.tasks.update_last_active.update_last_active_records']
INFO 2024-05-23 21:50:52,567 mixins 1 139896132422456 Connected to redis://redis:6379/0
INFO 2024-05-23 22:11:06,979 timetable_manager 36 140595327064872 Расписание звонков заполнены на период 2024-05-22 - 2024-06-30.
INFO 2024-05-23 22:26:22,156 command 1 139896229509928 15 detected, shutting down
INFO 2024-05-23 22:26:30,166 command 1 139941936048936 Visit me at http://0.0.0.0:5555
INFO 2024-05-23 22:26:30,173 command 1 139941936048936 Broker: redis://redis:6379/0
INFO 2024-05-23 22:26:30,181 command 1 139941936048936 Registered tasks: 
['celery.accumulate',
 'celery.backend_cleanup',
 'celery.chain',
 'celery.chord',
 'celery.chord_unlock',
 'celery.chunks',
 'celery.group',
 'celery.map',
 'celery.starmap',
 'scheduler.tasks.group_parser.update_groups',
 'scheduler.tasks.schedule_parser.parse_group_data',
 'scheduler.tasks.schedule_parser.process_data_final',
 'scheduler.tasks.schedule_parser.send_group_notification',
 'scheduler.tasks.schedule_parser.send_notifications',
 'scheduler.tasks.schedule_parser.update_schedule',
 'scheduler.tasks.timetable_manager.fill_lesson_times',
 'scheduler.tasks.update_last_active.delete_inactive_records',
 'scheduler.tasks.update_last_active.update_last_active_records']
INFO 2024-05-23 22:26:30,190 mixins 1 139941838965560 Connected to redis://redis:6379/0
WARNING 2024-05-23 22:26:31,233 inspector 1 139941835782968 Inspect method registered failed
WARNING 2024-05-23 22:26:31,243 inspector 1 139941837904696 Inspect method stats failed
WARNING 2024-05-23 22:26:31,244 inspector 1 139941834722104 Inspect method scheduled failed
WARNING 2024-05-23 22:26:31,244 inspector 1 139941831539512 Inspect method revoked failed
WARNING 2024-05-23 22:26:31,245 inspector 1 139941833661240 Inspect method active failed
WARNING 2024-05-23 22:26:31,246 inspector 1 139941832600376 Inspect method reserved failed
WARNING 2024-05-23 22:26:31,246 inspector 1 139941830478648 Inspect method conf failed
WARNING 2024-05-23 22:26:31,249 inspector 1 139941836843832 Inspect method active_queues failed
INFO 2024-05-24 02:42:07,214 command 1 139941936048936 15 detected, shutting down
INFO 2024-05-24 02:42:52,308 command 1 140519101733672 Visit me at http://0.0.0.0:5555
INFO 2024-05-24 02:42:52,314 command 1 140519101733672 Broker: redis://redis:6379/0
INFO 2024-05-24 02:42:52,322 command 1 140519101733672 Registered tasks: 
['celery.accumulate',
 'celery.backend_cleanup',
 'celery.chain',
 'celery.chord',
 'celery.chord_unlock',
 'celery.chunks',
 'celery.group',
 'celery.map',
 'celery.starmap',
 'scheduler.tasks.group_parser.update_groups',
 'scheduler.tasks.schedule_parser.parse_group_data',
 'scheduler.tasks.schedule_parser.process_data_final',
 'scheduler.tasks.schedule_parser.send_group_notification',
 'scheduler.tasks.schedule_parser.send_notifications',
 'scheduler.tasks.schedule_parser.update_schedule',
 'scheduler.tasks.timetable_manager.fill_lesson_times',
 'scheduler.tasks.update_last_active.delete_inactive_records',
 'scheduler.tasks.update_last_active.update_last_active_records']
INFO 2024-05-24 02:42:52,330 mixins 1 140519004646200 Connected to redis://redis:6379/0
WARNING 2024-05-24 02:42:53,370 inspector 1 140518998281016 Inspect method reserved failed
WARNING 2024-05-24 02:42:53,374 inspector 1 140519001463608 Inspect method registered failed
WARNING 2024-05-24 02:42:53,378 inspector 1 140519003585336 Inspect method stats failed
WARNING 2024-05-24 02:42:53,379 inspector 1 140518999341880 Inspect method active failed
WARNING 2024-05-24 02:42:53,381 inspector 1 140518996159288 Inspect method conf failed
WARNING 2024-05-24 02:42:53,381 inspector 1 140518997220152 Inspect method revoked failed
WARNING 2024-05-24 02:42:53,382 inspector 1 140519002524472 Inspect method active_queues failed
WARNING 2024-05-24 02:42:53,382 inspector 1 140519000402744 Inspect method scheduled failed
INFO 2024-05-24 02:57:26,811 command 1 140519101733672 15 detected, shutting down
INFO 2024-05-24 02:57:33,461 command 1 139718168435496 Visit me at http://0.0.0.0:5555
INFO 2024-05-24 02:57:33,469 command 1 139718168435496 Broker: redis://redis:6379/0
INFO 2024-05-24 02:57:33,479 command 1 139718168435496 Registered tasks: 
['celery.accumulate',
 'celery.backend_cleanup',
 'celery.chain',
 'celery.chord',
 'celery.chord_unlock',
 'celery.chunks',
 'celery.group',
 'celery.map',
 'celery.starmap',
 'scheduler.tasks.group_parser.update_groups',
 'scheduler.tasks.schedule_parser.parse_group_data',
 'scheduler.tasks.schedule_parser.process_data_final',
 'scheduler.tasks.schedule_parser.send_group_notification',
 'scheduler.tasks.schedule_parser.send_notifications',
 'scheduler.tasks.schedule_parser.update_schedule',
 'scheduler.tasks.timetable_manager.fill_lesson_times',
 'scheduler.tasks.update_last_active.delete_inactive_records',
 'scheduler.tasks.update_last_active.update_last_active_records']
INFO 2024-05-24 02:57:33,487 mixins 1 139718071360312 Connected to redis://redis:6379/0
WARNING 2024-05-24 02:57:34,536 inspector 1 139718069238584 Inspect method active_queues failed
WARNING 2024-05-24 02:57:34,543 inspector 1 139718062873400 Inspect method conf failed
WARNING 2024-05-24 02:57:34,544 inspector 1 139718068177720 Inspect method registered failed
WARNING 2024-05-24 02:57:34,545 inspector 1 139718070299448 Inspect method stats failed
WARNING 2024-05-24 02:57:34,547 inspector 1 139718064995128 Inspect method reserved failed
WARNING 2024-05-24 02:57:34,549 inspector 1 139718063934264 Inspect method revoked failed
WARNING 2024-05-24 02:57:34,550 inspector 1 139718066055992 Inspect method active failed
WARNING 2024-05-24 02:57:34,551 inspector 1 139718067116856 Inspect method scheduled failed
INFO 2024-05-25 12:53:51,476 command 1 139718168435496 15 detected, shutting down
INFO 2024-05-25 12:54:00,881 command 1 140213852707624 Visit me at http://0.0.0.0:5555
INFO 2024-05-25 12:54:00,895 command 1 140213852707624 Broker: redis://redis:6379/0
INFO 2024-05-25 12:54:00,903 command 1 140213852707624 Registered tasks: 
['celery.accumulate',
 'celery.backend_cleanup',
 'celery.chain',
 'celery.chord',
 'celery.chord_unlock',
 'celery.chunks',
 'celery.group',
 'celery.map',
 'celery.starmap',
 'scheduler.tasks.group_parser.deactivate_all_groups',
 'scheduler.tasks.group_parser.update_groups',
 'scheduler.tasks.schedule_parser.parse_group_data',
 'scheduler.tasks.schedule_parser.process_data_final',
 'scheduler.tasks.schedule_parser.send_group_notification',
 'scheduler.tasks.schedule_parser.send_notifications',
 'scheduler.tasks.schedule_parser.update_schedule',
 'scheduler.tasks.timetable_manager.fill_lesson_times',
 'scheduler.tasks.update_last_active.delete_inactive_records',
 'scheduler.tasks.update_last_active.update_last_active_records']
INFO 2024-05-25 12:54:00,913 mixins 1 140213758069560 Connected to redis://redis:6379/0
WARNING 2024-05-25 12:54:01,959 inspector 1 140213755947832 Inspect method active_queues failed
WARNING 2024-05-25 12:54:01,968 inspector 1 140213750643512 Inspect method revoked failed
WARNING 2024-05-25 12:54:01,969 inspector 1 140213753826104 Inspect method scheduled failed
WARNING 2024-05-25 12:54:01,970 inspector 1 140213751704376 Inspect method reserved failed
WARNING 2024-05-25 12:54:01,971 inspector 1 140213752765240 Inspect method active failed
WARNING 2024-05-25 12:54:01,975 inspector 1 140213754886968 Inspect method registered failed
WARNING 2024-05-25 12:54:01,976 inspector 1 140213749582648 Inspect method conf failed
WARNING 2024-05-25 12:54:01,976 inspector 1 140213757008696 Inspect method stats failed
INFO 2024-05-25 23:48:25,257 command 1 140213852707624 15 detected, shutting down
INFO 2024-05-26 13:00:43,468 command 1 140649620319016 Visit me at http://0.0.0.0:5555
INFO 2024-05-26 13:00:43,482 command 1 140649620319016 Broker: redis://redis:6379/0
INFO 2024-05-26 13:00:43,490 command 1 140649620319016 Registered tasks: 
['celery.accumulate',
 'celery.backend_cleanup',
 'celery.chain',
 'celery.chord',
 'celery.chord_unlock',
 'celery.chunks',
 'celery.group',
 'celery.map',
 'celery.starmap',
 'scheduler.tasks.group_parser.deactivate_all_groups',
 'scheduler.tasks.group_parser.update_groups',
 'scheduler.tasks.schedule_parser.parse_group_data',
 'scheduler.tasks.schedule_parser.process_data_final',
 'scheduler.tasks.schedule_parser.send_group_notification',
 'scheduler.tasks.schedule_parser.send_notifications',
 'scheduler.tasks.schedule_parser.update_schedule',
 'scheduler.tasks.timetable_manager.fill_lesson_times',
 'scheduler.tasks.update_last_active.delete_inactive_records',
 'scheduler.tasks.update_last_active.update_last_active_records']
INFO 2024-05-26 13:00:43,499 mixins 1 140649525664568 Connected to redis://redis:6379/0
WARNING 2024-05-26 13:00:44,540 inspector 1 140649522481976 Inspect method registered failed
WARNING 2024-05-26 13:00:44,545 inspector 1 140649520360248 Inspect method active failed
WARNING 2024-05-26 13:00:44,546 inspector 1 140649524603704 Inspect method stats failed
WARNING 2024-05-26 13:00:44,552 inspector 1 140649519299384 Inspect method reserved failed
WARNING 2024-05-26 13:00:44,553 inspector 1 140649517177656 Inspect method conf failed
WARNING 2024-05-26 13:00:44,554 inspector 1 140649518238520 Inspect method revoked failed
WARNING 2024-05-26 13:00:44,555 inspector 1 140649521421112 Inspect method scheduled failed
WARNING 2024-05-26 13:00:44,555 inspector 1 140649523542840 Inspect method active_queues failed
INFO 2024-05-26 18:19:38,471 command 1 139786084993832 Visit me at http://0.0.0.0:5555
INFO 2024-05-26 18:19:38,487 command 1 139786084993832 Broker: redis://redis:6379/0
INFO 2024-05-26 18:19:38,496 command 1 139786084993832 Registered tasks: 
['celery.accumulate',
 'celery.backend_cleanup',
 'celery.chain',
 'celery.chord',
 'celery.chord_unlock',
 'celery.chunks',
 'celery.group',
 'celery.map',
 'celery.starmap',
 'scheduler.tasks.group_parser.deactivate_all_groups',
 'scheduler.tasks.group_parser.update_groups',
 'scheduler.tasks.schedule_parser.parse_group_data',
 'scheduler.tasks.schedule_parser.process_data_final',
 'scheduler.tasks.schedule_parser.send_group_notification',
 'scheduler.tasks.schedule_parser.send_notifications',
 'scheduler.tasks.schedule_parser.update_schedule',
 'scheduler.tasks.timetable_manager.fill_lesson_times',
 'scheduler.tasks.update_last_active.delete_inactive_records',
 'scheduler.tasks.update_last_active.update_last_active_records']
INFO 2024-05-26 18:19:38,504 mixins 1 139785990433592 Connected to redis://redis:6379/0
WARNING 2024-05-26 18:19:39,543 inspector 1 139785987251000 Inspect method registered failed
WARNING 2024-05-26 18:19:39,544 inspector 1 139785986190136 Inspect method scheduled failed
WARNING 2024-05-26 18:19:39,550 inspector 1 139785984068408 Inspect method reserved failed
WARNING 2024-05-26 18:19:39,550 inspector 1 139785981946680 Inspect method conf failed
WARNING 2024-05-26 18:19:39,555 inspector 1 139785989372728 Inspect method stats failed
WARNING 2024-05-26 18:19:39,556 inspector 1 139785983007544 Inspect method revoked failed
WARNING 2024-05-26 18:19:39,556 inspector 1 139785985129272 Inspect method active failed
WARNING 2024-05-26 18:19:39,557 inspector 1 139785988311864 Inspect method active_queues failed
INFO 2024-05-27 02:32:06,991 command 1 139786084993832 15 detected, shutting down
INFO 2024-05-27 02:32:16,995 command 1 140036865014568 Visit me at http://0.0.0.0:5555
INFO 2024-05-27 02:32:17,009 command 1 140036865014568 Broker: redis://redis:6379/0
INFO 2024-05-27 02:32:17,020 command 1 140036865014568 Registered tasks: 
['celery.accumulate',
 'celery.backend_cleanup',
 'celery.chain',
 'celery.chord',
 'celery.chord_unlock',
 'celery.chunks',
 'celery.group',
 'celery.map',
 'celery.starmap',
 'scheduler.tasks.group_parser.deactivate_all_groups',
 'scheduler.tasks.group_parser.update_groups',
 'scheduler.tasks.schedule_parser.parse_group_data',
 'scheduler.tasks.schedule_parser.process_data_final',
 'scheduler.tasks.schedule_parser.send_group_notification',
 'scheduler.tasks.schedule_parser.send_notifications',
 'scheduler.tasks.schedule_parser.update_schedule',
 'scheduler.tasks.timetable_manager.fill_lesson_times',
 'scheduler.tasks.update_last_active.delete_inactive_records',
 'scheduler.tasks.update_last_active.update_last_active_records']
INFO 2024-05-27 02:32:17,029 mixins 1 140036770396984 Connected to redis://redis:6379/0
WARNING 2024-05-27 02:32:18,078 inspector 1 140036767214392 Inspect method registered failed
WARNING 2024-05-27 02:32:18,086 inspector 1 140036761910072 Inspect method conf failed
WARNING 2024-05-27 02:32:18,087 inspector 1 140036768275256 Inspect method active_queues failed
WARNING 2024-05-27 02:32:18,087 inspector 1 140036762970936 Inspect method revoked failed
WARNING 2024-05-27 02:32:18,093 inspector 1 140036764031800 Inspect method reserved failed
WARNING 2024-05-27 02:32:18,094 inspector 1 140036769336120 Inspect method stats failed
WARNING 2024-05-27 02:32:18,095 inspector 1 140036766153528 Inspect method scheduled failed
WARNING 2024-05-27 02:32:18,096 inspector 1 140036765092664 Inspect method active failed
INFO 2024-05-29 10:50:27,426 command 1 140036865014568 15 detected, shutting down
INFO 2024-05-31 02:52:57,158 command 1 139804679994152 Visit me at http://0.0.0.0:5555
INFO 2024-05-31 02:52:57,173 command 1 139804679994152 Broker: redis://redis:6379/0
INFO 2024-05-31 02:52:57,181 command 1 139804679994152 Registered tasks: 
['celery.accumulate',
 'celery.backend_cleanup',
 'celery.chain',
 'celery.chord',
 'celery.chord_unlock',
 'celery.chunks',
 'celery.group',
 'celery.map',
 'celery.starmap',
 'scheduler.tasks.group_parser.deactivate_all_groups',
 'scheduler.tasks.group_parser.update_groups',
 'scheduler.tasks.schedule_parser.parse_group_data',
 'scheduler.tasks.schedule_parser.process_data_final',
 'scheduler.tasks.schedule_parser.send_group_notification',
 'scheduler.tasks.schedule_parser.send_notifications',
 'scheduler.tasks.schedule_parser.update_schedule',
 'scheduler.tasks.timetable_manager.fill_lesson_times',
 'scheduler.tasks.update_last_active.delete_inactive_records',
 'scheduler.tasks.update_last_active.update_last_active_records']
INFO 2024-05-31 02:52:57,191 mixins 1 139804585380664 Connected to redis://redis:6379/0
WARNING 2024-05-31 02:52:58,241 inspector 1 139804582198072 Inspect method registered failed
WARNING 2024-05-31 02:52:58,246 inspector 1 139804583258936 Inspect method active_queues failed
WARNING 2024-05-31 02:52:58,246 inspector 1 139804576893752 Inspect method conf failed
WARNING 2024-05-31 02:52:58,247 inspector 1 139804581137208 Inspect method scheduled failed
WARNING 2024-05-31 02:52:58,248 inspector 1 139804579015480 Inspect method reserved failed
WARNING 2024-05-31 02:52:58,256 inspector 1 139804577954616 Inspect method revoked failed
WARNING 2024-05-31 02:52:58,256 inspector 1 139804584319800 Inspect method stats failed
WARNING 2024-05-31 02:52:58,256 inspector 1 139804580076344 Inspect method active failed
ERROR 2024-05-31 17:17:44,559 signal 18 140171025890104 Signal handler <promise@0x7f7c1ea20910 --> <bound method Celery._autodiscover_tasks of <Celery eazyclass at 0x7f7c1ea4f8c0>>> raised: ModuleNotFoundError("No module named 'telebot'")
Traceback (most recent call last):
  File "/usr/local/lib/python3.12/site-packages/celery/utils/dispatch/signal.py", line 276, in send
    response = receiver(signal=self, sender=sender, **named)
               ^^^^^^^^^^^^^^^^^^^^^^^^^^^^^^^^^^^^^^^^^^^^^
  File "/usr/local/lib/python3.12/site-packages/vine/promises.py", line 161, in __call__
    return self.throw()
           ^^^^^^^^^^^^
  File "/usr/local/lib/python3.12/site-packages/vine/promises.py", line 158, in __call__
    retval = fun(*final_args, **final_kwargs)
             ^^^^^^^^^^^^^^^^^^^^^^^^^^^^^^^^
  File "/usr/local/lib/python3.12/site-packages/celery/app/base.py", line 694, in _autodiscover_tasks
    return self._autodiscover_tasks_from_fixups(related_name)
           ^^^^^^^^^^^^^^^^^^^^^^^^^^^^^^^^^^^^^^^^^^^^^^^^^^
  File "/usr/local/lib/python3.12/site-packages/celery/app/base.py", line 703, in _autodiscover_tasks_from_fixups
    return self._autodiscover_tasks_from_names([
           ^^^^^^^^^^^^^^^^^^^^^^^^^^^^^^^^^^^^^
  File "/usr/local/lib/python3.12/site-packages/celery/app/base.py", line 698, in _autodiscover_tasks_from_names
    return self.loader.autodiscover_tasks(
           ^^^^^^^^^^^^^^^^^^^^^^^^^^^^^^^
  File "/usr/local/lib/python3.12/site-packages/celery/loaders/base.py", line 220, in autodiscover_tasks
    mod.__name__ for mod in autodiscover_tasks(packages or (),
                            ^^^^^^^^^^^^^^^^^^^^^^^^^^^^^^^^^^
  File "/usr/local/lib/python3.12/site-packages/celery/loaders/base.py", line 246, in autodiscover_tasks
    return [find_related_module(pkg, related_name) for pkg in packages]
            ^^^^^^^^^^^^^^^^^^^^^^^^^^^^^^^^^^^^^^
  File "/usr/local/lib/python3.12/site-packages/celery/loaders/base.py", line 278, in find_related_module
    raise e
  File "/usr/local/lib/python3.12/site-packages/celery/loaders/base.py", line 270, in find_related_module
    return importlib.import_module(module_name)
           ^^^^^^^^^^^^^^^^^^^^^^^^^^^^^^^^^^^^
  File "/usr/local/lib/python3.12/importlib/__init__.py", line 90, in import_module
    return _bootstrap._gcd_import(name[level:], package, level)
           ^^^^^^^^^^^^^^^^^^^^^^^^^^^^^^^^^^^^^^^^^^^^^^^^^^^^
  File "<frozen importlib._bootstrap>", line 1387, in _gcd_import
  File "<frozen importlib._bootstrap>", line 1360, in _find_and_load
  File "<frozen importlib._bootstrap>", line 1331, in _find_and_load_unlocked
  File "<frozen importlib._bootstrap>", line 935, in _load_unlocked
  File "<frozen importlib._bootstrap_external>", line 995, in exec_module
  File "<frozen importlib._bootstrap>", line 488, in _call_with_frames_removed
  File "/app/telegrambot/tasks.py", line 2, in <module>
    from .bot import bot
  File "/app/telegrambot/bot.py", line 5, in <module>
    import telebot
ModuleNotFoundError: No module named 'telebot'
ERROR 2024-05-31 17:27:34,169 signal 18 140171025890104 Signal handler <promise@0x7f7c1ea20910 --> <bound method Celery._autodiscover_tasks of <Celery eazyclass at 0x7f7c1ea4f8c0>>> raised: ModuleNotFoundError("No module named 'telebot'")
Traceback (most recent call last):
  File "/usr/local/lib/python3.12/site-packages/celery/utils/dispatch/signal.py", line 276, in send
    response = receiver(signal=self, sender=sender, **named)
               ^^^^^^^^^^^^^^^^^^^^^^^^^^^^^^^^^^^^^^^^^^^^^
  File "/usr/local/lib/python3.12/site-packages/vine/promises.py", line 161, in __call__
    return self.throw()
           ^^^^^^^^^^^^
  File "/usr/local/lib/python3.12/site-packages/vine/promises.py", line 158, in __call__
    retval = fun(*final_args, **final_kwargs)
             ^^^^^^^^^^^^^^^^^^^^^^^^^^^^^^^^
  File "/usr/local/lib/python3.12/site-packages/celery/app/base.py", line 694, in _autodiscover_tasks
    return self._autodiscover_tasks_from_fixups(related_name)
           ^^^^^^^^^^^^^^^^^^^^^^^^^^^^^^^^^^^^^^^^^^^^^^^^^^
  File "/usr/local/lib/python3.12/site-packages/celery/app/base.py", line 703, in _autodiscover_tasks_from_fixups
    return self._autodiscover_tasks_from_names([
           ^^^^^^^^^^^^^^^^^^^^^^^^^^^^^^^^^^^^^
  File "/usr/local/lib/python3.12/site-packages/celery/app/base.py", line 698, in _autodiscover_tasks_from_names
    return self.loader.autodiscover_tasks(
           ^^^^^^^^^^^^^^^^^^^^^^^^^^^^^^^
  File "/usr/local/lib/python3.12/site-packages/celery/loaders/base.py", line 220, in autodiscover_tasks
    mod.__name__ for mod in autodiscover_tasks(packages or (),
                            ^^^^^^^^^^^^^^^^^^^^^^^^^^^^^^^^^^
  File "/usr/local/lib/python3.12/site-packages/celery/loaders/base.py", line 246, in autodiscover_tasks
    return [find_related_module(pkg, related_name) for pkg in packages]
            ^^^^^^^^^^^^^^^^^^^^^^^^^^^^^^^^^^^^^^
  File "/usr/local/lib/python3.12/site-packages/celery/loaders/base.py", line 278, in find_related_module
    raise e
  File "/usr/local/lib/python3.12/site-packages/celery/loaders/base.py", line 270, in find_related_module
    return importlib.import_module(module_name)
           ^^^^^^^^^^^^^^^^^^^^^^^^^^^^^^^^^^^^
  File "/usr/local/lib/python3.12/importlib/__init__.py", line 90, in import_module
    return _bootstrap._gcd_import(name[level:], package, level)
           ^^^^^^^^^^^^^^^^^^^^^^^^^^^^^^^^^^^^^^^^^^^^^^^^^^^^
  File "<frozen importlib._bootstrap>", line 1387, in _gcd_import
  File "<frozen importlib._bootstrap>", line 1360, in _find_and_load
  File "<frozen importlib._bootstrap>", line 1331, in _find_and_load_unlocked
  File "<frozen importlib._bootstrap>", line 935, in _load_unlocked
  File "<frozen importlib._bootstrap_external>", line 995, in exec_module
  File "<frozen importlib._bootstrap>", line 488, in _call_with_frames_removed
  File "/app/telegrambot/tasks.py", line 2, in <module>
    from .bot import bot
  File "/app/telegrambot/bot.py", line 5, in <module>
    import telebot
ModuleNotFoundError: No module named 'telebot'
ERROR 2024-05-31 17:27:48,808 signal 18 140171025890104 Signal handler <promise@0x7f7c1ea20910 --> <bound method Celery._autodiscover_tasks of <Celery eazyclass at 0x7f7c1ea4f8c0>>> raised: ModuleNotFoundError("No module named 'telebot'")
Traceback (most recent call last):
  File "/usr/local/lib/python3.12/site-packages/celery/utils/dispatch/signal.py", line 276, in send
    response = receiver(signal=self, sender=sender, **named)
               ^^^^^^^^^^^^^^^^^^^^^^^^^^^^^^^^^^^^^^^^^^^^^
  File "/usr/local/lib/python3.12/site-packages/vine/promises.py", line 161, in __call__
    return self.throw()
           ^^^^^^^^^^^^
  File "/usr/local/lib/python3.12/site-packages/vine/promises.py", line 158, in __call__
    retval = fun(*final_args, **final_kwargs)
             ^^^^^^^^^^^^^^^^^^^^^^^^^^^^^^^^
  File "/usr/local/lib/python3.12/site-packages/celery/app/base.py", line 694, in _autodiscover_tasks
    return self._autodiscover_tasks_from_fixups(related_name)
           ^^^^^^^^^^^^^^^^^^^^^^^^^^^^^^^^^^^^^^^^^^^^^^^^^^
  File "/usr/local/lib/python3.12/site-packages/celery/app/base.py", line 703, in _autodiscover_tasks_from_fixups
    return self._autodiscover_tasks_from_names([
           ^^^^^^^^^^^^^^^^^^^^^^^^^^^^^^^^^^^^^
  File "/usr/local/lib/python3.12/site-packages/celery/app/base.py", line 698, in _autodiscover_tasks_from_names
    return self.loader.autodiscover_tasks(
           ^^^^^^^^^^^^^^^^^^^^^^^^^^^^^^^
  File "/usr/local/lib/python3.12/site-packages/celery/loaders/base.py", line 220, in autodiscover_tasks
    mod.__name__ for mod in autodiscover_tasks(packages or (),
                            ^^^^^^^^^^^^^^^^^^^^^^^^^^^^^^^^^^
  File "/usr/local/lib/python3.12/site-packages/celery/loaders/base.py", line 246, in autodiscover_tasks
    return [find_related_module(pkg, related_name) for pkg in packages]
            ^^^^^^^^^^^^^^^^^^^^^^^^^^^^^^^^^^^^^^
  File "/usr/local/lib/python3.12/site-packages/celery/loaders/base.py", line 278, in find_related_module
    raise e
  File "/usr/local/lib/python3.12/site-packages/celery/loaders/base.py", line 270, in find_related_module
    return importlib.import_module(module_name)
           ^^^^^^^^^^^^^^^^^^^^^^^^^^^^^^^^^^^^
  File "/usr/local/lib/python3.12/importlib/__init__.py", line 90, in import_module
    return _bootstrap._gcd_import(name[level:], package, level)
           ^^^^^^^^^^^^^^^^^^^^^^^^^^^^^^^^^^^^^^^^^^^^^^^^^^^^
  File "<frozen importlib._bootstrap>", line 1387, in _gcd_import
  File "<frozen importlib._bootstrap>", line 1360, in _find_and_load
  File "<frozen importlib._bootstrap>", line 1331, in _find_and_load_unlocked
  File "<frozen importlib._bootstrap>", line 935, in _load_unlocked
  File "<frozen importlib._bootstrap_external>", line 995, in exec_module
  File "<frozen importlib._bootstrap>", line 488, in _call_with_frames_removed
  File "/app/telegrambot/tasks.py", line 2, in <module>
    from .bot import bot
  File "/app/telegrambot/bot.py", line 5, in <module>
    import telebot
ModuleNotFoundError: No module named 'telebot'
INFO 2024-05-31 17:28:29,920 command 1 139804679994152 15 detected, shutting down
ERROR 2024-05-31 17:28:38,935 signal 1 139872107428648 Signal handler <promise@0x7f36801bc870 --> <bound method Celery._autodiscover_tasks of <Celery eazyclass at 0x7f368019c1a0>>> raised: ModuleNotFoundError("No module named 'eazyclass.scheduler'")
Traceback (most recent call last):
  File "/usr/local/lib/python3.12/site-packages/celery/utils/dispatch/signal.py", line 276, in send
    response = receiver(signal=self, sender=sender, **named)
               ^^^^^^^^^^^^^^^^^^^^^^^^^^^^^^^^^^^^^^^^^^^^^
  File "/usr/local/lib/python3.12/site-packages/vine/promises.py", line 161, in __call__
    return self.throw()
           ^^^^^^^^^^^^
  File "/usr/local/lib/python3.12/site-packages/vine/promises.py", line 158, in __call__
    retval = fun(*final_args, **final_kwargs)
             ^^^^^^^^^^^^^^^^^^^^^^^^^^^^^^^^
  File "/usr/local/lib/python3.12/site-packages/celery/app/base.py", line 694, in _autodiscover_tasks
    return self._autodiscover_tasks_from_fixups(related_name)
           ^^^^^^^^^^^^^^^^^^^^^^^^^^^^^^^^^^^^^^^^^^^^^^^^^^
  File "/usr/local/lib/python3.12/site-packages/celery/app/base.py", line 703, in _autodiscover_tasks_from_fixups
    return self._autodiscover_tasks_from_names([
           ^^^^^^^^^^^^^^^^^^^^^^^^^^^^^^^^^^^^^
  File "/usr/local/lib/python3.12/site-packages/celery/app/base.py", line 698, in _autodiscover_tasks_from_names
    return self.loader.autodiscover_tasks(
           ^^^^^^^^^^^^^^^^^^^^^^^^^^^^^^^
  File "/usr/local/lib/python3.12/site-packages/celery/loaders/base.py", line 220, in autodiscover_tasks
    mod.__name__ for mod in autodiscover_tasks(packages or (),
                            ^^^^^^^^^^^^^^^^^^^^^^^^^^^^^^^^^^
  File "/usr/local/lib/python3.12/site-packages/celery/loaders/base.py", line 246, in autodiscover_tasks
    return [find_related_module(pkg, related_name) for pkg in packages]
            ^^^^^^^^^^^^^^^^^^^^^^^^^^^^^^^^^^^^^^
  File "/usr/local/lib/python3.12/site-packages/celery/loaders/base.py", line 278, in find_related_module
    raise e
  File "/usr/local/lib/python3.12/site-packages/celery/loaders/base.py", line 270, in find_related_module
    return importlib.import_module(module_name)
           ^^^^^^^^^^^^^^^^^^^^^^^^^^^^^^^^^^^^
  File "/usr/local/lib/python3.12/importlib/__init__.py", line 90, in import_module
    return _bootstrap._gcd_import(name[level:], package, level)
           ^^^^^^^^^^^^^^^^^^^^^^^^^^^^^^^^^^^^^^^^^^^^^^^^^^^^
  File "<frozen importlib._bootstrap>", line 1387, in _gcd_import
  File "<frozen importlib._bootstrap>", line 1360, in _find_and_load
  File "<frozen importlib._bootstrap>", line 1331, in _find_and_load_unlocked
  File "<frozen importlib._bootstrap>", line 935, in _load_unlocked
  File "<frozen importlib._bootstrap_external>", line 995, in exec_module
  File "<frozen importlib._bootstrap>", line 488, in _call_with_frames_removed
  File "/app/telegrambot/tasks.py", line 2, in <module>
    from .bot import bot
  File "/app/telegrambot/bot.py", line 8, in <module>
    from .bot_keyboards import generate_faculty_keyboard, generate_group_keyboard, generate_course_keyboard
  File "/app/telegrambot/bot_keyboards.py", line 8, in <module>
    from eazyclass.scheduler.models import Faculty, Group, Teacher
ModuleNotFoundError: No module named 'eazyclass.scheduler'
ERROR 2024-05-31 17:28:39,081 signal 1 140304260594472 Signal handler <promise@0x7f9b1e734870 --> <bound method Celery._autodiscover_tasks of <Celery eazyclass at 0x7f9b1e70be30>>> raised: ModuleNotFoundError("No module named 'telebot'")
Traceback (most recent call last):
  File "/usr/local/lib/python3.12/site-packages/celery/utils/dispatch/signal.py", line 276, in send
    response = receiver(signal=self, sender=sender, **named)
               ^^^^^^^^^^^^^^^^^^^^^^^^^^^^^^^^^^^^^^^^^^^^^
  File "/usr/local/lib/python3.12/site-packages/vine/promises.py", line 161, in __call__
    return self.throw()
           ^^^^^^^^^^^^
  File "/usr/local/lib/python3.12/site-packages/vine/promises.py", line 158, in __call__
    retval = fun(*final_args, **final_kwargs)
             ^^^^^^^^^^^^^^^^^^^^^^^^^^^^^^^^
  File "/usr/local/lib/python3.12/site-packages/celery/app/base.py", line 694, in _autodiscover_tasks
    return self._autodiscover_tasks_from_fixups(related_name)
           ^^^^^^^^^^^^^^^^^^^^^^^^^^^^^^^^^^^^^^^^^^^^^^^^^^
  File "/usr/local/lib/python3.12/site-packages/celery/app/base.py", line 703, in _autodiscover_tasks_from_fixups
    return self._autodiscover_tasks_from_names([
           ^^^^^^^^^^^^^^^^^^^^^^^^^^^^^^^^^^^^^
  File "/usr/local/lib/python3.12/site-packages/celery/app/base.py", line 698, in _autodiscover_tasks_from_names
    return self.loader.autodiscover_tasks(
           ^^^^^^^^^^^^^^^^^^^^^^^^^^^^^^^
  File "/usr/local/lib/python3.12/site-packages/celery/loaders/base.py", line 220, in autodiscover_tasks
    mod.__name__ for mod in autodiscover_tasks(packages or (),
                            ^^^^^^^^^^^^^^^^^^^^^^^^^^^^^^^^^^
  File "/usr/local/lib/python3.12/site-packages/celery/loaders/base.py", line 246, in autodiscover_tasks
    return [find_related_module(pkg, related_name) for pkg in packages]
            ^^^^^^^^^^^^^^^^^^^^^^^^^^^^^^^^^^^^^^
  File "/usr/local/lib/python3.12/site-packages/celery/loaders/base.py", line 278, in find_related_module
    raise e
  File "/usr/local/lib/python3.12/site-packages/celery/loaders/base.py", line 270, in find_related_module
    return importlib.import_module(module_name)
           ^^^^^^^^^^^^^^^^^^^^^^^^^^^^^^^^^^^^
  File "/usr/local/lib/python3.12/importlib/__init__.py", line 90, in import_module
    return _bootstrap._gcd_import(name[level:], package, level)
           ^^^^^^^^^^^^^^^^^^^^^^^^^^^^^^^^^^^^^^^^^^^^^^^^^^^^
  File "<frozen importlib._bootstrap>", line 1387, in _gcd_import
  File "<frozen importlib._bootstrap>", line 1360, in _find_and_load
  File "<frozen importlib._bootstrap>", line 1331, in _find_and_load_unlocked
  File "<frozen importlib._bootstrap>", line 935, in _load_unlocked
  File "<frozen importlib._bootstrap_external>", line 995, in exec_module
  File "<frozen importlib._bootstrap>", line 488, in _call_with_frames_removed
  File "/app/telegrambot/tasks.py", line 2, in <module>
    from .bot import bot
  File "/app/telegrambot/bot.py", line 5, in <module>
    import telebot
ModuleNotFoundError: No module named 'telebot'
ERROR 2024-05-31 17:28:39,092 signal 1 139850083818280 Signal handler <promise@0x7f315f660870 --> <bound method Celery._autodiscover_tasks of <Celery eazyclass at 0x7f315f801130>>> raised: ModuleNotFoundError("No module named 'eazyclass.scheduler'")
Traceback (most recent call last):
  File "/usr/local/lib/python3.12/site-packages/celery/utils/dispatch/signal.py", line 276, in send
    response = receiver(signal=self, sender=sender, **named)
               ^^^^^^^^^^^^^^^^^^^^^^^^^^^^^^^^^^^^^^^^^^^^^
  File "/usr/local/lib/python3.12/site-packages/vine/promises.py", line 161, in __call__
    return self.throw()
           ^^^^^^^^^^^^
  File "/usr/local/lib/python3.12/site-packages/vine/promises.py", line 158, in __call__
    retval = fun(*final_args, **final_kwargs)
             ^^^^^^^^^^^^^^^^^^^^^^^^^^^^^^^^
  File "/usr/local/lib/python3.12/site-packages/celery/app/base.py", line 694, in _autodiscover_tasks
    return self._autodiscover_tasks_from_fixups(related_name)
           ^^^^^^^^^^^^^^^^^^^^^^^^^^^^^^^^^^^^^^^^^^^^^^^^^^
  File "/usr/local/lib/python3.12/site-packages/celery/app/base.py", line 703, in _autodiscover_tasks_from_fixups
    return self._autodiscover_tasks_from_names([
           ^^^^^^^^^^^^^^^^^^^^^^^^^^^^^^^^^^^^^
  File "/usr/local/lib/python3.12/site-packages/celery/app/base.py", line 698, in _autodiscover_tasks_from_names
    return self.loader.autodiscover_tasks(
           ^^^^^^^^^^^^^^^^^^^^^^^^^^^^^^^
  File "/usr/local/lib/python3.12/site-packages/celery/loaders/base.py", line 220, in autodiscover_tasks
    mod.__name__ for mod in autodiscover_tasks(packages or (),
                            ^^^^^^^^^^^^^^^^^^^^^^^^^^^^^^^^^^
  File "/usr/local/lib/python3.12/site-packages/celery/loaders/base.py", line 246, in autodiscover_tasks
    return [find_related_module(pkg, related_name) for pkg in packages]
            ^^^^^^^^^^^^^^^^^^^^^^^^^^^^^^^^^^^^^^
  File "/usr/local/lib/python3.12/site-packages/celery/loaders/base.py", line 278, in find_related_module
    raise e
  File "/usr/local/lib/python3.12/site-packages/celery/loaders/base.py", line 270, in find_related_module
    return importlib.import_module(module_name)
           ^^^^^^^^^^^^^^^^^^^^^^^^^^^^^^^^^^^^
  File "/usr/local/lib/python3.12/importlib/__init__.py", line 90, in import_module
    return _bootstrap._gcd_import(name[level:], package, level)
           ^^^^^^^^^^^^^^^^^^^^^^^^^^^^^^^^^^^^^^^^^^^^^^^^^^^^
  File "<frozen importlib._bootstrap>", line 1387, in _gcd_import
  File "<frozen importlib._bootstrap>", line 1360, in _find_and_load
  File "<frozen importlib._bootstrap>", line 1331, in _find_and_load_unlocked
  File "<frozen importlib._bootstrap>", line 935, in _load_unlocked
  File "<frozen importlib._bootstrap_external>", line 995, in exec_module
  File "<frozen importlib._bootstrap>", line 488, in _call_with_frames_removed
  File "/app/telegrambot/tasks.py", line 2, in <module>
    from .bot import bot
  File "/app/telegrambot/bot.py", line 8, in <module>
    from .bot_keyboards import generate_faculty_keyboard, generate_group_keyboard, generate_course_keyboard
  File "/app/telegrambot/bot_keyboards.py", line 8, in <module>
    from eazyclass.scheduler.models import Faculty, Group, Teacher
ModuleNotFoundError: No module named 'eazyclass.scheduler'
ERROR 2024-05-31 17:28:39,099 signal 1 140645971331880 Signal handler <promise@0x7feaadff0870 --> <bound method Celery._autodiscover_tasks of <Celery eazyclass at 0x7feaaf4d4ad0>>> raised: ModuleNotFoundError("No module named 'eazyclass.scheduler'")
Traceback (most recent call last):
  File "/usr/local/lib/python3.12/site-packages/celery/utils/dispatch/signal.py", line 276, in send
    response = receiver(signal=self, sender=sender, **named)
               ^^^^^^^^^^^^^^^^^^^^^^^^^^^^^^^^^^^^^^^^^^^^^
  File "/usr/local/lib/python3.12/site-packages/vine/promises.py", line 161, in __call__
    return self.throw()
           ^^^^^^^^^^^^
  File "/usr/local/lib/python3.12/site-packages/vine/promises.py", line 158, in __call__
    retval = fun(*final_args, **final_kwargs)
             ^^^^^^^^^^^^^^^^^^^^^^^^^^^^^^^^
  File "/usr/local/lib/python3.12/site-packages/celery/app/base.py", line 694, in _autodiscover_tasks
    return self._autodiscover_tasks_from_fixups(related_name)
           ^^^^^^^^^^^^^^^^^^^^^^^^^^^^^^^^^^^^^^^^^^^^^^^^^^
  File "/usr/local/lib/python3.12/site-packages/celery/app/base.py", line 703, in _autodiscover_tasks_from_fixups
    return self._autodiscover_tasks_from_names([
           ^^^^^^^^^^^^^^^^^^^^^^^^^^^^^^^^^^^^^
  File "/usr/local/lib/python3.12/site-packages/celery/app/base.py", line 698, in _autodiscover_tasks_from_names
    return self.loader.autodiscover_tasks(
           ^^^^^^^^^^^^^^^^^^^^^^^^^^^^^^^
  File "/usr/local/lib/python3.12/site-packages/celery/loaders/base.py", line 220, in autodiscover_tasks
    mod.__name__ for mod in autodiscover_tasks(packages or (),
                            ^^^^^^^^^^^^^^^^^^^^^^^^^^^^^^^^^^
  File "/usr/local/lib/python3.12/site-packages/celery/loaders/base.py", line 246, in autodiscover_tasks
    return [find_related_module(pkg, related_name) for pkg in packages]
            ^^^^^^^^^^^^^^^^^^^^^^^^^^^^^^^^^^^^^^
  File "/usr/local/lib/python3.12/site-packages/celery/loaders/base.py", line 278, in find_related_module
    raise e
  File "/usr/local/lib/python3.12/site-packages/celery/loaders/base.py", line 270, in find_related_module
    return importlib.import_module(module_name)
           ^^^^^^^^^^^^^^^^^^^^^^^^^^^^^^^^^^^^
  File "/usr/local/lib/python3.12/importlib/__init__.py", line 90, in import_module
    return _bootstrap._gcd_import(name[level:], package, level)
           ^^^^^^^^^^^^^^^^^^^^^^^^^^^^^^^^^^^^^^^^^^^^^^^^^^^^
  File "<frozen importlib._bootstrap>", line 1387, in _gcd_import
  File "<frozen importlib._bootstrap>", line 1360, in _find_and_load
  File "<frozen importlib._bootstrap>", line 1331, in _find_and_load_unlocked
  File "<frozen importlib._bootstrap>", line 935, in _load_unlocked
  File "<frozen importlib._bootstrap_external>", line 995, in exec_module
  File "<frozen importlib._bootstrap>", line 488, in _call_with_frames_removed
  File "/app/telegrambot/tasks.py", line 2, in <module>
    from .bot import bot
  File "/app/telegrambot/bot.py", line 8, in <module>
    from .bot_keyboards import generate_faculty_keyboard, generate_group_keyboard, generate_course_keyboard
  File "/app/telegrambot/bot_keyboards.py", line 8, in <module>
    from eazyclass.scheduler.models import Faculty, Group, Teacher
ModuleNotFoundError: No module named 'eazyclass.scheduler'
ERROR 2024-05-31 17:30:05,113 signal 1 140034764196648 Signal handler <promise@0x7f5c5f3d4870 --> <bound method Celery._autodiscover_tasks of <Celery eazyclass at 0x7f5c5f39c350>>> raised: ModuleNotFoundError("No module named 'telebot'")
Traceback (most recent call last):
  File "/usr/local/lib/python3.12/site-packages/celery/utils/dispatch/signal.py", line 276, in send
    response = receiver(signal=self, sender=sender, **named)
               ^^^^^^^^^^^^^^^^^^^^^^^^^^^^^^^^^^^^^^^^^^^^^
  File "/usr/local/lib/python3.12/site-packages/vine/promises.py", line 161, in __call__
    return self.throw()
           ^^^^^^^^^^^^
  File "/usr/local/lib/python3.12/site-packages/vine/promises.py", line 158, in __call__
    retval = fun(*final_args, **final_kwargs)
             ^^^^^^^^^^^^^^^^^^^^^^^^^^^^^^^^
  File "/usr/local/lib/python3.12/site-packages/celery/app/base.py", line 694, in _autodiscover_tasks
    return self._autodiscover_tasks_from_fixups(related_name)
           ^^^^^^^^^^^^^^^^^^^^^^^^^^^^^^^^^^^^^^^^^^^^^^^^^^
  File "/usr/local/lib/python3.12/site-packages/celery/app/base.py", line 703, in _autodiscover_tasks_from_fixups
    return self._autodiscover_tasks_from_names([
           ^^^^^^^^^^^^^^^^^^^^^^^^^^^^^^^^^^^^^
  File "/usr/local/lib/python3.12/site-packages/celery/app/base.py", line 698, in _autodiscover_tasks_from_names
    return self.loader.autodiscover_tasks(
           ^^^^^^^^^^^^^^^^^^^^^^^^^^^^^^^
  File "/usr/local/lib/python3.12/site-packages/celery/loaders/base.py", line 220, in autodiscover_tasks
    mod.__name__ for mod in autodiscover_tasks(packages or (),
                            ^^^^^^^^^^^^^^^^^^^^^^^^^^^^^^^^^^
  File "/usr/local/lib/python3.12/site-packages/celery/loaders/base.py", line 246, in autodiscover_tasks
    return [find_related_module(pkg, related_name) for pkg in packages]
            ^^^^^^^^^^^^^^^^^^^^^^^^^^^^^^^^^^^^^^
  File "/usr/local/lib/python3.12/site-packages/celery/loaders/base.py", line 278, in find_related_module
    raise e
  File "/usr/local/lib/python3.12/site-packages/celery/loaders/base.py", line 270, in find_related_module
    return importlib.import_module(module_name)
           ^^^^^^^^^^^^^^^^^^^^^^^^^^^^^^^^^^^^
  File "/usr/local/lib/python3.12/importlib/__init__.py", line 90, in import_module
    return _bootstrap._gcd_import(name[level:], package, level)
           ^^^^^^^^^^^^^^^^^^^^^^^^^^^^^^^^^^^^^^^^^^^^^^^^^^^^
  File "<frozen importlib._bootstrap>", line 1387, in _gcd_import
  File "<frozen importlib._bootstrap>", line 1360, in _find_and_load
  File "<frozen importlib._bootstrap>", line 1331, in _find_and_load_unlocked
  File "<frozen importlib._bootstrap>", line 935, in _load_unlocked
  File "<frozen importlib._bootstrap_external>", line 995, in exec_module
  File "<frozen importlib._bootstrap>", line 488, in _call_with_frames_removed
  File "/app/telegrambot/tasks.py", line 2, in <module>
    from .bot import bot
  File "/app/telegrambot/bot.py", line 5, in <module>
    import telebot
ModuleNotFoundError: No module named 'telebot'
INFO 2024-05-31 17:31:01,713 command 1 140350626515752 Visit me at http://0.0.0.0:5555
INFO 2024-05-31 17:31:01,725 command 1 140350626515752 Broker: redis://redis:6379/0
INFO 2024-05-31 17:31:01,735 command 1 140350626515752 Registered tasks: 
['celery.accumulate',
 'celery.backend_cleanup',
 'celery.chain',
 'celery.chord',
 'celery.chord_unlock',
 'celery.chunks',
 'celery.group',
 'celery.map',
 'celery.starmap',
 'scheduler.tasks.group_parser.deactivate_all_groups',
 'scheduler.tasks.group_parser.update_groups',
 'scheduler.tasks.schedule_parser.parse_group_data',
 'scheduler.tasks.schedule_parser.process_data_final',
 'scheduler.tasks.schedule_parser.send_group_notification',
 'scheduler.tasks.schedule_parser.send_notifications',
 'scheduler.tasks.schedule_parser.update_schedule',
 'scheduler.tasks.timetable_manager.fill_lesson_times',
 'scheduler.tasks.update_last_active.delete_inactive_records',
 'scheduler.tasks.update_last_active.update_last_active_records']
INFO 2024-05-31 17:31:01,745 mixins 1 140350532328248 Connected to redis://redis:6379/0
WARNING 2024-05-31 17:31:02,798 inspector 1 140350530206520 Inspect method active_queues failed
WARNING 2024-05-31 17:31:02,799 inspector 1 140350522792760 Inspect method conf failed
WARNING 2024-05-31 17:31:02,803 inspector 1 140350528084792 Inspect method scheduled failed
WARNING 2024-05-31 17:31:02,805 inspector 1 140350531267384 Inspect method stats failed
WARNING 2024-05-31 17:31:02,808 inspector 1 140350529145656 Inspect method registered failed
WARNING 2024-05-31 17:31:02,810 inspector 1 140350525963064 Inspect method reserved failed
WARNING 2024-05-31 17:31:02,810 inspector 1 140350527023928 Inspect method active failed
WARNING 2024-05-31 17:31:02,813 inspector 1 140350523853624 Inspect method revoked failed
INFO 2024-06-19 21:17:11,191 command 1 140319282707240 Visit me at http://0.0.0.0:5555
INFO 2024-06-19 21:17:11,214 command 1 140319282707240 Broker: redis://redis:6379/0
INFO 2024-06-19 21:17:11,223 command 1 140319282707240 Registered tasks: 
['celery.accumulate',
 'celery.backend_cleanup',
 'celery.chain',
 'celery.chord',
 'celery.chord_unlock',
 'celery.chunks',
 'celery.group',
 'celery.map',
 'celery.starmap',
 'scheduler.tasks.group_parser.deactivate_all_groups',
 'scheduler.tasks.group_parser.update_groups',
 'scheduler.tasks.schedule_parser.parse_group_data',
 'scheduler.tasks.schedule_parser.process_data_final',
 'scheduler.tasks.schedule_parser.send_group_notification',
 'scheduler.tasks.schedule_parser.send_notifications',
 'scheduler.tasks.schedule_parser.update_schedule',
 'scheduler.tasks.timetable_manager.fill_lesson_times',
 'scheduler.tasks.update_last_active.delete_inactive_records',
 'scheduler.tasks.update_last_active.update_last_active_records']
INFO 2024-06-19 21:17:11,233 mixins 1 140319188036408 Connected to redis://redis:6379/0
WARNING 2024-06-19 21:17:12,277 inspector 1 140319179549496 Inspect method conf failed
WARNING 2024-06-19 21:17:12,284 inspector 1 140319181671224 Inspect method reserved failed
WARNING 2024-06-19 21:17:12,285 inspector 1 140319180610360 Inspect method revoked failed
WARNING 2024-06-19 21:17:12,287 inspector 1 140319184853816 Inspect method registered failed
WARNING 2024-06-19 21:17:12,289 inspector 1 140319183792952 Inspect method scheduled failed
WARNING 2024-06-19 21:17:12,293 inspector 1 140319182732088 Inspect method active failed
WARNING 2024-06-19 21:17:12,295 inspector 1 140319186975544 Inspect method stats failed
WARNING 2024-06-19 21:17:12,295 inspector 1 140319185914680 Inspect method active_queues failed
INFO 2024-06-20 00:13:30,819 command 1 140319282707240 15 detected, shutting down
ERROR 2024-06-24 00:54:30,820 signal 1 140107370146600 Signal handler <bound method DjangoFixup.on_import_modules of <celery.fixups.django.DjangoFixup object at 0x7f6d47282b70>> raised: ModuleNotFoundError("No module named 'debug_toolbar'")
Traceback (most recent call last):
  File "/usr/local/lib/python3.12/site-packages/celery/utils/dispatch/signal.py", line 276, in send
    response = receiver(signal=self, sender=sender, **named)
               ^^^^^^^^^^^^^^^^^^^^^^^^^^^^^^^^^^^^^^^^^^^^^
  File "/usr/local/lib/python3.12/site-packages/celery/fixups/django.py", line 100, in on_import_modules
    self.worker_fixup.validate_models()
  File "/usr/local/lib/python3.12/site-packages/celery/fixups/django.py", line 138, in validate_models
    self.django_setup()
  File "/usr/local/lib/python3.12/site-packages/celery/fixups/django.py", line 134, in django_setup
    django.setup()
  File "/usr/local/lib/python3.12/site-packages/django/__init__.py", line 24, in setup
    apps.populate(settings.INSTALLED_APPS)
  File "/usr/local/lib/python3.12/site-packages/django/apps/registry.py", line 91, in populate
    app_config = AppConfig.create(entry)
                 ^^^^^^^^^^^^^^^^^^^^^^^
  File "/usr/local/lib/python3.12/site-packages/django/apps/config.py", line 193, in create
    import_module(entry)
  File "/usr/local/lib/python3.12/importlib/__init__.py", line 90, in import_module
    return _bootstrap._gcd_import(name[level:], package, level)
           ^^^^^^^^^^^^^^^^^^^^^^^^^^^^^^^^^^^^^^^^^^^^^^^^^^^^
  File "<frozen importlib._bootstrap>", line 1387, in _gcd_import
  File "<frozen importlib._bootstrap>", line 1360, in _find_and_load
  File "<frozen importlib._bootstrap>", line 1324, in _find_and_load_unlocked
ModuleNotFoundError: No module named 'debug_toolbar'
ERROR 2024-06-24 00:54:30,824 signal 1 140107370146600 Signal handler <promise@0x7f6d46e00870 --> <bound method Celery._autodiscover_tasks of <Celery eazyclass at 0x7f6d46fb7cb0>>> raised: AppRegistryNotReady("Apps aren't loaded yet.")
Traceback (most recent call last):
  File "/usr/local/lib/python3.12/site-packages/celery/utils/dispatch/signal.py", line 276, in send
    response = receiver(signal=self, sender=sender, **named)
               ^^^^^^^^^^^^^^^^^^^^^^^^^^^^^^^^^^^^^^^^^^^^^
  File "/usr/local/lib/python3.12/site-packages/vine/promises.py", line 161, in __call__
    return self.throw()
           ^^^^^^^^^^^^
  File "/usr/local/lib/python3.12/site-packages/vine/promises.py", line 158, in __call__
    retval = fun(*final_args, **final_kwargs)
             ^^^^^^^^^^^^^^^^^^^^^^^^^^^^^^^^
  File "/usr/local/lib/python3.12/site-packages/celery/app/base.py", line 694, in _autodiscover_tasks
    return self._autodiscover_tasks_from_fixups(related_name)
           ^^^^^^^^^^^^^^^^^^^^^^^^^^^^^^^^^^^^^^^^^^^^^^^^^^
  File "/usr/local/lib/python3.12/site-packages/celery/app/base.py", line 706, in _autodiscover_tasks_from_fixups
    for pkg in fixup.autodiscover_tasks()
               ^^^^^^^^^^^^^^^^^^^^^^^^^^
  File "/usr/local/lib/python3.12/site-packages/celery/fixups/django.py", line 110, in autodiscover_tasks
    return [config.name for config in apps.get_app_configs()]
                                      ^^^^^^^^^^^^^^^^^^^^^^
  File "/usr/local/lib/python3.12/site-packages/django/apps/registry.py", line 147, in get_app_configs
    self.check_apps_ready()
  File "/usr/local/lib/python3.12/site-packages/django/apps/registry.py", line 138, in check_apps_ready
    raise AppRegistryNotReady("Apps aren't loaded yet.")
django.core.exceptions.AppRegistryNotReady: Apps aren't loaded yet.
ERROR 2024-06-24 00:54:30,858 signal 1 140594372213544 Signal handler <bound method DjangoFixup.on_import_modules of <celery.fixups.django.DjangoFixup object at 0x7fdeaa6f81d0>> raised: ModuleNotFoundError("No module named 'debug_toolbar'")
Traceback (most recent call last):
  File "/usr/local/lib/python3.12/site-packages/celery/utils/dispatch/signal.py", line 276, in send
    response = receiver(signal=self, sender=sender, **named)
               ^^^^^^^^^^^^^^^^^^^^^^^^^^^^^^^^^^^^^^^^^^^^^
  File "/usr/local/lib/python3.12/site-packages/celery/fixups/django.py", line 100, in on_import_modules
    self.worker_fixup.validate_models()
  File "/usr/local/lib/python3.12/site-packages/celery/fixups/django.py", line 138, in validate_models
    self.django_setup()
  File "/usr/local/lib/python3.12/site-packages/celery/fixups/django.py", line 134, in django_setup
    django.setup()
  File "/usr/local/lib/python3.12/site-packages/django/__init__.py", line 24, in setup
    apps.populate(settings.INSTALLED_APPS)
  File "/usr/local/lib/python3.12/site-packages/django/apps/registry.py", line 91, in populate
    app_config = AppConfig.create(entry)
                 ^^^^^^^^^^^^^^^^^^^^^^^
  File "/usr/local/lib/python3.12/site-packages/django/apps/config.py", line 193, in create
    import_module(entry)
  File "/usr/local/lib/python3.12/importlib/__init__.py", line 90, in import_module
    return _bootstrap._gcd_import(name[level:], package, level)
           ^^^^^^^^^^^^^^^^^^^^^^^^^^^^^^^^^^^^^^^^^^^^^^^^^^^^
  File "<frozen importlib._bootstrap>", line 1387, in _gcd_import
  File "<frozen importlib._bootstrap>", line 1360, in _find_and_load
  File "<frozen importlib._bootstrap>", line 1324, in _find_and_load_unlocked
ModuleNotFoundError: No module named 'debug_toolbar'
ERROR 2024-06-24 00:54:30,861 signal 1 140594372213544 Signal handler <promise@0x7fdeaa6fc870 --> <bound method Celery._autodiscover_tasks of <Celery eazyclass at 0x7fdeaa6f8050>>> raised: AppRegistryNotReady("Apps aren't loaded yet.")
Traceback (most recent call last):
  File "/usr/local/lib/python3.12/site-packages/celery/utils/dispatch/signal.py", line 276, in send
    response = receiver(signal=self, sender=sender, **named)
               ^^^^^^^^^^^^^^^^^^^^^^^^^^^^^^^^^^^^^^^^^^^^^
  File "/usr/local/lib/python3.12/site-packages/vine/promises.py", line 161, in __call__
    return self.throw()
           ^^^^^^^^^^^^
  File "/usr/local/lib/python3.12/site-packages/vine/promises.py", line 158, in __call__
    retval = fun(*final_args, **final_kwargs)
             ^^^^^^^^^^^^^^^^^^^^^^^^^^^^^^^^
  File "/usr/local/lib/python3.12/site-packages/celery/app/base.py", line 694, in _autodiscover_tasks
    return self._autodiscover_tasks_from_fixups(related_name)
           ^^^^^^^^^^^^^^^^^^^^^^^^^^^^^^^^^^^^^^^^^^^^^^^^^^
  File "/usr/local/lib/python3.12/site-packages/celery/app/base.py", line 706, in _autodiscover_tasks_from_fixups
    for pkg in fixup.autodiscover_tasks()
               ^^^^^^^^^^^^^^^^^^^^^^^^^^
  File "/usr/local/lib/python3.12/site-packages/celery/fixups/django.py", line 110, in autodiscover_tasks
    return [config.name for config in apps.get_app_configs()]
                                      ^^^^^^^^^^^^^^^^^^^^^^
  File "/usr/local/lib/python3.12/site-packages/django/apps/registry.py", line 147, in get_app_configs
    self.check_apps_ready()
  File "/usr/local/lib/python3.12/site-packages/django/apps/registry.py", line 138, in check_apps_ready
    raise AppRegistryNotReady("Apps aren't loaded yet.")
django.core.exceptions.AppRegistryNotReady: Apps aren't loaded yet.
ERROR 2024-06-24 00:54:31,255 signal 1 139745978034984 Signal handler <bound method DjangoFixup.on_import_modules of <celery.fixups.django.DjangoFixup object at 0x7f192364d4c0>> raised: ModuleNotFoundError("No module named 'debug_toolbar'")
Traceback (most recent call last):
  File "/usr/local/lib/python3.12/site-packages/celery/utils/dispatch/signal.py", line 276, in send
    response = receiver(signal=self, sender=sender, **named)
               ^^^^^^^^^^^^^^^^^^^^^^^^^^^^^^^^^^^^^^^^^^^^^
  File "/usr/local/lib/python3.12/site-packages/celery/fixups/django.py", line 100, in on_import_modules
    self.worker_fixup.validate_models()
  File "/usr/local/lib/python3.12/site-packages/celery/fixups/django.py", line 138, in validate_models
    self.django_setup()
  File "/usr/local/lib/python3.12/site-packages/celery/fixups/django.py", line 134, in django_setup
    django.setup()
  File "/usr/local/lib/python3.12/site-packages/django/__init__.py", line 24, in setup
    apps.populate(settings.INSTALLED_APPS)
  File "/usr/local/lib/python3.12/site-packages/django/apps/registry.py", line 91, in populate
    app_config = AppConfig.create(entry)
                 ^^^^^^^^^^^^^^^^^^^^^^^
  File "/usr/local/lib/python3.12/site-packages/django/apps/config.py", line 193, in create
    import_module(entry)
  File "/usr/local/lib/python3.12/importlib/__init__.py", line 90, in import_module
    return _bootstrap._gcd_import(name[level:], package, level)
           ^^^^^^^^^^^^^^^^^^^^^^^^^^^^^^^^^^^^^^^^^^^^^^^^^^^^
  File "<frozen importlib._bootstrap>", line 1387, in _gcd_import
  File "<frozen importlib._bootstrap>", line 1360, in _find_and_load
  File "<frozen importlib._bootstrap>", line 1324, in _find_and_load_unlocked
ModuleNotFoundError: No module named 'debug_toolbar'
ERROR 2024-06-24 00:54:31,254 signal 1 139833691675432 Signal handler <bound method DjangoFixup.on_import_modules of <celery.fixups.django.DjangoFixup object at 0x7f2d8fac4d70>> raised: ModuleNotFoundError("No module named 'debug_toolbar'")
Traceback (most recent call last):
  File "/usr/local/lib/python3.12/site-packages/celery/utils/dispatch/signal.py", line 276, in send
    response = receiver(signal=self, sender=sender, **named)
               ^^^^^^^^^^^^^^^^^^^^^^^^^^^^^^^^^^^^^^^^^^^^^
  File "/usr/local/lib/python3.12/site-packages/celery/fixups/django.py", line 100, in on_import_modules
    self.worker_fixup.validate_models()
  File "/usr/local/lib/python3.12/site-packages/celery/fixups/django.py", line 138, in validate_models
    self.django_setup()
  File "/usr/local/lib/python3.12/site-packages/celery/fixups/django.py", line 134, in django_setup
    django.setup()
  File "/usr/local/lib/python3.12/site-packages/django/__init__.py", line 24, in setup
    apps.populate(settings.INSTALLED_APPS)
  File "/usr/local/lib/python3.12/site-packages/django/apps/registry.py", line 91, in populate
    app_config = AppConfig.create(entry)
                 ^^^^^^^^^^^^^^^^^^^^^^^
  File "/usr/local/lib/python3.12/site-packages/django/apps/config.py", line 193, in create
    import_module(entry)
  File "/usr/local/lib/python3.12/importlib/__init__.py", line 90, in import_module
    return _bootstrap._gcd_import(name[level:], package, level)
           ^^^^^^^^^^^^^^^^^^^^^^^^^^^^^^^^^^^^^^^^^^^^^^^^^^^^
  File "<frozen importlib._bootstrap>", line 1387, in _gcd_import
  File "<frozen importlib._bootstrap>", line 1360, in _find_and_load
  File "<frozen importlib._bootstrap>", line 1324, in _find_and_load_unlocked
ModuleNotFoundError: No module named 'debug_toolbar'
ERROR 2024-06-24 00:54:31,260 signal 1 139833691675432 Signal handler <promise@0x7f2d8e57c870 --> <bound method Celery._autodiscover_tasks of <Celery eazyclass at 0x7f2d8e5701a0>>> raised: AppRegistryNotReady("Apps aren't loaded yet.")
Traceback (most recent call last):
  File "/usr/local/lib/python3.12/site-packages/celery/utils/dispatch/signal.py", line 276, in send
    response = receiver(signal=self, sender=sender, **named)
               ^^^^^^^^^^^^^^^^^^^^^^^^^^^^^^^^^^^^^^^^^^^^^
  File "/usr/local/lib/python3.12/site-packages/vine/promises.py", line 161, in __call__
    return self.throw()
           ^^^^^^^^^^^^
  File "/usr/local/lib/python3.12/site-packages/vine/promises.py", line 158, in __call__
    retval = fun(*final_args, **final_kwargs)
             ^^^^^^^^^^^^^^^^^^^^^^^^^^^^^^^^
  File "/usr/local/lib/python3.12/site-packages/celery/app/base.py", line 694, in _autodiscover_tasks
    return self._autodiscover_tasks_from_fixups(related_name)
           ^^^^^^^^^^^^^^^^^^^^^^^^^^^^^^^^^^^^^^^^^^^^^^^^^^
  File "/usr/local/lib/python3.12/site-packages/celery/app/base.py", line 706, in _autodiscover_tasks_from_fixups
    for pkg in fixup.autodiscover_tasks()
               ^^^^^^^^^^^^^^^^^^^^^^^^^^
  File "/usr/local/lib/python3.12/site-packages/celery/fixups/django.py", line 110, in autodiscover_tasks
    return [config.name for config in apps.get_app_configs()]
                                      ^^^^^^^^^^^^^^^^^^^^^^
  File "/usr/local/lib/python3.12/site-packages/django/apps/registry.py", line 147, in get_app_configs
    self.check_apps_ready()
  File "/usr/local/lib/python3.12/site-packages/django/apps/registry.py", line 138, in check_apps_ready
    raise AppRegistryNotReady("Apps aren't loaded yet.")
django.core.exceptions.AppRegistryNotReady: Apps aren't loaded yet.
ERROR 2024-06-24 00:54:31,260 signal 1 139745978034984 Signal handler <promise@0x7f1922324870 --> <bound method Celery._autodiscover_tasks of <Celery eazyclass at 0x7f1922320230>>> raised: AppRegistryNotReady("Apps aren't loaded yet.")
Traceback (most recent call last):
  File "/usr/local/lib/python3.12/site-packages/celery/utils/dispatch/signal.py", line 276, in send
    response = receiver(signal=self, sender=sender, **named)
               ^^^^^^^^^^^^^^^^^^^^^^^^^^^^^^^^^^^^^^^^^^^^^
  File "/usr/local/lib/python3.12/site-packages/vine/promises.py", line 161, in __call__
    return self.throw()
           ^^^^^^^^^^^^
  File "/usr/local/lib/python3.12/site-packages/vine/promises.py", line 158, in __call__
    retval = fun(*final_args, **final_kwargs)
             ^^^^^^^^^^^^^^^^^^^^^^^^^^^^^^^^
  File "/usr/local/lib/python3.12/site-packages/celery/app/base.py", line 694, in _autodiscover_tasks
    return self._autodiscover_tasks_from_fixups(related_name)
           ^^^^^^^^^^^^^^^^^^^^^^^^^^^^^^^^^^^^^^^^^^^^^^^^^^
  File "/usr/local/lib/python3.12/site-packages/celery/app/base.py", line 706, in _autodiscover_tasks_from_fixups
    for pkg in fixup.autodiscover_tasks()
               ^^^^^^^^^^^^^^^^^^^^^^^^^^
  File "/usr/local/lib/python3.12/site-packages/celery/fixups/django.py", line 110, in autodiscover_tasks
    return [config.name for config in apps.get_app_configs()]
                                      ^^^^^^^^^^^^^^^^^^^^^^
  File "/usr/local/lib/python3.12/site-packages/django/apps/registry.py", line 147, in get_app_configs
    self.check_apps_ready()
  File "/usr/local/lib/python3.12/site-packages/django/apps/registry.py", line 138, in check_apps_ready
    raise AppRegistryNotReady("Apps aren't loaded yet.")
django.core.exceptions.AppRegistryNotReady: Apps aren't loaded yet.
ERROR 2024-06-24 00:57:02,949 signal 1 140539471268648 Signal handler <promise@0x7fd1e218c870 --> <bound method Celery._autodiscover_tasks of <Celery eazyclass at 0x7fd1e45bd1f0>>> raised: ImportError('attempted relative import beyond top-level package')
Traceback (most recent call last):
  File "/usr/local/lib/python3.12/site-packages/celery/utils/dispatch/signal.py", line 276, in send
    response = receiver(signal=self, sender=sender, **named)
               ^^^^^^^^^^^^^^^^^^^^^^^^^^^^^^^^^^^^^^^^^^^^^
  File "/usr/local/lib/python3.12/site-packages/vine/promises.py", line 161, in __call__
    return self.throw()
           ^^^^^^^^^^^^
  File "/usr/local/lib/python3.12/site-packages/vine/promises.py", line 158, in __call__
    retval = fun(*final_args, **final_kwargs)
             ^^^^^^^^^^^^^^^^^^^^^^^^^^^^^^^^
  File "/usr/local/lib/python3.12/site-packages/celery/app/base.py", line 694, in _autodiscover_tasks
    return self._autodiscover_tasks_from_fixups(related_name)
           ^^^^^^^^^^^^^^^^^^^^^^^^^^^^^^^^^^^^^^^^^^^^^^^^^^
  File "/usr/local/lib/python3.12/site-packages/celery/app/base.py", line 703, in _autodiscover_tasks_from_fixups
    return self._autodiscover_tasks_from_names([
           ^^^^^^^^^^^^^^^^^^^^^^^^^^^^^^^^^^^^^
  File "/usr/local/lib/python3.12/site-packages/celery/app/base.py", line 698, in _autodiscover_tasks_from_names
    return self.loader.autodiscover_tasks(
           ^^^^^^^^^^^^^^^^^^^^^^^^^^^^^^^
  File "/usr/local/lib/python3.12/site-packages/celery/loaders/base.py", line 220, in autodiscover_tasks
    mod.__name__ for mod in autodiscover_tasks(packages or (),
                            ^^^^^^^^^^^^^^^^^^^^^^^^^^^^^^^^^^
  File "/usr/local/lib/python3.12/site-packages/celery/loaders/base.py", line 246, in autodiscover_tasks
    return [find_related_module(pkg, related_name) for pkg in packages]
            ^^^^^^^^^^^^^^^^^^^^^^^^^^^^^^^^^^^^^^
  File "/usr/local/lib/python3.12/site-packages/celery/loaders/base.py", line 270, in find_related_module
    return importlib.import_module(module_name)
           ^^^^^^^^^^^^^^^^^^^^^^^^^^^^^^^^^^^^
  File "/usr/local/lib/python3.12/importlib/__init__.py", line 90, in import_module
    return _bootstrap._gcd_import(name[level:], package, level)
           ^^^^^^^^^^^^^^^^^^^^^^^^^^^^^^^^^^^^^^^^^^^^^^^^^^^^
  File "<frozen importlib._bootstrap>", line 1387, in _gcd_import
  File "<frozen importlib._bootstrap>", line 1360, in _find_and_load
  File "<frozen importlib._bootstrap>", line 1331, in _find_and_load_unlocked
  File "<frozen importlib._bootstrap>", line 935, in _load_unlocked
  File "<frozen importlib._bootstrap_external>", line 995, in exec_module
  File "<frozen importlib._bootstrap>", line 488, in _call_with_frames_removed
  File "/app/telegrambot/tasks.py", line 2, in <module>
    from .bot import bot
  File "/app/telegrambot/bot.py", line 8, in <module>
    from .keyboards import start_keyboard, get_keyboard
  File "/app/telegrambot/keyboards.py", line 8, in <module>
    from ..scheduler.models import Faculty, Group, Teacher
ImportError: attempted relative import beyond top-level package
ERROR 2024-06-24 00:57:03,230 signal 1 140305263700776 Signal handler <promise@0x7f9b5a388870 --> <bound method Celery._autodiscover_tasks of <Celery eazyclass at 0x7f9b5a380140>>> raised: ImportError('attempted relative import beyond top-level package')
Traceback (most recent call last):
  File "/usr/local/lib/python3.12/site-packages/celery/utils/dispatch/signal.py", line 276, in send
    response = receiver(signal=self, sender=sender, **named)
               ^^^^^^^^^^^^^^^^^^^^^^^^^^^^^^^^^^^^^^^^^^^^^
  File "/usr/local/lib/python3.12/site-packages/vine/promises.py", line 161, in __call__
    return self.throw()
           ^^^^^^^^^^^^
  File "/usr/local/lib/python3.12/site-packages/vine/promises.py", line 158, in __call__
    retval = fun(*final_args, **final_kwargs)
             ^^^^^^^^^^^^^^^^^^^^^^^^^^^^^^^^
  File "/usr/local/lib/python3.12/site-packages/celery/app/base.py", line 694, in _autodiscover_tasks
    return self._autodiscover_tasks_from_fixups(related_name)
           ^^^^^^^^^^^^^^^^^^^^^^^^^^^^^^^^^^^^^^^^^^^^^^^^^^
  File "/usr/local/lib/python3.12/site-packages/celery/app/base.py", line 703, in _autodiscover_tasks_from_fixups
    return self._autodiscover_tasks_from_names([
           ^^^^^^^^^^^^^^^^^^^^^^^^^^^^^^^^^^^^^
  File "/usr/local/lib/python3.12/site-packages/celery/app/base.py", line 698, in _autodiscover_tasks_from_names
    return self.loader.autodiscover_tasks(
           ^^^^^^^^^^^^^^^^^^^^^^^^^^^^^^^
  File "/usr/local/lib/python3.12/site-packages/celery/loaders/base.py", line 220, in autodiscover_tasks
    mod.__name__ for mod in autodiscover_tasks(packages or (),
                            ^^^^^^^^^^^^^^^^^^^^^^^^^^^^^^^^^^
  File "/usr/local/lib/python3.12/site-packages/celery/loaders/base.py", line 246, in autodiscover_tasks
    return [find_related_module(pkg, related_name) for pkg in packages]
            ^^^^^^^^^^^^^^^^^^^^^^^^^^^^^^^^^^^^^^
  File "/usr/local/lib/python3.12/site-packages/celery/loaders/base.py", line 270, in find_related_module
    return importlib.import_module(module_name)
           ^^^^^^^^^^^^^^^^^^^^^^^^^^^^^^^^^^^^
  File "/usr/local/lib/python3.12/importlib/__init__.py", line 90, in import_module
    return _bootstrap._gcd_import(name[level:], package, level)
           ^^^^^^^^^^^^^^^^^^^^^^^^^^^^^^^^^^^^^^^^^^^^^^^^^^^^
  File "<frozen importlib._bootstrap>", line 1387, in _gcd_import
  File "<frozen importlib._bootstrap>", line 1360, in _find_and_load
  File "<frozen importlib._bootstrap>", line 1331, in _find_and_load_unlocked
  File "<frozen importlib._bootstrap>", line 935, in _load_unlocked
  File "<frozen importlib._bootstrap_external>", line 995, in exec_module
  File "<frozen importlib._bootstrap>", line 488, in _call_with_frames_removed
  File "/app/telegrambot/tasks.py", line 2, in <module>
    from .bot import bot
  File "/app/telegrambot/bot.py", line 8, in <module>
    from .keyboards import start_keyboard, get_keyboard
  File "/app/telegrambot/keyboards.py", line 8, in <module>
    from ..scheduler.models import Faculty, Group, Teacher
ImportError: attempted relative import beyond top-level package
ERROR 2024-06-24 00:57:03,482 signal 1 140551160601384 Signal handler <promise@0x7fd49ad48870 --> <bound method Celery._autodiscover_tasks of <Celery eazyclass at 0x7fd49ad3c320>>> raised: ImportError('attempted relative import beyond top-level package')
Traceback (most recent call last):
  File "/usr/local/lib/python3.12/site-packages/celery/utils/dispatch/signal.py", line 276, in send
    response = receiver(signal=self, sender=sender, **named)
               ^^^^^^^^^^^^^^^^^^^^^^^^^^^^^^^^^^^^^^^^^^^^^
  File "/usr/local/lib/python3.12/site-packages/vine/promises.py", line 161, in __call__
    return self.throw()
           ^^^^^^^^^^^^
  File "/usr/local/lib/python3.12/site-packages/vine/promises.py", line 158, in __call__
    retval = fun(*final_args, **final_kwargs)
             ^^^^^^^^^^^^^^^^^^^^^^^^^^^^^^^^
  File "/usr/local/lib/python3.12/site-packages/celery/app/base.py", line 694, in _autodiscover_tasks
    return self._autodiscover_tasks_from_fixups(related_name)
           ^^^^^^^^^^^^^^^^^^^^^^^^^^^^^^^^^^^^^^^^^^^^^^^^^^
  File "/usr/local/lib/python3.12/site-packages/celery/app/base.py", line 703, in _autodiscover_tasks_from_fixups
    return self._autodiscover_tasks_from_names([
           ^^^^^^^^^^^^^^^^^^^^^^^^^^^^^^^^^^^^^
  File "/usr/local/lib/python3.12/site-packages/celery/app/base.py", line 698, in _autodiscover_tasks_from_names
    return self.loader.autodiscover_tasks(
           ^^^^^^^^^^^^^^^^^^^^^^^^^^^^^^^
  File "/usr/local/lib/python3.12/site-packages/celery/loaders/base.py", line 220, in autodiscover_tasks
    mod.__name__ for mod in autodiscover_tasks(packages or (),
                            ^^^^^^^^^^^^^^^^^^^^^^^^^^^^^^^^^^
  File "/usr/local/lib/python3.12/site-packages/celery/loaders/base.py", line 246, in autodiscover_tasks
    return [find_related_module(pkg, related_name) for pkg in packages]
            ^^^^^^^^^^^^^^^^^^^^^^^^^^^^^^^^^^^^^^
  File "/usr/local/lib/python3.12/site-packages/celery/loaders/base.py", line 270, in find_related_module
    return importlib.import_module(module_name)
           ^^^^^^^^^^^^^^^^^^^^^^^^^^^^^^^^^^^^
  File "/usr/local/lib/python3.12/importlib/__init__.py", line 90, in import_module
    return _bootstrap._gcd_import(name[level:], package, level)
           ^^^^^^^^^^^^^^^^^^^^^^^^^^^^^^^^^^^^^^^^^^^^^^^^^^^^
  File "<frozen importlib._bootstrap>", line 1387, in _gcd_import
  File "<frozen importlib._bootstrap>", line 1360, in _find_and_load
  File "<frozen importlib._bootstrap>", line 1331, in _find_and_load_unlocked
  File "<frozen importlib._bootstrap>", line 935, in _load_unlocked
  File "<frozen importlib._bootstrap_external>", line 995, in exec_module
  File "<frozen importlib._bootstrap>", line 488, in _call_with_frames_removed
  File "/app/telegrambot/tasks.py", line 2, in <module>
    from .bot import bot
  File "/app/telegrambot/bot.py", line 8, in <module>
    from .keyboards import start_keyboard, get_keyboard
  File "/app/telegrambot/keyboards.py", line 8, in <module>
    from ..scheduler.models import Faculty, Group, Teacher
ImportError: attempted relative import beyond top-level package
ERROR 2024-06-24 00:57:03,488 signal 1 140203606276904 Signal handler <promise@0x7f83aefc0870 --> <bound method Celery._autodiscover_tasks of <Celery eazyclass at 0x7f83aefa0470>>> raised: ImportError('attempted relative import beyond top-level package')
Traceback (most recent call last):
  File "/usr/local/lib/python3.12/site-packages/celery/utils/dispatch/signal.py", line 276, in send
    response = receiver(signal=self, sender=sender, **named)
               ^^^^^^^^^^^^^^^^^^^^^^^^^^^^^^^^^^^^^^^^^^^^^
  File "/usr/local/lib/python3.12/site-packages/vine/promises.py", line 161, in __call__
    return self.throw()
           ^^^^^^^^^^^^
  File "/usr/local/lib/python3.12/site-packages/vine/promises.py", line 158, in __call__
    retval = fun(*final_args, **final_kwargs)
             ^^^^^^^^^^^^^^^^^^^^^^^^^^^^^^^^
  File "/usr/local/lib/python3.12/site-packages/celery/app/base.py", line 694, in _autodiscover_tasks
    return self._autodiscover_tasks_from_fixups(related_name)
           ^^^^^^^^^^^^^^^^^^^^^^^^^^^^^^^^^^^^^^^^^^^^^^^^^^
  File "/usr/local/lib/python3.12/site-packages/celery/app/base.py", line 703, in _autodiscover_tasks_from_fixups
    return self._autodiscover_tasks_from_names([
           ^^^^^^^^^^^^^^^^^^^^^^^^^^^^^^^^^^^^^
  File "/usr/local/lib/python3.12/site-packages/celery/app/base.py", line 698, in _autodiscover_tasks_from_names
    return self.loader.autodiscover_tasks(
           ^^^^^^^^^^^^^^^^^^^^^^^^^^^^^^^
  File "/usr/local/lib/python3.12/site-packages/celery/loaders/base.py", line 220, in autodiscover_tasks
    mod.__name__ for mod in autodiscover_tasks(packages or (),
                            ^^^^^^^^^^^^^^^^^^^^^^^^^^^^^^^^^^
  File "/usr/local/lib/python3.12/site-packages/celery/loaders/base.py", line 246, in autodiscover_tasks
    return [find_related_module(pkg, related_name) for pkg in packages]
            ^^^^^^^^^^^^^^^^^^^^^^^^^^^^^^^^^^^^^^
  File "/usr/local/lib/python3.12/site-packages/celery/loaders/base.py", line 270, in find_related_module
    return importlib.import_module(module_name)
           ^^^^^^^^^^^^^^^^^^^^^^^^^^^^^^^^^^^^
  File "/usr/local/lib/python3.12/importlib/__init__.py", line 90, in import_module
    return _bootstrap._gcd_import(name[level:], package, level)
           ^^^^^^^^^^^^^^^^^^^^^^^^^^^^^^^^^^^^^^^^^^^^^^^^^^^^
  File "<frozen importlib._bootstrap>", line 1387, in _gcd_import
  File "<frozen importlib._bootstrap>", line 1360, in _find_and_load
  File "<frozen importlib._bootstrap>", line 1331, in _find_and_load_unlocked
  File "<frozen importlib._bootstrap>", line 935, in _load_unlocked
  File "<frozen importlib._bootstrap_external>", line 995, in exec_module
  File "<frozen importlib._bootstrap>", line 488, in _call_with_frames_removed
  File "/app/telegrambot/tasks.py", line 2, in <module>
    from .bot import bot
  File "/app/telegrambot/bot.py", line 8, in <module>
    from .keyboards import start_keyboard, get_keyboard
  File "/app/telegrambot/keyboards.py", line 8, in <module>
    from ..scheduler.models import Faculty, Group, Teacher
ImportError: attempted relative import beyond top-level package
ERROR 2024-06-24 01:22:43,598 signal 1 140613265980200 Signal handler <promise@0x7fe3109a4870 --> <bound method Celery._autodiscover_tasks of <Celery eazyclass at 0x7fe311498230>>> raised: ImportError('attempted relative import beyond top-level package')
Traceback (most recent call last):
  File "/usr/local/lib/python3.12/site-packages/celery/utils/dispatch/signal.py", line 276, in send
    response = receiver(signal=self, sender=sender, **named)
               ^^^^^^^^^^^^^^^^^^^^^^^^^^^^^^^^^^^^^^^^^^^^^
  File "/usr/local/lib/python3.12/site-packages/vine/promises.py", line 161, in __call__
    return self.throw()
           ^^^^^^^^^^^^
  File "/usr/local/lib/python3.12/site-packages/vine/promises.py", line 158, in __call__
    retval = fun(*final_args, **final_kwargs)
             ^^^^^^^^^^^^^^^^^^^^^^^^^^^^^^^^
  File "/usr/local/lib/python3.12/site-packages/celery/app/base.py", line 694, in _autodiscover_tasks
    return self._autodiscover_tasks_from_fixups(related_name)
           ^^^^^^^^^^^^^^^^^^^^^^^^^^^^^^^^^^^^^^^^^^^^^^^^^^
  File "/usr/local/lib/python3.12/site-packages/celery/app/base.py", line 703, in _autodiscover_tasks_from_fixups
    return self._autodiscover_tasks_from_names([
           ^^^^^^^^^^^^^^^^^^^^^^^^^^^^^^^^^^^^^
  File "/usr/local/lib/python3.12/site-packages/celery/app/base.py", line 698, in _autodiscover_tasks_from_names
    return self.loader.autodiscover_tasks(
           ^^^^^^^^^^^^^^^^^^^^^^^^^^^^^^^
  File "/usr/local/lib/python3.12/site-packages/celery/loaders/base.py", line 220, in autodiscover_tasks
    mod.__name__ for mod in autodiscover_tasks(packages or (),
                            ^^^^^^^^^^^^^^^^^^^^^^^^^^^^^^^^^^
  File "/usr/local/lib/python3.12/site-packages/celery/loaders/base.py", line 246, in autodiscover_tasks
    return [find_related_module(pkg, related_name) for pkg in packages]
            ^^^^^^^^^^^^^^^^^^^^^^^^^^^^^^^^^^^^^^
  File "/usr/local/lib/python3.12/site-packages/celery/loaders/base.py", line 270, in find_related_module
    return importlib.import_module(module_name)
           ^^^^^^^^^^^^^^^^^^^^^^^^^^^^^^^^^^^^
  File "/usr/local/lib/python3.12/importlib/__init__.py", line 90, in import_module
    return _bootstrap._gcd_import(name[level:], package, level)
           ^^^^^^^^^^^^^^^^^^^^^^^^^^^^^^^^^^^^^^^^^^^^^^^^^^^^
  File "<frozen importlib._bootstrap>", line 1387, in _gcd_import
  File "<frozen importlib._bootstrap>", line 1360, in _find_and_load
  File "<frozen importlib._bootstrap>", line 1331, in _find_and_load_unlocked
  File "<frozen importlib._bootstrap>", line 935, in _load_unlocked
  File "<frozen importlib._bootstrap_external>", line 995, in exec_module
  File "<frozen importlib._bootstrap>", line 488, in _call_with_frames_removed
  File "/app/telegrambot/tasks.py", line 2, in <module>
    from .keyboards import update_group_keyboard_cache, update_teacher_keyboard_cache
  File "/app/telegrambot/keyboards.py", line 8, in <module>
    from ..scheduler.models import Faculty, Group, Teacher
ImportError: attempted relative import beyond top-level package
INFO 2024-06-24 01:27:45,613 command 1 140557391235880 Visit me at http://0.0.0.0:5555
INFO 2024-06-24 01:27:45,626 command 1 140557391235880 Broker: redis://redis:6379/0
INFO 2024-06-24 01:27:45,635 command 1 140557391235880 Registered tasks: 
['celery.accumulate',
 'celery.backend_cleanup',
 'celery.chain',
 'celery.chord',
 'celery.chord_unlock',
 'celery.chunks',
 'celery.group',
 'celery.map',
 'celery.starmap',
 'scheduler.tasks.group_parser.deactivate_all_groups',
 'scheduler.tasks.group_parser.update_groups',
 'scheduler.tasks.schedule_parser.parse_group_data',
 'scheduler.tasks.schedule_parser.process_data_final',
 'scheduler.tasks.schedule_parser.send_group_notification',
 'scheduler.tasks.schedule_parser.send_notifications',
 'scheduler.tasks.schedule_parser.update_schedule',
 'scheduler.tasks.timetable_manager.fill_lesson_times',
 'scheduler.tasks.update_last_active.delete_inactive_records',
 'scheduler.tasks.update_last_active.update_last_active_records',
 'telegrambot.tasks.update_keyboard_cache']
INFO 2024-06-24 01:27:45,643 mixins 1 140557294476088 Connected to redis://redis:6379/0
INFO 2024-06-24 01:30:40,544 command 1 140557391235880 15 detected, shutting down
INFO 2024-06-24 01:30:52,702 command 1 140598408788776 Visit me at http://0.0.0.0:5555
INFO 2024-06-24 01:30:52,709 command 1 140598408788776 Broker: redis://redis:6379/0
INFO 2024-06-24 01:30:52,721 command 1 140598408788776 Registered tasks: 
['celery.accumulate',
 'celery.backend_cleanup',
 'celery.chain',
 'celery.chord',
 'celery.chord_unlock',
 'celery.chunks',
 'celery.group',
 'celery.map',
 'celery.starmap',
 'scheduler.tasks.group_parser.deactivate_all_groups',
 'scheduler.tasks.group_parser.update_groups',
 'scheduler.tasks.schedule_parser.parse_group_data',
 'scheduler.tasks.schedule_parser.process_data_final',
 'scheduler.tasks.schedule_parser.send_group_notification',
 'scheduler.tasks.schedule_parser.send_notifications',
 'scheduler.tasks.schedule_parser.update_schedule',
 'scheduler.tasks.timetable_manager.fill_lesson_times',
 'scheduler.tasks.update_last_active.delete_inactive_records',
 'scheduler.tasks.update_last_active.update_last_active_records',
 'telegrambot.tasks.update_keyboard_cache']
INFO 2024-06-24 01:30:52,730 mixins 1 140598310247224 Connected to redis://redis:6379/0
WARNING 2024-06-24 01:30:53,779 inspector 1 140598304860984 Inspect method active failed
WARNING 2024-06-24 01:30:53,780 inspector 1 140598308092728 Inspect method active_queues failed
WARNING 2024-06-24 01:30:53,785 inspector 1 140598309169976 Inspect method stats failed
WARNING 2024-06-24 01:30:53,785 inspector 1 140598305938232 Inspect method scheduled failed
WARNING 2024-06-24 01:30:53,785 inspector 1 140598303783736 Inspect method reserved failed
WARNING 2024-06-24 01:30:53,787 inspector 1 140598302706488 Inspect method revoked failed
WARNING 2024-06-24 01:30:53,790 inspector 1 140598301629240 Inspect method conf failed
WARNING 2024-06-24 01:30:53,790 inspector 1 140598307015480 Inspect method registered failed
INFO 2024-06-24 01:32:07,331 command 1 140598408788776 15 detected, shutting down
INFO 2024-06-24 01:32:17,325 command 1 140171895532328 Visit me at http://0.0.0.0:5555
INFO 2024-06-24 01:32:17,332 command 1 140171895532328 Broker: redis://redis:6379/0
INFO 2024-06-24 01:32:17,342 command 1 140171895532328 Registered tasks: 
['celery.accumulate',
 'celery.backend_cleanup',
 'celery.chain',
 'celery.chord',
 'celery.chord_unlock',
 'celery.chunks',
 'celery.group',
 'celery.map',
 'celery.starmap',
 'scheduler.tasks.group_parser.deactivate_all_groups',
 'scheduler.tasks.group_parser.update_groups',
 'scheduler.tasks.schedule_parser.parse_group_data',
 'scheduler.tasks.schedule_parser.process_data_final',
 'scheduler.tasks.schedule_parser.send_group_notification',
 'scheduler.tasks.schedule_parser.send_notifications',
 'scheduler.tasks.schedule_parser.update_schedule',
 'scheduler.tasks.timetable_manager.fill_lesson_times',
 'scheduler.tasks.update_last_active.delete_inactive_records',
 'scheduler.tasks.update_last_active.update_last_active_records',
 'telegrambot.tasks.update_keyboard_cache']
INFO 2024-06-24 01:32:17,356 mixins 1 140171797011256 Connected to redis://redis:6379/0
WARNING 2024-06-24 01:32:18,407 inspector 1 140171790494520 Inspect method reserved failed
WARNING 2024-06-24 01:32:18,408 inspector 1 140171789433656 Inspect method revoked failed
WARNING 2024-06-24 01:32:18,409 inspector 1 140171793779512 Inspect method registered failed
WARNING 2024-06-24 01:32:18,412 inspector 1 140171795934008 Inspect method stats failed
WARNING 2024-06-24 01:32:18,413 inspector 1 140171791555384 Inspect method active failed
WARNING 2024-06-24 01:32:18,415 inspector 1 140171792702264 Inspect method scheduled failed
WARNING 2024-06-24 01:32:18,415 inspector 1 140171788372792 Inspect method conf failed
WARNING 2024-06-24 01:32:18,415 inspector 1 140171794856760 Inspect method active_queues failed
